Workbook

Sheet Executive_Summary
A1: LayerZero — Bridge Bytecode Vulnerability Detection: Executive Summary
A3: KEY METRICS
A4: ="Addresses queried: "&COUNTA(Data!A2:A89)&" | Chains covered: 1" -> Addresses queried: 88 | Chains covered: 1
A5: ="Contracts with resolved bytecode: "&SUM(Data!C2:C89)&" | No bytecode (EOA/unverified): "&(COUNTA(Data!A2:A89)-SUM(Data!C2:C89)) -> Contracts with resolved bytecode: 72 | No bytecode (EOA/unverified): 16
A6: ="Overall vulnerable (>=1 tool): "&TEXT(Per_Vulnerability_Analysis!C15/Per_Vulnerability_Analysis!D15,"0.0%")&" of resolved contracts ("&Per_Vulnerability_Analysis!C15&"/"&Per_Vulnerability_Analysis!D15&")" -> Overall vulnerable (>=1 tool): 59.7% of resolved contracts (43/72)
A7: ="MAIAN flag rate: "&TEXT(Tool_Wise_Analysis!E4,"0.0%") -> MAIAN flag rate: 59.7%
A8: ="Mythril flag rate: "&TEXT(Tool_Wise_Analysis!E5,"0.0%") -> Mythril flag rate: 48.6%
A9: ="Tool agreement (Jaccard, MAIAN vs Mythril): "&TEXT(Agreement_Jaccard!B11,"0.0000") -> Tool agreement (Jaccard, MAIAN vs Mythril): 0.8140
A11: WHAT THE DATA SHOWS
A12: ="Highest-prevalence category: "&INDEX(Per_Vulnerability_Analysis!A5:A14,MATCH(MAX(Per_Vulnerability_Analysis!C5:C14),Per_Vulnerability_Analysis!C5:C14,0))&" ("&TEXT(MAX(Per_Vulnerability_Analysis!E5:E14),"0.0%")&" prevalence)" -> Highest-prevalence category: Ether Leak (59.7% prevalence)
A13: ="Only MAIAN and Mythril returned detections in this run; 8 of 11 tracked categories show zero hits — see Formula_Definitions / Per_Vulnerability_Analysis." -> Only MAIAN and Mythril returned detections in this run; 8 of 11 tracked categories show zero hits — see Formula_Definitions / Per_Vulnerability_Analysis.

Sheet Formula_Definitions
A1: Metric | B1: Formula | C1: Interpretation
A2: Detections D(v) | B2: COUNTIF(category_column, "<>") | C2: Number of contracts flagged for vulnerability v by its reporting tool
A3: Contracts w/ Bytecode | B3: SUM(Has_Bytecode) | C3: Denominator for prevalence; excludes EOA/unverified/no-code addresses
A4: Prevalence % | B4: D(v) / Contracts_w_Bytecode | C4: Share of resolved contracts flagged for category v
A5: Overall Vulnerable | B5: COUNTIFS(Has_Bytecode=1, Vulnerable="Yes") | C5: Contracts flagged by >=1 tool, among resolved contracts
A6: Flags per Contract | B6: COUNT of active categories triggered per row | C6: How many distinct categories fire on the same contract
A7: Tool Flag Rate % | B7: Tool-flagged contracts / Contracts w/ Bytecode | C7: Per-tool prevalence, independent of category breakdown
A8: Jaccard Index J(A,B) | B8: |A ∩ B| / |A ∪ B| | C8: Overlap between the two tools' flagged sets; 0=no overlap, 1=identical sets
A9: Vulnerable Rate % (chain) | B9: Vulnerable(chain) / With_Bytecode(chain) | C9: Per-chain share of resolved contracts flagged

Sheet Per_Vulnerability_Analysis
A1: LayerZero — Per-Vulnerability Analysis
A3: Category | B3: Detecting Tool | C3: Detections D(v) | D3: Contracts w/ Bytecode | E3: Prevalence % | F3: Note
A4: Reentrancy | B4: Not covered (0 detections) | C4: =COUNTIF(Data!E2:E89,"<>") -> 0 | D4: =SUM(Data!C2:C89) -> 72 | E4: =IF(D4=0,0,C4/D4) -> 0 | F4: Zero detections this run
A5: Integer | B5: Mythril | C5: =COUNTIF(Data!F2:F89,"<>") -> 35 | D5: =SUM(Data!C2:C89) -> 72 | E5: =IF(D5=0,0,C5/D5) -> 0.48611111 | F5: Bytecode-level detection
A6: Access Control | B6: Not covered (0 detections) | C6: =COUNTIF(Data!G2:G89,"<>") -> 0 | D6: =SUM(Data!C2:C89) -> 72 | E6: =IF(D6=0,0,C6/D6) -> 0 | F6: Zero detections this run
A7: Delegatecall | B7: Not covered (0 detections) | C7: =COUNTIF(Data!H2:H89,"<>") -> 0 | D7: =SUM(Data!C2:C89) -> 72 | E7: =IF(D7=0,0,C7/D7) -> 0 | F7: Zero detections this run
A8: Unchecked Call | B8: Not covered (0 detections) | C8: =COUNTIF(Data!I2:I89,"<>") -> 0 | D8: =SUM(Data!C2:C89) -> 72 | E8: =IF(D8=0,0,C8/D8) -> 0 | F8: Zero detections this run
A9: Timestamp | B9: Not covered (0 detections) | C9: =COUNTIF(Data!J2:J89,"<>") -> 0 | D9: =SUM(Data!C2:C89) -> 72 | E9: =IF(D9=0,0,C9/D9) -> 0 | F9: Zero detections this run
A10: TOD | B10: Not covered (0 detections) | C10: =COUNTIF(Data!K2:K89,"<>") -> 0 | D10: =SUM(Data!C2:C89) -> 72 | E10: =IF(D10=0,0,C10/D10) -> 0 | F10: Zero detections this run
A11: DoS | B11: Not covered (0 detections) | C11: =COUNTIF(Data!L2:L89,"<>") -> 0 | D11: =SUM(Data!C2:C89) -> 72 | E11: =IF(D11=0,0,C11/D11) -> 0 | F11: Zero detections this run
A12: Selfdestruct | B12: Not covered (0 detections) | C12: =COUNTIF(Data!M2:M89,"<>") -> 0 | D12: =SUM(Data!C2:C89) -> 72 | E12: =IF(D12=0,0,C12/D12) -> 0 | F12: Zero detections this run
A13: Locked Ether | B13: MAIAN | C13: =COUNTIF(Data!N2:N89,"<>") -> 32 | D13: =SUM(Data!C2:C89) -> 72 | E13: =IF(D13=0,0,C13/D13) -> 0.44444444 | F13: Bytecode-level detection
A14: Ether Leak | B14: MAIAN | C14: =COUNTIF(Data!O2:O89,"<>") -> 43 | D14: =SUM(Data!C2:C89) -> 72 | E14: =IF(D14=0,0,C14/D14) -> 0.59722222 | F14: Bytecode-level detection
A15: OVERALL VULNERABLE | B15: Any tool | C15: =COUNTIFS(Data!C2:C89,1,Data!P2:P89,"Yes") -> 43 | D15: =SUM(Data!C2:C89) -> 72 | E15: =IF(D15=0,0,C15/D15) -> 0.59722222 | F15: Flagged by >=1 tool

Sheet Detection_Count_Analysis
A1: LayerZero — Detection Count Analysis
A3: Flags per contract = count of (Integer, Locked Ether, Ether Leak) triggered on that contract
A5: Flags per Contract | B5: Contract Count | C5: % of Bytecode Contracts | D5: Note
A6: 0 categories flagged | B6: =SUMPRODUCT((Data!C2:C89=1)*(((Data!F2:F89<>"")+(Data!N2:N89<>"")+(Data!O2:O89<>""))=0)) -> 29 | C6: =IF(SUM(Data!C2:C89)=0,0,B6/SUM(Data!C2:C89)) -> 0.40277778
A7: 1 categories flagged | B7: =SUMPRODUCT((Data!C2:C89=1)*(((Data!F2:F89<>"")+(Data!N2:N89<>"")+(Data!O2:O89<>""))=1)) -> 0 | C7: =IF(SUM(Data!C2:C89)=0,0,B7/SUM(Data!C2:C89)) -> 0
A8: 2 categories flagged | B8: =SUMPRODUCT((Data!C2:C89=1)*(((Data!F2:F89<>"")+(Data!N2:N89<>"")+(Data!O2:O89<>""))=2)) -> 19 | C8: =IF(SUM(Data!C2:C89)=0,0,B8/SUM(Data!C2:C89)) -> 0.26388889
A9: 3 categories flagged | B9: =SUMPRODUCT((Data!C2:C89=1)*(((Data!F2:F89<>"")+(Data!N2:N89<>"")+(Data!O2:O89<>""))=3)) -> 24 | C9: =IF(SUM(Data!C2:C89)=0,0,B9/SUM(Data!C2:C89)) -> 0.33333333
A10: Total contracts w/ bytecode | B10: =SUM(B6:B9) -> 72
A12: Total raw detections (sum across all 11 categories) | B12: =COUNTIF(Data!E2:E89,"<>")+COUNTIF(Data!F2:F89,"<>")+COUNTIF(Data!G2:G89,"<>")+COUNTIF(Data!H2:H89,"<>")+COUNTIF(Data!I2:I89,"<>")+COUNTIF(Data!J2:J89,"<>")+COUNTIF(Data!K2:K89,"<>")+COUNTIF(Data!L2:L89,"<>")+COUNTIF(Data!M2:M89,"<>")+COUNTIF(Data!N2:N89,"<>")+COUNTIF(Data!O2:O89,"<>") -> 110
A13: Avg detections per bytecode-resolved contract | B13: =B12/SUM(Data!C2:C89) -> 1.5277778

Sheet Tool_Wise_Analysis
A1: LayerZero — Tool-wise Analysis
A3: Tool | B3: Categories Covered | C3: Contracts Flagged | D3: Contracts w/ Bytecode | E3: Flag Rate % | F3: Note
A4: MAIAN | B4: Locked Ether, Ether Leak | C4: =SUM(Data!Q2:Q89) -> 43 | D4: =SUM(Data!C2:C89) -> 72 | E4: =IF(D4=0,0,C4/D4) -> 0.59722222 | F4: Symbolic execution, financial-flow analysis
A5: Mythril | B5: Integer | C5: =SUM(Data!R2:R89) -> 35 | D5: =SUM(Data!C2:C89) -> 72 | E5: =IF(D5=0,0,C5/D5) -> 0.48611111 | F5: Bytecode symbolic execution
A6: Others (n/a) | B6: Reentrancy, Access Control, Delegatecall, Unchecked Call, Timestamp, TOD, DoS, Selfdestruct | C6: 0 | D6: =SUM(Data!C2:C89) -> 72 | E6: 0 | F6: Zero detections in this run

Sheet Contract_Level_Statistics
A1: LayerZero — Contract-Level Statistics
A3: Addresses queried | B3: =COUNTA(Data!A2:A89) -> 88
A4: Chains covered | B4: 1
A5: Contracts analyzed (bytecode resolved / detection ran) | B5: =SUM(Data!C2:C89) -> 72
A6: Not analyzed (EOA / unverified / not found) | B6: =COUNTA(Data!A2:A89)-SUM(Data!C2:C89) -> 16
A7: ...of which bytecode text is blank in source export | B7: =SUMPRODUCT((Data!C2:C89=1)*(Data!D2:D89=0)) -> 0 | D7: Detections still recorded; only the raw bytecode string is missing from the export
A8: Avg bytecode length (hex chars, where text available) | B8: =IF(SUMPRODUCT((Data!C2:C89=1)*(Data!D2:D89>0))=0,0,SUMIF(Data!C2:C89,1,Data!D2:D89)/SUMPRODUCT((Data!C2:C89=1)*(Data!D2:D89>0))) -> 28151.611 | D8: Rounded to nearest char; excludes blank-text rows
A9: Min bytecode length (where text available) | B9: =_xlfn.MINIFS(Data!D2:D89,Data!C2:C89,1,Data!D2:D89,">0") -> 2498
A10: Max bytecode length | B10: =_xlfn.MAXIFS(Data!D2:D89,Data!C2:C89,1) -> 189634
A12: Per-Chain Breakdown
A13: Chain | B13: Addresses | C13: With Bytecode | D13: Vulnerable Rate %
A14: All (chain not encoded in address) | B14: =COUNTIF(Data!B2:B89,A14) -> 88 | C14: =COUNTIFS(Data!B2:B89,A14,Data!C2:C89,1) -> 72 | D14: =IF(C14=0,0,(COUNTIFS(Data!B2:B89,A14,Data!C2:C89,1,Data!P2:P89,"Yes"))/C14) -> 0.59722222

Sheet Agreement_Jaccard
A1: LayerZero — Tool Agreement (Jaccard Index)
A2: Agreement between MAIAN and Mythril, among contracts with bytecode.
A4: Set | B4: Count | C4: % of Bytecode Contracts | D4: Definition
A5: Both tools flag (A ∩ B) | B5: =SUMPRODUCT((Data!C2:C89=1)*(Data!Q2:Q89=1)*(Data!R2:R89=1)) -> 35 | C5: =IF(SUM(Data!C2:C89)=0,0,B5/SUM(Data!C2:C89)) -> 0.48611111 | D5: MAIAN AND Mythril
A6: Only MAIAN flags (A \ B) | B6: =SUMPRODUCT((Data!C2:C89=1)*(Data!Q2:Q89=1)*(Data!R2:R89=0)) -> 8 | C6: =IF(SUM(Data!C2:C89)=0,0,B6/SUM(Data!C2:C89)) -> 0.11111111 | D6: MAIAN only
A7: Only Mythril flags (B \ A) | B7: =SUMPRODUCT((Data!C2:C89=1)*(Data!Q2:Q89=0)*(Data!R2:R89=1)) -> 0 | C7: =IF(SUM(Data!C2:C89)=0,0,B7/SUM(Data!C2:C89)) -> 0 | D7: Mythril only
A8: Neither flags | B8: =SUMPRODUCT((Data!C2:C89=1)*(Data!Q2:Q89=0)*(Data!R2:R89=0)) -> 29 | C8: =IF(SUM(Data!C2:C89)=0,0,B8/SUM(Data!C2:C89)) -> 0.40277778 | D8: Resolved contract, no flag from either tool
A10: Union (A ∪ B) | B10: =B5+B6+B7 -> 43
A11: Jaccard Index J(A,B) = |A∩B| / |A∪B| | B11: =IF(B10=0,0,B5/B10) -> 0.81395349

Sheet Key_Findings
A1: LayerZero — Key Findings
A3: ="1. Bytecode resolution: "&SUM(Data!C2:C89)&" of "&COUNTA(Data!A2:A89)&" queried addresses ("&TEXT(SUM(Data!C2:C89)/COUNTA(Data!A2:A89),"0.0%")&") resolved to deployed bytecode; the rest are EOAs, unverified, or not found on-chain." -> 1. Bytecode resolution: 72 of 88 queried addresses (81.8%) resolved to deployed bytecode; the rest are EOAs, unverified, or not found on-chain.
A4: ="2. Detection coverage: only MAIAN and Mythril produced any detections. Reentrancy, Access Control, Delegatecall, Unchecked Call, Timestamp, TOD, DoS, Selfdestruct all show zero hits in this bytecode run." -> 2. Detection coverage: only MAIAN and Mythril produced any detections. Reentrancy, Access Control, Delegatecall, Unchecked Call, Timestamp, TOD, DoS, Selfdestruct all show zero hits in this bytecode run.
A5: ="3. Mythril flag rate ("&TEXT(Tool_Wise_Analysis!E5,"0.0%")&") vs MAIAN flag rate ("&TEXT(Tool_Wise_Analysis!E4,"0.0%")&") among resolved contracts." -> 3. Mythril flag rate (48.6%) vs MAIAN flag rate (59.7%) among resolved contracts.
A6: ="4. Tool overlap: Jaccard(MAIAN, Mythril) = "&TEXT(Agreement_Jaccard!B11,"0.0000")&" — "&Agreement_Jaccard!B5&" contracts triggered both tools, "&Agreement_Jaccard!B6&" only MAIAN, "&Agreement_Jaccard!B7&" only Mythril." -> 4. Tool overlap: Jaccard(MAIAN, Mythril) = 0.8140 — 35 contracts triggered both tools, 8 only MAIAN, 0 only Mythril.
A7: ="5. "&Per_Vulnerability_Analysis!C15&" of "&Per_Vulnerability_Analysis!D15&" resolved contracts ("&TEXT(Per_Vulnerability_Analysis!C15/Per_Vulnerability_Analysis!D15,"0.0%")&") were flagged by at least one tool." -> 5. 43 of 72 resolved contracts (59.7%) were flagged by at least one tool.

Sheet Why_These_Results
A1: LayerZero — Why These Results: Forensic Explanation of the Detection Pattern
A2: Findings below are derived from direct inspection of the raw deployed bytecode (length, opcode counts, function-selector signatures) behind this protocol's CSV, not just the tool output.
A4: 1. WHY THE ANALYZED RATE IS 81.8%
A5: Of 88 addresses queried for LayerZero, 72 (81.8%) resolved to a contract with recorded detection results. The remainder are addresses listed in the bridge's cross-chain registry that do not currently hold deployed bytecode on the chain they're paired with in the source data.
A6: This is a registry-completeness artifact, not a tool failure: cross-chain bridge protocols typically reserve or intend the SAME contract address across every supported chain (often via CREATE2 deterministic deployment), but do not necessarily deploy on all of them at the same time - some chains get the contract later, some never, and some registries list planned/future chains. A low analyzed rate signals partial rollout, not analysis error.
A8: 2. PROXY-PATTERN CONTRACTS AND THEIR EFFECT ON DETECTION
A9: 32 of 72 contracts with inspectable bytecode (44.4%) expose the classic UUPS/ERC-1967 upgradeable-proxy function selectors (upgradeTo, upgradeToAndCall, implementation) - meaning their bytecode is a thin delegatecall shell, with the real logic living in a separate implementation contract this analysis does not see.
A10: Vulnerable rate on these proxy-pattern contracts: 9.4% (3/32), versus 100.0% (40/40) on non-proxy contracts.
A11: Category breakdown on proxy contracts: Locked Ether: 3, Ether Leak: 3.
A12: This is the single largest driver of LayerZero's lower overall vulnerable rate (59.7%, versus ~100% for every other protocol in this dataset): its proxy contracts are almost entirely clean (9.4% flagged) because bytecode-level tools like Mythril and MAIAN cannot trace through a delegatecall into the implementation contract's actual logic - a proxy that just forwards calls has essentially no arithmetic or ether-handling code of its own to flag.
A14: 3. WHY MAIAN FIRES MORE OFTEN THAN MYTHRIL
A15: In this protocol, MAIAN's flag rate (59.7%) is higher than Mythril's (48.6%), with tool agreement (Jaccard) of 0.8140. This asymmetry appears consistently across all 5 protocols in this dataset and has two likely structural causes:
... A26: LayerZero's 59.7% vulnerable rate - the only sub-100% result in this dataset - is best explained by its unusually high share of proxy-pattern contracts (44.4% of analyzed contracts) that bytecode-level analysis structurally cannot see through, not by LayerZero's logic being more secure than the other four protocols.

Sheet Data
A1: Address | B1: Chain | C1: Has_Bytecode | D1: Bytecode_Length | E1: Reentrancy | F1: Integer | G1: Access_Control | H1: Delegatecall | I1: Unchecked_Call | J1: Timestamp | K1: TOD | L1: DoS | M1: Selfdestruct | N1: Locked_Ether | O1: Ether_Leak | P1: Vulnerable | Q1: MAIAN_Flag | R1: Mythril_Flag
A2: 0x0171830E6C8d7f28cbE35A2045919a415B04a5fF | B2: All (chain not encoded in address) | C2: 1 | D2: 46944 | F2: Mythril | N2: MAIAN | O2: MAIAN | P2: Yes | Q2: 1 | R2: 1
A3: 0x0408804C5dcD9796F22558464E6fE5bDdF16A7c7 | B3: All (chain not encoded in address) | C3: 1 | D3: 4610 | P3: No | Q3: 0 | R3: 0
A4: 0x05B52859Adb077a7b7D6277a512aEfEFbaDDc9C8 | B4: All (chain not encoded in address) | C4: 1 | D4: 4610 | P4: No | Q4: 0 | R4: 0
A5: 0x068EC1f0bd53cf86923BbB0986046be6af3f5922 | B5: All (chain not encoded in address) | C5: 1 | D5: 29378 | N5: MAIAN | O5: MAIAN | P5: Yes | Q5: 1 | R5: 0
A6: 0x06e56abD0cb3C88880644bA3C534A498cA18E5C8 | B6: All (chain not encoded in address) | C6: 1 | D6: 3778 | N6: MAIAN | O6: MAIAN | P6: Yes | Q6: 1 | R6: 0
A7: 0x14a6A3d612A04225df4825A365688F33DA4969De | B7: All (chain not encoded in address) | C7: 1 | D7: 46944 | F7: Mythril | N7: MAIAN | O7: MAIAN | P7: Yes | Q7: 1 | R7: 1
A8: 0x1641D737e97916f1400CB6BA032eceE765484D9C | B8: All (chain not encoded in address) | C8: 1 | D8: 46944 | F8: Mythril | N8: MAIAN | O8: MAIAN | P8: Yes | Q8: 1 | R8: 1
A9: 0x166CAb679EBDB0853055522D3B523621b94029a1 | B9: All (chain not encoded in address) | C9: 1 | D9: 172226 | N9: MAIAN | O9: MAIAN | P9: Yes | Q9: 1 | R9: 0
A10: 0x173272739Bd7Aa6e4e214714048a9fE699453059 | B10: All (chain not encoded in address) | C10: 1 | D10: 4610 | P10: No | Q10: 0 | R10: 0
A11: 0x1BAcC2205312534375c8d1801C27D28370656cFf | B11: All (chain not encoded in address) | C11: 1 | D11: 45992 | F11: Mythril | N11: MAIAN | O11: MAIAN | P11: Yes | Q11: 1 | R11: 1
A12: 0x1Bef2d7C5c60fD826Cc1b1f29cA357Af2d0Ae2c6 | B12: All (chain not encoded in address) | C12: 1 | D12: 4610 | P12: No | Q12: 0 | R12: 0
A13: 0x1E1E9A04735B9ca509eF8a46255f5104C10C6e99 | B13: All (chain not encoded in address) | C13: 1 | D13: 4610 | P13: No | Q13: 0 | R13: 0
A14: 0x1b368a0d7c57080a01054862114B5a42e54CBb98 | B14: All (chain not encoded in address) | C14: 0 | D14: 0 | P14: No | Q14: 0 | R14: 0
A15: 0x1ccBf0db9C192d969de57E25B3fF09A25bb1D862 | B15: All (chain not encoded in address) | C15: 0 | D15: 0 | P15: No | Q15: 0 | R15: 0
A16: 0x1dDbaF8b75F2291A97C22428afEf411b7bB19e28 | B16: All (chain not encoded in address) | C16: 1 | D16: 4610 | P16: No | Q16: 0 | R16: 0
A17: 0x24D7ff228a81e827Efc29ec45E7b30a99B96C653 | B17: All (chain not encoded in address) | C17: 0 | D17: 0 | P17: No | Q17: 0 | R17: 0
A18: 0x28eEE23B2b6C5582112037FD43A4d8C359F54D4D | B18: All (chain not encoded in address) | C18: 0 | D18: 0 | P18: No | Q18: 0 | R18: 0
A19: 0x2B79f3C2EE059E465a24bf5A2F4FE989546053B1 | B19: All (chain not encoded in address) | C19: 1 | D19: 189634 | N19: MAIAN | O19: MAIAN | P19: Yes | Q19: 1 | R19: 0
A20: 0x2F0788fFbf8fCa58B2ea10c05F0CA9931ffC8978 | B20: All (chain not encoded in address) | C20: 1 | D20: 4610 | P20: No | Q20: 0 | R20: 0
A21: 0x2F4C6eeA955e95e6d65E08620D980C0e0e92211F | B21: All (chain not encoded in address) | C21: 1 | D21: 22022 | F21: Mythril | O21: MAIAN | P21: Yes | Q21: 1 | R21: 1
A22: 0x2F64656569c098fdfb0bD0ab2f3616005E295810 | B22: All (chain not encoded in address) | C22: 1 | D22: 4610 | P22: No | Q22: 0 | R22: 0
A23: 0x2c83731aa397cd8E6bF8C77d9090b8845581d08c | B23: All (chain not encoded in address) | C23: 1 | D23: 4610 | P23: No | Q23: 0 | R23: 0
A24: 0x2e2AF282E98bfADed5dd6EC51c7240D818DDBBD9 | B24: All (chain not encoded in address) | C24: 0 | D24: 0 | P24: No | Q24: 0 | R24: 0
A25: 0x30F776548f9Aaad0935E2c03e930d10F15cE558f | B25: All (chain not encoded in address) | C25: 1 | D25: 46944 | F25: Mythril | N25: MAIAN | O25: MAIAN | P25: Yes | Q25: 1 | R25: 1
A26: 0x31CAe3B7fB82d847621859fb1585353c5720660D | B26: All (chain not encoded in address) | C26: 1 | D26: 4610 | P26: No | Q26: 0 | R26: 0
A27: 0x32042142DD551b4EbE17B6FEd53131dd4b4eEa06 | B27: All (chain not encoded in address) | C27: 1 | D27: 45992 | F27: Mythril | N27: MAIAN | O27: MAIAN | P27: Yes | Q27: 1 | R27: 1
A28: 0x3258287147FB7887d8A643006e26E19368057377 | B28: All (chain not encoded in address) | C28: 1 | D28: 2498 | N28: MAIAN | O28: MAIAN | P28: Yes | Q28: 1 | R28: 0
A29: 0x377530cdA84DFb2673bF4d145DCF0C4D7fdcB5b6 | B29: All (chain not encoded in address) | C29: 1 | D29: 22022 | F29: Mythril | O29: MAIAN | P29: Yes | Q29: 1 | R29: 1
A30: 0x38340337f9ADF5D76029Ab3A667d34E5a032F7BA | B30: All (chain not encoded in address) | C30: 1 | D30: 4610 | P30: No | Q30: 0 | R30: 0
A31: 0x3C156b1f625D2B4E004D43E91aC2c3a719C29c7B | B31: All (chain not encoded in address) | C31: 1 | D31: 45992 | F31: Mythril | N31: MAIAN | O31: MAIAN | P31: Yes | Q31: 1 | R31: 1
A32: 0x3b4453D9e884dA5A8C917Ab7679D66c92069e7F7 | B32: All (chain not encoded in address) | C32: 1 | D32: 46944 | F32: Mythril | N32: MAIAN | O32: MAIAN | P32: Yes | Q32: 1 | R32: 1
A33: 0x42b4E9C6495B4cFDaE024B1eC32E09F28027620e | B33: All (chain not encoded in address) | C33: 1 | D33: 45992 | F33: Mythril | N33: MAIAN | O33: MAIAN | P33: Yes | Q33: 1 | R33: 1
A34: 0x43CFcc293CdF99F7D021F21FfD443f174AB0e843 | B34: All (chain not encoded in address) | C34: 0 | D34: 0 | P34: No | Q34: 0 | R34: 0
A35: 0x44289609cc6781fa2C665796b6c5AAbf9FFceDC5 | B35: All (chain not encoded in address) | C35: 1 | D35: 45992 | F35: Mythril | N35: MAIAN | O35: MAIAN | P35: Yes | Q35: 1 | R35: 1
A36: 0x4E341b9Cf90514A5b7dfec2c9A1f20AA4514C260 | B36: All (chain not encoded in address) | C36: 1 | D36: 4610 | P36: No | Q36: 0 | R36: 0
A37: 0x4Fc3f4A38Acd6E4cC0ccBc04B3Dd1CCAeFd7F3Cd | B37: All (chain not encoded in address) | C37: 1 | D37: 4610 | P37: No | Q37: 0 | R37: 0
A38: 0x52fFEeaE5Ffa89D4b31c72F87ead3699FCB79e40 | B38: All (chain not encoded in address) | C38: 1 | D38: 29378 | N38: MAIAN | O38: MAIAN | P38: Yes | Q38: 1 | R38: 0
A39: 0x5440E2097C41F8e0a8551521d569c71de70fDe23 | B39: All (chain not encoded in address) | C39: 1 | D39: 4610 | P39: No | Q39: 0 | R39: 0
A40: 0x552661d1C85F256E008eE2315103c80fd1E298DF | B40: All (chain not encoded in address) | C40: 1 | D40: 4610 | P40: No | Q40: 0 | R40: 0
...
