Workbook

Sheet Executive_Summary
A1: Wormhole — Bridge Bytecode Vulnerability Detection: Executive Summary
A3: KEY METRICS
A4: ="Addresses queried: "&COUNTA(Data!A2:A52)&" | Chains covered: 12" -> Addresses queried: 51 | Chains covered: 12
A5: ="Contracts with resolved bytecode: "&SUM(Data!C2:C52)&" | No bytecode (EOA/unverified): "&(COUNTA(Data!A2:A52)-SUM(Data!C2:C52)) -> Contracts with resolved bytecode: 25 | No bytecode (EOA/unverified): 26
A6: ="Overall vulnerable (>=1 tool): "&TEXT(Per_Vulnerability_Analysis!C15/Per_Vulnerability_Analysis!D15,"0.0%")&" of resolved contracts ("&Per_Vulnerability_Analysis!C15&"/"&Per_Vulnerability_Analysis!D15&")" -> Overall vulnerable (>=1 tool): 100.0% of resolved contracts (25/25)
A7: ="MAIAN flag rate: "&TEXT(Tool_Wise_Analysis!E4,"0.0%") -> MAIAN flag rate: 96.0%
A8: ="Mythril flag rate: "&TEXT(Tool_Wise_Analysis!E5,"0.0%") -> Mythril flag rate: 76.0%
A9: ="Tool agreement (Jaccard, MAIAN vs Mythril): "&TEXT(Agreement_Jaccard!B11,"0.0000") -> Tool agreement (Jaccard, MAIAN vs Mythril): 0.7200
A11: WHAT THE DATA SHOWS
A12: ="Highest-prevalence category: "&INDEX(Per_Vulnerability_Analysis!A5:A14,MATCH(MAX(Per_Vulnerability_Analysis!C5:C14),Per_Vulnerability_Analysis!C5:C14,0))&" ("&TEXT(MAX(Per_Vulnerability_Analysis!E5:E14),"0.0%")&" prevalence)" -> Highest-prevalence category: Ether Leak (96.0% prevalence)
A13: ="Only MAIAN and Mythril returned detections in this run; 7 of 11 tracked categories show zero hits — see Formula_Definitions / Per_Vulnerability_Analysis." -> Only MAIAN and Mythril returned detections in this run; 7 of 11 tracked categories show zero hits — see Formula_Definitions / Per_Vulnerability_Analysis.

Sheet Formula_Definitions
A1: Metric | B1: Formula | C1: Interpretation
A2: Detections D(v) | B2: COUNTIF(category_column, "<>") | C2: Number of contracts flagged for vulnerability v by its reporting tool
A3: Contracts w/ Bytecode | B3: SUM(Has_Bytecode) | C3: Denominator for prevalence; excludes EOA/unverified/no-code addresses
A4: Prevalence % | B4: D(v) / Contracts_w_Bytecode | C4: Share of resolved contracts flagged for category v
A5: Overall Vulnerable | B5: COUNTIFS(Has_Bytecode=1, Vulnerable="Yes") | C5: Contracts flagged by >=1 tool, among resolved contracts
A6: Flags per Contract | B6: COUNT of active categories triggered per row | C6: How many distinct categories fire on the same contract
A7: Tool Flag Rate % | B7: Tool-flagged contracts / Contracts w/ Bytecode | C7: Per-tool prevalence, independent of category breakdown
A8: Jaccard Index J(A,B) | B8: |A ∩ B| / |A ∪ B| | C8: Overlap between the two tools' flagged sets; 0=no overlap, 1=identical sets
A9: Vulnerable Rate % (chain) | B9: Vulnerable(chain) / With_Bytecode(chain) | C9: Per-chain share of resolved contracts flagged

Sheet Per_Vulnerability_Analysis
A1: Wormhole — Per-Vulnerability Analysis
A3: Category | B3: Detecting Tool | C3: Detections D(v) | D3: Contracts w/ Bytecode | E3: Prevalence % | F3: Note
A4: Reentrancy | B4: Not covered (0 detections) | C4: =COUNTIF(Data!E2:E52,"<>") -> 0 | D4: =SUM(Data!C2:C52) -> 25 | E4: =IF(D4=0,0,C4/D4) -> 0 | F4: Zero detections this run
A5: Integer | B5: Mythril | C5: =COUNTIF(Data!F2:F52,"<>") -> 18 | D5: =SUM(Data!C2:C52) -> 25 | E5: =IF(D5=0,0,C5/D5) -> 0.72 | F5: Bytecode-level detection
A6: Access Control | B6: Not covered (0 detections) | C6: =COUNTIF(Data!G2:G52,"<>") -> 0 | D6: =SUM(Data!C2:C52) -> 25 | E6: =IF(D6=0,0,C6/D6) -> 0 | F6: Zero detections this run
A7: Delegatecall | B7: Not covered (0 detections) | C7: =COUNTIF(Data!H2:H52,"<>") -> 0 | D7: =SUM(Data!C2:C52) -> 25 | E7: =IF(D7=0,0,C7/D7) -> 0 | F7: Zero detections this run
A8: Unchecked Call | B8: Not covered (0 detections) | C8: =COUNTIF(Data!I2:I52,"<>") -> 0 | D8: =SUM(Data!C2:C52) -> 25 | E8: =IF(D8=0,0,C8/D8) -> 0 | F8: Zero detections this run
A9: Timestamp | B9: Mythril | C9: =COUNTIF(Data!J2:J52,"<>") -> 14 | D9: =SUM(Data!C2:C52) -> 25 | E9: =IF(D9=0,0,C9/D9) -> 0.56 | F9: Bytecode-level detection
A10: TOD | B10: Not covered (0 detections) | C10: =COUNTIF(Data!K2:K52,"<>") -> 0 | D10: =SUM(Data!C2:C52) -> 25 | E10: =IF(D10=0,0,C10/D10) -> 0 | F10: Zero detections this run
A11: DoS | B11: Not covered (0 detections) | C11: =COUNTIF(Data!L2:L52,"<>") -> 0 | D11: =SUM(Data!C2:C52) -> 25 | E11: =IF(D11=0,0,C11/D11) -> 0 | F11: Zero detections this run
A12: Selfdestruct | B12: Not covered (0 detections) | C12: =COUNTIF(Data!M2:M52,"<>") -> 0 | D12: =SUM(Data!C2:C52) -> 25 | E12: =IF(D12=0,0,C12/D12) -> 0 | F12: Zero detections this run
A13: Locked Ether | B13: MAIAN | C13: =COUNTIF(Data!N2:N52,"<>") -> 3 | D13: =SUM(Data!C2:C52) -> 25 | E13: =IF(D13=0,0,C13/D13) -> 0.12 | F13: Bytecode-level detection
A14: Ether Leak | B14: MAIAN | C14: =COUNTIF(Data!O2:O52,"<>") -> 24 | D14: =SUM(Data!C2:C52) -> 25 | E14: =IF(D14=0,0,C14/D14) -> 0.96 | F14: Bytecode-level detection
A15: OVERALL VULNERABLE | B15: Any tool | C15: =COUNTIFS(Data!C2:C52,1,Data!P2:P52,"Yes") -> 25 | D15: =SUM(Data!C2:C52) -> 25 | E15: =IF(D15=0,0,C15/D15) -> 1 | F15: Flagged by >=1 tool

Sheet Detection_Count_Analysis
A1: Wormhole — Detection Count Analysis
A3: Flags per contract = count of (Integer, Timestamp, Locked Ether, Ether Leak) triggered on that contract
A5: Flags per Contract | B5: Contract Count | C5: % of Bytecode Contracts | D5: Note
A6: 0 categories flagged | B6: =SUMPRODUCT((Data!C2:C52=1)*(((Data!F2:F52<>"")+(Data!J2:J52<>"")+(Data!N2:N52<>"")+(Data!O2:O52<>""))=0)) -> 0 | C6: =IF(SUM(Data!C2:C52)=0,0,B6/SUM(Data!C2:C52)) -> 0
A7: 1 categories flagged | B7: =SUMPRODUCT((Data!C2:C52=1)*(((Data!F2:F52<>"")+(Data!J2:J52<>"")+(Data!N2:N52<>"")+(Data!O2:O52<>""))=1)) -> 4 | C7: =IF(SUM(Data!C2:C52)=0,0,B7/SUM(Data!C2:C52)) -> 0.16
A8: 2 categories flagged | B8: =SUMPRODUCT((Data!C2:C52=1)*(((Data!F2:F52<>"")+(Data!J2:J52<>"")+(Data!N2:N52<>"")+(Data!O2:O52<>""))=2)) -> 8 | C8: =IF(SUM(Data!C2:C52)=0,0,B8/SUM(Data!C2:C52)) -> 0.32
A9: 3 categories flagged | B9: =SUMPRODUCT((Data!C2:C52=1)*(((Data!F2:F52<>"")+(Data!J2:J52<>"")+(Data!N2:N52<>"")+(Data!O2:O52<>""))=3)) -> 13 | C9: =IF(SUM(Data!C2:C52)=0,0,B9/SUM(Data!C2:C52)) -> 0.52
A10: 4 categories flagged | B10: =SUMPRODUCT((Data!C2:C52=1)*(((Data!F2:F52<>"")+(Data!J2:J52<>"")+(Data!N2:N52<>"")+(Data!O2:O52<>""))=4)) -> 0 | C10: =IF(SUM(Data!C2:C52)=0,0,B10/SUM(Data!C2:C52)) -> 0
A11: Total contracts w/ bytecode | B11: =SUM(B6:B10) -> 25
A13: Total raw detections (sum across all 11 categories) | B13: =COUNTIF(Data!E2:E52,"<>")+COUNTIF(Data!F2:F52,"<>")+COUNTIF(Data!G2:G52,"<>")+COUNTIF(Data!H2:H52,"<>")+COUNTIF(Data!I2:I52,"<>")+COUNTIF(Data!J2:J52,"<>")+COUNTIF(Data!K2:K52,"<>")+COUNTIF(Data!L2:L52,"<>")+COUNTIF(Data!M2:M52,"<>")+COUNTIF(Data!N2:N52,"<>")+COUNTIF(Data!O2:O52,"<>") -> 59
A14: Avg detections per bytecode-resolved contract | B14: =B13/SUM(Data!C2:C52) -> 2.36

Sheet Tool_Wise_Analysis
A1: Wormhole — Tool-wise Analysis
A3: Tool | B3: Categories Covered | C3: Contracts Flagged | D3: Contracts w/ Bytecode | E3: Flag Rate % | F3: Note
A4: MAIAN | B4: Locked Ether, Ether Leak | C4: =SUM(Data!Q2:Q52) -> 24 | D4: =SUM(Data!C2:C52) -> 25 | E4: =IF(D4=0,0,C4/D4) -> 0.96 | F4: Symbolic execution, financial-flow analysis
A5: Mythril | B5: Integer, Timestamp | C5: =SUM(Data!R2:R52) -> 19 | D5: =SUM(Data!C2:C52) -> 25 | E5: =IF(D5=0,0,C5/D5) -> 0.76 | F5: Bytecode symbolic execution
A6: Others (n/a) | B6: Reentrancy, Access Control, Delegatecall, Unchecked Call, TOD, DoS, Selfdestruct | C6: 0 | D6: =SUM(Data!C2:C52) -> 25 | E6: 0 | F6: Zero detections in this run

Sheet Contract_Level_Statistics
A1: Wormhole — Contract-Level Statistics
A3: Addresses queried | B3: =COUNTA(Data!A2:A52) -> 51
A4: Chains covered | B4: 12
A5: Contracts analyzed (bytecode resolved / detection ran) | B5: =SUM(Data!C2:C52) -> 25
A6: Not analyzed (EOA / unverified / not found) | B6: =COUNTA(Data!A2:A52)-SUM(Data!C2:C52) -> 26
A7: ...of which bytecode text is blank in source export | B7: =SUMPRODUCT((Data!C2:C52=1)*(Data!D2:D52=0)) -> 0 | D7: Detections still recorded; only the raw bytecode string is missing from the export
A8: Avg bytecode length (hex chars, where text available) | B8: =IF(SUMPRODUCT((Data!C2:C52=1)*(Data!D2:D52>0))=0,0,SUMIF(Data!C2:C52,1,Data!D2:D52)/SUMPRODUCT((Data!C2:C52=1)*(Data!D2:D52>0))) -> 3867.68 | D8: Rounded to nearest char; excludes blank-text rows
A9: Min bytecode length (where text available) | B9: =_xlfn.MINIFS(Data!D2:D52,Data!C2:C52,1,Data!D2:D52,">0") -> 1362
A10: Max bytecode length | B10: =_xlfn.MAXIFS(Data!D2:D52,Data!C2:C52,1) -> 6818
A12: Per-Chain Breakdown
A13: Chain | B13: Addresses | C13: With Bytecode | D13: Vulnerable Rate %
A14: arbitrum | B14: =COUNTIF(Data!B2:B52,A14) -> 7 | C14: =COUNTIFS(Data!B2:B52,A14,Data!C2:C52,1) -> 3 | D14: =IF(C14=0,0,(COUNTIFS(Data!B2:B52,A14,Data!C2:C52,1,Data!P2:P52,"Yes"))/C14) -> 1
A15: berachain | B15: =COUNTIF(Data!B2:B52,A15) -> 4 | C15: =COUNTIFS(Data!B2:B52,A15,Data!C2:C52,1) -> 2 | D15: =IF(C15=0,0,(COUNTIFS(Data!B2:B52,A15,Data!C2:C52,1,Data!P2:P52,"Yes"))/C15) -> 1
A16: blast | B16: =COUNTIF(Data!B2:B52,A16) -> 3 | C16: =COUNTIFS(Data!B2:B52,A16,Data!C2:C52,1) -> 1 | D16: =IF(C16=0,0,(COUNTIFS(Data!B2:B52,A16,Data!C2:C52,1,Data!P2:P52,"Yes"))/C16) -> 1
A17: celo | B17: =COUNTIF(Data!B2:B52,A17) -> 4 | C17: =COUNTIFS(Data!B2:B52,A17,Data!C2:C52,1) -> 1 | D17: =IF(C17=0,0,(COUNTIFS(Data!B2:B52,A17,Data!C2:C52,1,Data!P2:P52,"Yes"))/C17) -> 1
A18: ethereum | B18: =COUNTIF(Data!B2:B52,A18) -> 11 | C18: =COUNTIFS(Data!B2:B52,A18,Data!C2:C52,1) -> 6 | D18: =IF(C18=0,0,(COUNTIFS(Data!B2:B52,A18,Data!C2:C52,1,Data!P2:P52,"Yes"))/C18) -> 1
A19: mantle | B19: =COUNTIF(Data!B2:B52,A19) -> 3 | C19: =COUNTIFS(Data!B2:B52,A19,Data!C2:C52,1) -> 1 | D19: =IF(C19=0,0,(COUNTIFS(Data!B2:B52,A19,Data!C2:C52,1,Data!P2:P52,"Yes"))/C19) -> 1
A20: moonbeam | B20: =COUNTIF(Data!B2:B52,A20) -> 5 | C20: =COUNTIFS(Data!B2:B52,A20,Data!C2:C52,1) -> 2 | D20: =IF(C20=0,0,(COUNTIFS(Data!B2:B52,A20,Data!C2:C52,1,Data!P2:P52,"Yes"))/C20) -> 1
A21: polygon | B21: =COUNTIF(Data!B2:B52,A21) -> 7 | C21: =COUNTIFS(Data!B2:B52,A21,Data!C2:C52,1) -> 4 | D21: =IF(C21=0,0,(COUNTIFS(Data!B2:B52,A21,Data!C2:C52,1,Data!P2:P52,"Yes"))/C21) -> 1
A22: sei | B22: =COUNTIF(Data!B2:B52,A22) -> 1 | C22: =COUNTIFS(Data!B2:B52,A22,Data!C2:C52,1) -> 1 | D22: =IF(C22=0,0,(COUNTIFS(Data!B2:B52,A22,Data!C2:C52,1,Data!P2:P52,"Yes"))/C22) -> 1
A23: sonic | B23: =COUNTIF(Data!B2:B52,A23) -> 1 | C23: =COUNTIFS(Data!B2:B52,A23,Data!C2:C52,1) -> 1 | D23: =IF(C23=0,0,(COUNTIFS(Data!B2:B52,A23,Data!C2:C52,1,Data!P2:P52,"Yes"))/C23) -> 1
A24: unichain | B24: =COUNTIF(Data!B2:B52,A24) -> 2 | C24: =COUNTIFS(Data!B2:B52,A24,Data!C2:C52,1) -> 2 | D24: =IF(C24=0,0,(COUNTIFS(Data!B2:B52,A24,Data!C2:C52,1,Data!P2:P52,"Yes"))/C24) -> 1
A25: world_chain | B25: =COUNTIF(Data!B2:B52,A25) -> 3 | C25: =COUNTIFS(Data!B2:B52,A25,Data!C2:C52,1) -> 1 | D25: =IF(C25=0,0,(COUNTIFS(Data!B2:B52,A25,Data!C2:C52,1,Data!P2:P52,"Yes"))/C25) -> 1

Sheet Agreement_Jaccard
A1: Wormhole — Tool Agreement (Jaccard Index)
A2: Agreement between MAIAN and Mythril, among contracts with bytecode.
A4: Set | B4: Count | C4: % of Bytecode Contracts | D4: Definition
A5: Both tools flag (A ∩ B) | B5: =SUMPRODUCT((Data!C2:C52=1)*(Data!Q2:Q52=1)*(Data!R2:R52=1)) -> 18 | C5: =IF(SUM(Data!C2:C52)=0,0,B5/SUM(Data!C2:C52)) -> 0.72 | D5: MAIAN AND Mythril
A6: Only MAIAN flags (A \ B) | B6: =SUMPRODUCT((Data!C2:C52=1)*(Data!Q2:Q52=1)*(Data!R2:R52=0)) -> 6 | C6: =IF(SUM(Data!C2:C52)=0,0,B6/SUM(Data!C2:C52)) -> 0.24 | D6: MAIAN only
A7: Only Mythril flags (B \ A) | B7: =SUMPRODUCT((Data!C2:C52=1)*(Data!Q2:Q52=0)*(Data!R2:R52=1)) -> 1 | C7: =IF(SUM(Data!C2:C52)=0,0,B7/SUM(Data!C2:C52)) -> 0.04 | D7: Mythril only
A8: Neither flags | B8: =SUMPRODUCT((Data!C2:C52=1)*(Data!Q2:Q52=0)*(Data!R2:R52=0)) -> 0 | C8: =IF(SUM(Data!C2:C52)=0,0,B8/SUM(Data!C2:C52)) -> 0 | D8: Resolved contract, no flag from either tool
A10: Union (A ∪ B) | B10: =B5+B6+B7 -> 25
A11: Jaccard Index J(A,B) = |A∩B| / |A∪B| | B11: =IF(B10=0,0,B5/B10) -> 0.72

Sheet Key_Findings
A1: Wormhole — Key Findings
A3: ="1. Bytecode resolution: "&SUM(Data!C2:C52)&" of "&COUNTA(Data!A2:A52)&" queried addresses ("&TEXT(SUM(Data!C2:C52)/COUNTA(Data!A2:A52),"0.0%")&") resolved to deployed bytecode; the rest are EOAs, unverified, or not found on-chain." -> 1. Bytecode resolution: 25 of 51 queried addresses (49.0%) resolved to deployed bytecode; the rest are EOAs, unverified, or not found on-chain.
A4: ="2. Detection coverage: only MAIAN and Mythril produced any detections. Reentrancy, Access Control, Delegatecall, Unchecked Call, TOD, DoS, Selfdestruct all show zero hits in this bytecode run." -> 2. Detection coverage: only MAIAN and Mythril produced any detections. Reentrancy, Access Control, Delegatecall, Unchecked Call, TOD, DoS, Selfdestruct all show zero hits in this bytecode run.
A5: ="3. Mythril flag rate ("&TEXT(Tool_Wise_Analysis!E5,"0.0%")&") vs MAIAN flag rate ("&TEXT(Tool_Wise_Analysis!E4,"0.0%")&") among resolved contracts." -> 3. Mythril flag rate (76.0%) vs MAIAN flag rate (96.0%) among resolved contracts.
A6: ="4. Tool overlap: Jaccard(MAIAN, Mythril) = "&TEXT(Agreement_Jaccard!B11,"0.0000")&" — "&Agreement_Jaccard!B5&" contracts triggered both tools, "&Agreement_Jaccard!B6&" only MAIAN, "&Agreement_Jaccard!B7&" only Mythril." -> 4. Tool overlap: Jaccard(MAIAN, Mythril) = 0.7200 — 18 contracts triggered both tools, 6 only MAIAN, 1 only Mythril.
A7: ="5. "&Per_Vulnerability_Analysis!C15&" of "&Per_Vulnerability_Analysis!D15&" resolved contracts ("&TEXT(Per_Vulnerability_Analysis!C15/Per_Vulnerability_Analysis!D15,"0.0%")&") were flagged by at least one tool." -> 5. 25 of 25 resolved contracts (100.0%) were flagged by at least one tool.

Sheet Why_These_Results
A1: Wormhole — Why These Results: Forensic Explanation of the Detection Pattern
A2: Findings below are derived from direct inspection of the raw deployed bytecode (length, opcode counts, function-selector signatures) behind this protocol's CSV, not just the tool output.
A4: 1. WHY THE ANALYZED RATE IS 49.0%
A5: Of 51 addresses queried for Wormhole, 25 (49.0%) resolved to a contract with recorded detection results. The remainder are addresses listed in the bridge's cross-chain registry that do not currently hold deployed bytecode on the chain they're paired with in the source data.
A6: This is a registry-completeness artifact, not a tool failure: cross-chain bridge protocols typically reserve or intend the SAME contract address across every supported chain (often via CREATE2 deterministic deployment), but do not necessarily deploy on all of them at the same time - some chains get the contract later, some never, and some registries list planned/future chains. A low analyzed rate signals partial rollout, not analysis error.
A8: 2. PROXY-PATTERN CONTRACTS AND THEIR EFFECT ON DETECTION
A9: No UUPS/ERC-1967 proxy selectors were found in any of the 25 analyzed Wormhole contracts' bytecode - these appear to be full logic contracts rather than thin proxies, which is consistent with every analyzed contract exposing enough arithmetic/ether-handling surface for the tools to flag something.
A11: 3. WHY MAIAN FIRES MORE OFTEN THAN MYTHRIL
A12: In this protocol, MAIAN's flag rate (96.0%) is higher than Mythril's (76.0%), with tool agreement (Jaccard) of 0.7200. This asymmetry appears consistently across all 5 protocols in this dataset and has two likely structural causes:
A13: (a) Mythril's Integer category targets classic integer overflow/underflow. Solidity >=0.8.0 added automatic overflow/underflow reverts at the compiler level, so this entire bug class is largely closed off in modern contracts unless the code explicitly uses an `unchecked{}` block. Bridge contracts deployed in the last 2-3 years are predominantly 0.8.x, which suppresses Mythril's hit rate by design, not by absence of scrutiny.
A14: (b) MAIAN's Locked_Ether/Ether_Leak checks flag any contract that can receive ETH but lacks a statically-provable unconditional withdrawal path. Bridge contracts almost always accept native-token value (bridging fees, wrapped-native deposits) and almost never expose a simple public withdraw() - value moves through multi-step, permissioned, or cross-contract release logic that MAIAN's local analysis cannot fully trace. This makes MAIAN's categories structurally prone to firing on this entire class of contract, independent of whether a real fund-locking bug exists.
A16: 4. WHY "ETHER LEAK" IS THE TOP CATEGORY HERE
... A23: Wormhole's 100.0% vulnerable rate reflects near-universal MAIAN Locked_Ether/Ether_Leak flags on payable, complex-withdrawal-path bridge contracts, compounded by a negligible share of proxy-pattern contracts that are not present here to dilute the rate. This is consistent with a tool-heuristic effect at least as much as a genuine vulnerability signal - see Formula_Definitions in the individual report and the Combined_Bridge_Vulnerability_Report for the cross-protocol pattern.

Sheet Data
A1: Address | B1: Chain | C1: Has_Bytecode | D1: Bytecode_Length | E1: Reentrancy | F1: Integer | G1: Access_Control | H1: Delegatecall | I1: Unchecked_Call | J1: Timestamp | K1: TOD | L1: DoS | M1: Selfdestruct | N1: Locked_Ether | O1: Ether_Leak | P1: Vulnerable | Q1: MAIAN_Flag | R1: Mythril_Flag
A2: arbitrum_0x0b2402144Bb366A632D14B83F244D2e0e21bD39c | B2: arbitrum | C2: 0 | D2: 0 | P2: No | Q2: 0 | R2: 0
A3: arbitrum_0x2703483B1a5a7c577e8680de9Df8Be03c6f30e3c | B3: arbitrum | C3: 0 | D3: 0 | P3: No | Q3: 0 | R3: 0
A4: arbitrum_0x32eec14c963c23176bd8951f192292006756bDcC | B4: arbitrum | C4: 1 | D4: 4844 | F4: Mythril | J4: Mythril | O4: MAIAN | P4: Yes | Q4: 1 | R4: 1
A5: arbitrum_0x36CF4c88FA548c6Ad9fcDc696e1c27Bb3306163F | B5: arbitrum | C5: 1 | D5: 6818 | F5: Mythril | O5: MAIAN | P5: Yes | Q5: 1 | R5: 1
A6: arbitrum_0x3980f8318fc03d79033Bbb421A622CDF8d2Eeab4 | B6: arbitrum | C6: 1 | D6: 1924 | F6: Mythril | J6: Mythril | O6: MAIAN | P6: Yes | Q6: 1 | R6: 1
A7: arbitrum_0x3dD14D553cFD986EAC8e3bddF629d82073e188c8 | B7: arbitrum | C7: 0 | D7: 0 | P7: No | Q7: 0 | R7: 0
A8: arbitrum_0xa5f208e072434bC67592E4C49C1B991BA79BCA46 | B8: arbitrum | C8: 0 | D8: 0 | P8: No | Q8: 0 | R8: 0
A9: berachain_0x0Dd7a5a32311b8D87A615Cc7f079B632D3d5e2D3 | B9: berachain | C9: 1 | D9: 1924 | F9: Mythril | J9: Mythril | O9: MAIAN | P9: Yes | Q9: 1 | R9: 1
A10: berachain_0x3Ff72741fd67D6AD0668d93B41a09248F4700560 | B10: berachain | C10: 0 | D10: 0 | P10: No | Q10: 0 | R10: 0
A11: berachain_0x6969696969696969696969696969696969696969 | B11: berachain | C11: 1 | D11: 5194 | J11: Mythril | O11: MAIAN | P11: Yes | Q11: 1 | R11: 1
A12: berachain_0xCa1D5a146B03f6303baF59e5AD5615ae0b9d146D | B12: berachain | C12: 0 | D12: 0 | P12: No | Q12: 0 | R12: 0
A13: blast_0x24850c6f61C438823F01B7A3BF2B89B72174Fa9d | B13: blast | C13: 1 | D13: 1362 | O13: MAIAN | P13: Yes | Q13: 1 | R13: 0
A14: blast_0x9D020B1697035d9d54f115194c9e04a1e4Eb9aF7 | B14: blast | C14: 0 | D14: 0 | P14: No | Q14: 0 | R14: 0
A15: blast_0xbebdb6C8ddC678FfA9f8748f85C815C556Dd8ac6 | B15: blast | C15: 0 | D15: 0 | P15: No | Q15: 0 | R15: 0
A16: celo_0x796Dff6D74F3E27060B71255Fe517BFb23C93eed | B16: celo | C16: 0 | D16: 0 | P16: No | Q16: 0 | R16: 0
A17: celo_0xA6A377d75ca5c9052c9a77ED1e865Cc25Bd97bf3 | B17: celo | C17: 0 | D17: 0 | P17: No | Q17: 0 | R17: 0
A18: celo_0xa321448d90d4e5b0A732867c18eA198e75CAC48E | B18: celo | C18: 0 | D18: 0 | P18: No | Q18: 0 | R18: 0
A19: celo_0xe6Ea5087c6860B94Cf098a403506262D8F28cF05 | B19: celo | C19: 1 | D19: 1924 | F19: Mythril | J19: Mythril | O19: MAIAN | P19: Yes | Q19: 1 | R19: 1
A20: ethereum_0x1462800febd49232798132e8c8b721aa86c4c209 | B20: ethereum | C20: 0 | D20: 0 | P20: No | Q20: 0 | R20: 0
A21: ethereum_0x23Fea5514DFC9821479fBE18BA1D7e1A61f6FfCf | B21: ethereum | C21: 1 | D21: 6818 | F21: Mythril | O21: MAIAN | P21: Yes | Q21: 1 | R21: 1
A22: ethereum_0x3ee18B2214AFF97000D974cf647E7C347E8fa585 | B22: ethereum | C22: 0 | D22: 0 | P22: No | Q22: 0 | R22: 0
A23: ethereum_0x6FFd7EdE62328b3Af38FCD61461Bbfc52F5651fE | B23: ethereum | C23: 0 | D23: 0 | P23: No | Q23: 0 | R23: 0
A24: ethereum_0x70287c79ee41C5D1df8259Cd68Ba0890cd389c47 | B24: ethereum | C24: 0 | D24: 0 | P24: No | Q24: 0 | R24: 0
A25: ethereum_0x84EEe8dBa37C36947397E1E11251cA9A06Fc6F8a | B25: ethereum | C25: 1 | D25: 1924 | F25: Mythril | J25: Mythril | O25: MAIAN | P25: Yes | Q25: 1 | R25: 1
A26: ethereum_0x98f3c9e6E3fAce36bAAd05FE09d375Ef1464288B | B26: ethereum | C26: 1 | D26: 1362 | O26: MAIAN | P26: Yes | Q26: 1 | R26: 0
A27: ethereum_0xA25862D222Eb8343505c12d96e097e4332468D60 | B27: ethereum | C27: 1 | D27: 5024 | F27: Mythril | P27: Yes | Q27: 0 | R27: 1
A28: ethereum_0xAaDA05BD399372f0b0463744C09113c137636f6a | B28: ethereum | C28: 0 | D28: 0 | P28: No | Q28: 0 | R28: 0
A29: ethereum_0xC02aaA39b223FE8D0A0e5C4F27eAD9083C756Cc2 | B29: ethereum | C29: 1 | D29: 6250 | N29: MAIAN | O29: MAIAN | P29: Yes | Q29: 1 | R29: 0
A30: ethereum_0xF22F1c0A3a8Cb42F695601731974784C499C4EF3 | B30: ethereum | C30: 1 | D30: 4844 | F30: Mythril | J30: Mythril | O30: MAIAN | P30: Yes | Q30: 1 | R30: 1
A31: mantle_0x24850c6f61C438823F01B7A3BF2B89B72174Fa9d | B31: mantle | C31: 0 | D31: 0 | P31: No | Q31: 0 | R31: 0
A32: mantle_0x78c1b0C915c4FAA5FffA6CAbf0219DA63d7f4cb8 | B32: mantle | C32: 1 | D32: 6642 | F32: Mythril | O32: MAIAN | P32: Yes | Q32: 1 | R32: 1
A33: mantle_0xbebdb6C8ddC678FfA9f8748f85C815C556Dd8ac6 | B33: mantle | C33: 0 | D33: 0 | P33: No | Q33: 0 | R33: 0
A34: moonbeam_0x453cfbe096c0f8d763e8c5f24b441097d577bde2 | B34: moonbeam | C34: 0 | D34: 0 | P34: No | Q34: 0 | R34: 0
A35: moonbeam_0x85D06449C78064c2E02d787e9DC71716786F8D19 | B35: moonbeam | C35: 1 | D35: 1924 | F35: Mythril | J35: Mythril | O35: MAIAN | P35: Yes | Q35: 1 | R35: 1
A36: moonbeam_0xAcc15dC74880C9944775448304B263D191c6077F | B36: moonbeam | C36: 1 | D36: 6250 | N36: MAIAN | O36: MAIAN | P36: Yes | Q36: 1 | R36: 0
A37: moonbeam_0xC8e2b0cD52Cf01b0Ce87d389Daa3d414d4cE29f3 | B37: moonbeam | C37: 0 | D37: 0 | P37: No | Q37: 0 | R37: 0
A38: moonbeam_0xb1731c586ca89a23809861c6103f0b96b3f57d92 | B38: moonbeam | C38: 0 | D38: 0 | P38: No | Q38: 0 | R38: 0
A39: polygon_0x0B23efA164aB3eD08e9a39AC7aD930Ff4F5A5e81 | B39: polygon | C39: 1 | D39: 1924 | F39: Mythril | J39: Mythril | O39: MAIAN | P39: Yes | Q39: 1 | R39: 1
A40: polygon_0x0FF28217dCc90372345954563486528aa865cDd6 | B40: polygon | C40: 0 | D40: 0 | P40: No | Q40: 0 | R40: 0
...
