Workbook

Sheet Executive_Summary
A1: Axelar_Obfuscated — Bridge Bytecode Vulnerability Detection: Executive Summary
A3: KEY METRICS
A4: ="Addresses queried: "&COUNTA(Data!A2:A266)&" | Chains covered: 26" -> Addresses queried: 265 | Chains covered: 26
A5: ="Contracts with resolved bytecode: "&SUM(Data!C2:C266)&" | No bytecode (EOA/unverified): "&(COUNTA(Data!A2:A266)-SUM(Data!C2:C266)) -> Contracts with resolved bytecode: 265 | No bytecode (EOA/unverified): 0
A6: ="Overall vulnerable (>=1 tool): "&TEXT(Per_Vulnerability_Analysis!C15/Per_Vulnerability_Analysis!D15,"0.0%")&" of resolved contracts ("&Per_Vulnerability_Analysis!C15&"/"&Per_Vulnerability_Analysis!D15&")" -> Overall vulnerable (>=1 tool): 7.2% of resolved contracts (19/265)
A7: ="Mythril flag rate: "&TEXT(Tool_Wise_Analysis!E4,"0.0%") -> Mythril flag rate: 7.2%
A9: WHAT THE DATA SHOWS
A10: ="Highest-prevalence category: "&INDEX(Per_Vulnerability_Analysis!A11:A11,MATCH(MAX(Per_Vulnerability_Analysis!C11:C11),Per_Vulnerability_Analysis!C11:C11,0))&" ("&TEXT(MAX(Per_Vulnerability_Analysis!E11:E11),"0.0%")&" prevalence)" -> Highest-prevalence category: DoS (7.2% prevalence)
A11: ="Only Mythril returned detections in this run; 10 of 11 tracked categories show zero hits — see Formula_Definitions / Per_Vulnerability_Analysis." -> Only Mythril returned detections in this run; 10 of 11 tracked categories show zero hits — see Formula_Definitions / Per_Vulnerability_Analysis.

Sheet Formula_Definitions
A1: Metric | B1: Formula | C1: Interpretation
A2: Detections D(v) | B2: COUNTIF(category_column, "<>") | C2: Number of contracts flagged for vulnerability v by its reporting tool
A3: Contracts w/ Bytecode | B3: SUM(Has_Bytecode) | C3: Denominator for prevalence; excludes EOA/unverified/no-code addresses
A4: Prevalence % | B4: D(v) / Contracts_w_Bytecode | C4: Share of resolved contracts flagged for category v
A5: Overall Vulnerable | B5: COUNTIFS(Has_Bytecode=1, Vulnerable="Yes") | C5: Contracts flagged by >=1 tool, among resolved contracts
A6: Flags per Contract | B6: COUNT of active categories triggered per row | C6: How many distinct categories fire on the same contract
A7: Tool Flag Rate % | B7: Tool-flagged contracts / Contracts w/ Bytecode | C7: Per-tool prevalence, independent of category breakdown
A8: Jaccard Index J(A,B) | B8: |A ∩ B| / |A ∪ B| | C8: Overlap between the two tools' flagged sets; 0=no overlap, 1=identical sets
A9: Vulnerable Rate % (chain) | B9: Vulnerable(chain) / With_Bytecode(chain) | C9: Per-chain share of resolved contracts flagged

Sheet Per_Vulnerability_Analysis
A1: Axelar_Obfuscated — Per-Vulnerability Analysis
A3: Category | B3: Detecting Tool | C3: Detections D(v) | D3: Contracts w/ Bytecode | E3: Prevalence % | F3: Note
A4: Reentrancy | B4: Not covered (0 detections) | C4: =COUNTIF(Data!E2:E266,"<>") -> 0 | D4: =SUM(Data!C2:C266) -> 265 | E4: =IF(D4=0,0,C4/D4) -> 0 | F4: Zero detections this run
A5: Integer | B5: Not covered (0 detections) | C5: =COUNTIF(Data!F2:F266,"<>") -> 0 | D5: =SUM(Data!C2:C266) -> 265 | E5: =IF(D5=0,0,C5/D5) -> 0 | F5: Zero detections this run
A6: Access Control | B6: Not covered (0 detections) | C6: =COUNTIF(Data!G2:G266,"<>") -> 0 | D6: =SUM(Data!C2:C266) -> 265 | E6: =IF(D6=0,0,C6/D6) -> 0 | F6: Zero detections this run
A7: Delegatecall | B7: Not covered (0 detections) | C7: =COUNTIF(Data!H2:H266,"<>") -> 0 | D7: =SUM(Data!C2:C266) -> 265 | E7: =IF(D7=0,0,C7/D7) -> 0 | F7: Zero detections this run
A8: Unchecked Call | B8: Not covered (0 detections) | C8: =COUNTIF(Data!I2:I266,"<>") -> 0 | D8: =SUM(Data!C2:C266) -> 265 | E8: =IF(D8=0,0,C8/D8) -> 0 | F8: Zero detections this run
A9: Timestamp | B9: Not covered (0 detections) | C9: =COUNTIF(Data!J2:J266,"<>") -> 0 | D9: =SUM(Data!C2:C266) -> 265 | E9: =IF(D9=0,0,C9/D9) -> 0 | F9: Zero detections this run
A10: TOD | B10: Not covered (0 detections) | C10: =COUNTIF(Data!K2:K266,"<>") -> 0 | D10: =SUM(Data!C2:C266) -> 265 | E10: =IF(D10=0,0,C10/D10) -> 0 | F10: Zero detections this run
A11: DoS | B11: Mythril | C11: =COUNTIF(Data!L2:L266,"<>") -> 19 | D11: =SUM(Data!C2:C266) -> 265 | E11: =IF(D11=0,0,C11/D11) -> 0.071698113 | F11: Bytecode-level detection
A12: Selfdestruct | B12: Not covered (0 detections) | C12: =COUNTIF(Data!M2:M266,"<>") -> 0 | D12: =SUM(Data!C2:C266) -> 265 | E12: =IF(D12=0,0,C12/D12) -> 0 | F12: Zero detections this run
A13: Locked Ether | B13: Not covered (0 detections) | C13: =COUNTIF(Data!N2:N266,"<>") -> 0 | D13: =SUM(Data!C2:C266) -> 265 | E13: =IF(D13=0,0,C13/D13) -> 0 | F13: Zero detections this run
A14: Ether Leak | B14: Not covered (0 detections) | C14: =COUNTIF(Data!O2:O266,"<>") -> 0 | D14: =SUM(Data!C2:C266) -> 265 | E14: =IF(D14=0,0,C14/D14) -> 0 | F14: Zero detections this run
A15: OVERALL VULNERABLE | B15: Any tool | C15: =COUNTIFS(Data!C2:C266,1,Data!P2:P266,"Yes") -> 19 | D15: =SUM(Data!C2:C266) -> 265 | E15: =IF(D15=0,0,C15/D15) -> 0.071698113 | F15: Flagged by >=1 tool

Sheet Detection_Count_Analysis
A1: Axelar_Obfuscated — Detection Count Analysis
A3: Flags per contract = count of (DoS) triggered on that contract
A5: Flags per Contract | B5: Contract Count | C5: % of Bytecode Contracts | D5: Note
A6: 0 categories flagged | B6: =SUMPRODUCT((Data!C2:C266=1)*(((Data!L2:L266<>""))=0)) -> 246 | C6: =IF(SUM(Data!C2:C266)=0,0,B6/SUM(Data!C2:C266)) -> 0.92830189
A7: 1 categories flagged | B7: =SUMPRODUCT((Data!C2:C266=1)*(((Data!L2:L266<>""))=1)) -> 19 | C7: =IF(SUM(Data!C2:C266)=0,0,B7/SUM(Data!C2:C266)) -> 0.071698113
A8: Total contracts w/ bytecode | B8: =SUM(B6:B7) -> 265
A10: Total raw detections (sum across all 11 categories) | B10: =COUNTIF(Data!E2:E266,"<>")+COUNTIF(Data!F2:F266,"<>")+COUNTIF(Data!G2:G266,"<>")+COUNTIF(Data!H2:H266,"<>")+COUNTIF(Data!I2:I266,"<>")+COUNTIF(Data!J2:J266,"<>")+COUNTIF(Data!K2:K266,"<>")+COUNTIF(Data!L2:L266,"<>")+COUNTIF(Data!M2:M266,"<>")+COUNTIF(Data!N2:N266,"<>")+COUNTIF(Data!O2:O266,"<>") -> 19
A11: Avg detections per bytecode-resolved contract | B11: =B10/SUM(Data!C2:C266) -> 0.071698113

Sheet Tool_Wise_Analysis
A1: Axelar_Obfuscated — Tool-wise Analysis
A3: Tool | B3: Categories Covered | C3: Contracts Flagged | D3: Contracts w/ Bytecode | E3: Flag Rate % | F3: Note
A4: Mythril | B4: DoS | C4: =SUM(Data!Q2:Q266) -> 19 | D4: =SUM(Data!C2:C266) -> 265 | E4: =IF(D4=0,0,C4/D4) -> 0.071698113 | F4: Bytecode symbolic execution
A5: Others (n/a) | B5: Reentrancy, Integer, Access Control, Delegatecall, Unchecked Call, Timestamp, TOD, Selfdestruct, Locked Ether, Ether Leak | C5: 0 | D5: =SUM(Data!C2:C266) -> 265 | E5: 0 | F5: Zero detections in this run

Sheet Contract_Level_Statistics
A1: Axelar_Obfuscated — Contract-Level Statistics
A3: Addresses queried | B3: =COUNTA(Data!A2:A266) -> 265
A4: Chains covered | B4: 26
A5: Contracts analyzed (bytecode resolved / detection ran) | B5: =SUM(Data!C2:C266) -> 265
A6: Not analyzed (EOA / unverified / not found) | B6: =COUNTA(Data!A2:A266)-SUM(Data!C2:C266) -> 0
A7: ...of which bytecode text is blank in source export | B7: =SUMPRODUCT((Data!C2:C266=1)*(Data!D2:D266=0)) -> 0 | D7: Detections still recorded; only the raw bytecode string is missing from the export
A8: Avg bytecode length (hex chars, where text available) | B8: =IF(SUMPRODUCT((Data!C2:C266=1)*(Data!D2:D266>0))=0,0,SUMIF(Data!C2:C266,1,Data!D2:D266)/SUMPRODUCT((Data!C2:C266=1)*(Data!D2:D266>0))) -> 333.75849 | D8: Rounded to nearest char; excludes blank-text rows
A9: Min bytecode length (where text available) | B9: =_xlfn.MINIFS(Data!D2:D266,Data!C2:C266,1,Data!D2:D266,">0") -> 5
A10: Max bytecode length | B10: =_xlfn.MAXIFS(Data!D2:D266,Data!C2:C266,1) -> 1579
A12: Per-Chain Breakdown
A13: Chain | B13: Addresses | C13: With Bytecode | D13: Vulnerable Rate %
A14: arbitrum | B14: =COUNTIF(Data!B2:B266,A14) -> 11 | C14: =COUNTIFS(Data!B2:B266,A14,Data!C2:C266,1) -> 11 | D14: =IF(C14=0,0,(COUNTIFS(Data!B2:B266,A14,Data!C2:C266,1,Data!P2:P266,"Yes"))/C14) -> 0.090909091
A15: arbitrum-sepolia | B15: =COUNTIF(Data!B2:B266,A15) -> 9 | C15: =COUNTIFS(Data!B2:B266,A15,Data!C2:C266,1) -> 9 | D15: =IF(C15=0,0,(COUNTIFS(Data!B2:B266,A15,Data!C2:C266,1,Data!P2:P266,"Yes"))/C15) -> 0.11111111
A16: avalanche | B16: =COUNTIF(Data!B2:B266,A16) -> 14 | C16: =COUNTIFS(Data!B2:B266,A16,Data!C2:C266,1) -> 14 | D16: =IF(C16=0,0,(COUNTIFS(Data!B2:B266,A16,Data!C2:C266,1,Data!P2:P266,"Yes"))/C16) -> 0
A17: base | B17: =COUNTIF(Data!B2:B266,A17) -> 12 | C17: =COUNTIFS(Data!B2:B266,A17,Data!C2:C266,1) -> 12 | D17: =IF(C17=0,0,(COUNTIFS(Data!B2:B266,A17,Data!C2:C266,1,Data!P2:P266,"Yes"))/C17) -> 0
A18: base-sepolia | B18: =COUNTIF(Data!B2:B266,A18) -> 9 | C18: =COUNTIFS(Data!B2:B266,A18,Data!C2:C266,1) -> 9 | D18: =IF(C18=0,0,(COUNTIFS(Data!B2:B266,A18,Data!C2:C266,1,Data!P2:P266,"Yes"))/C18) -> 0.11111111
A19: berachain | B19: =COUNTIF(Data!B2:B266,A19) -> 8 | C19: =COUNTIFS(Data!B2:B266,A19,Data!C2:C266,1) -> 8 | D19: =IF(C19=0,0,(COUNTIFS(Data!B2:B266,A19,Data!C2:C266,1,Data!P2:P266,"Yes"))/C19) -> 0.25
A20: binance | B20: =COUNTIF(Data!B2:B266,A20) -> 16 | C20: =COUNTIFS(Data!B2:B266,A20,Data!C2:C266,1) -> 16 | D20: =IF(C20=0,0,(COUNTIFS(Data!B2:B266,A20,Data!C2:C266,1,Data!P2:P266,"Yes"))/C20) -> 0
A21: blast | B21: =COUNTIF(Data!B2:B266,A21) -> 9 | C21: =COUNTIFS(Data!B2:B266,A21,Data!C2:C266,1) -> 9 | D21: =IF(C21=0,0,(COUNTIFS(Data!B2:B266,A21,Data!C2:C266,1,Data!P2:P266,"Yes"))/C21) -> 0.11111111
A22: blast-sepolia | B22: =COUNTIF(Data!B2:B266,A22) -> 9 | C22: =COUNTIFS(Data!B2:B266,A22,Data!C2:C266,1) -> 9 | D22: =IF(C22=0,0,(COUNTIFS(Data!B2:B266,A22,Data!C2:C266,1,Data!P2:P266,"Yes"))/C22) -> 0.11111111
A23: celo | B23: =COUNTIF(Data!B2:B266,A23) -> 11 | C23: =COUNTIFS(Data!B2:B266,A23,Data!C2:C266,1) -> 11 | D23: =IF(C23=0,0,(COUNTIFS(Data!B2:B266,A23,Data!C2:C266,1,Data!P2:P266,"Yes"))/C23) -> 0.090909091
A24: celo-sepolia | B24: =COUNTIF(Data!B2:B266,A24) -> 8 | C24: =COUNTIFS(Data!B2:B266,A24,Data!C2:C266,1) -> 8 | D24: =IF(C24=0,0,(COUNTIFS(Data!B2:B266,A24,Data!C2:C266,1,Data!P2:P266,"Yes"))/C24) -> 0.125
A25: centrifuge | B25: =COUNTIF(Data!B2:B266,A25) -> 7 | C25: =COUNTIFS(Data!B2:B266,A25,Data!C2:C266,1) -> 7 | D25: =IF(C25=0,0,(COUNTIFS(Data!B2:B266,A25,Data!C2:C266,1,Data!P2:P266,"Yes"))/C25) -> 0
A26: ethereum | B26: =COUNTIF(Data!B2:B266,A26) -> 13 | C26: =COUNTIFS(Data!B2:B266,A26,Data!C2:C266,1) -> 13 | D26: =IF(C26=0,0,(COUNTIFS(Data!B2:B266,A26,Data!C2:C266,1,Data!P2:P266,"Yes"))/C26) -> 0.076923077
A27: ethereum-sepolia | B27: =COUNTIF(Data!B2:B266,A27) -> 11 | C27: =COUNTIFS(Data!B2:B266,A27,Data!C2:C266,1) -> 11 | D27: =IF(C27=0,0,(COUNTIFS(Data!B2:B266,A27,Data!C2:C266,1,Data!P2:P266,"Yes"))/C27) -> 0.090909091
A28: fraxtal | B28: =COUNTIF(Data!B2:B266,A28) -> 9 | C28: =COUNTIFS(Data!B2:B266,A28,Data!C2:C266,1) -> 9 | D28: =IF(C28=0,0,(COUNTIFS(Data!B2:B266,A28,Data!C2:C266,1,Data!P2:P266,"Yes"))/C28) -> 0.11111111
A29: immutable | B29: =COUNTIF(Data!B2:B266,A29) -> 12 | C29: =COUNTIFS(Data!B2:B266,A29,Data!C2:C266,1) -> 12 | D29: =IF(C29=0,0,(COUNTIFS(Data!B2:B266,A29,Data!C2:C266,1,Data!P2:P266,"Yes"))/C29) -> 0
A30: linea | B30: =COUNTIF(Data!B2:B266,A30) -> 11 | C30: =COUNTIFS(Data!B2:B266,A30,Data!C2:C266,1) -> 11 | D30: =IF(C30=0,0,(COUNTIFS(Data!B2:B266,A30,Data!C2:C266,1,Data!P2:P266,"Yes"))/C30) -> 0.090909091
A31: linea-sepolia | B31: =COUNTIF(Data!B2:B266,A31) -> 9 | C31: =COUNTIFS(Data!B2:B266,A31,Data!C2:C266,1) -> 9 | D31: =IF(C31=0,0,(COUNTIFS(Data!B2:B266,A31,Data!C2:C266,1,Data!P2:P266,"Yes"))/C31) -> 0.11111111
A32: mantle | B32: =COUNTIF(Data!B2:B266,A32) -> 11 | C32: =COUNTIFS(Data!B2:B266,A32,Data!C2:C266,1) -> 11 | D32: =IF(C32=0,0,(COUNTIFS(Data!B2:B266,A32,Data!C2:C266,1,Data!P2:P266,"Yes"))/C32) -> 0.090909091
A33: moonbeam | B33: =COUNTIF(Data!B2:B266,A33) -> 11 | C33: =COUNTIFS(Data!B2:B266,A33,Data!C2:C266,1) -> 11 | D33: =IF(C33=0,0,(COUNTIFS(Data!B2:B266,A33,Data!C2:C266,1,Data!P2:P266,"Yes"))/C33) -> 0.090909091
A34: optimism | B34: =COUNTIF(Data!B2:B266,A34) -> 12 | C34: =COUNTIFS(Data!B2:B266,A34,Data!C2:C266,1) -> 12 | D34: =IF(C34=0,0,(COUNTIFS(Data!B2:B266,A34,Data!C2:C266,1,Data!P2:P266,"Yes"))/C34) -> 0
A35: optimism-sepolia | B35: =COUNTIF(Data!B2:B266,A35) -> 9 | C35: =COUNTIFS(Data!B2:B266,A35,Data!C2:C266,1) -> 9 | D35: =IF(C35=0,0,(COUNTIFS(Data!B2:B266,A35,Data!C2:C266,1,Data!P2:P266,"Yes"))/C35) -> 0.11111111
A36: polygon | B36: =COUNTIF(Data!B2:B266,A36) -> 11 | C36: =COUNTIFS(Data!B2:B266,A36,Data!C2:C266,1) -> 11 | D36: =IF(C36=0,0,(COUNTIFS(Data!B2:B266,A36,Data!C2:C266,1,Data!P2:P266,"Yes"))/C36) -> 0.090909091
A37: polygon-sepolia | B37: =COUNTIF(Data!B2:B266,A37) -> 9 | C37: =COUNTIFS(Data!B2:B266,A37,Data!C2:C266,1) -> 9 | D37: =IF(C37=0,0,(COUNTIFS(Data!B2:B266,A37,Data!C2:C266,1,Data!P2:P266,"Yes"))/C37) -> 0.11111111
A38: test-avalanche | B38: =COUNTIF(Data!B2:B266,A38) -> 7 | C38: =COUNTIFS(Data!B2:B266,A38,Data!C2:C266,1) -> 7 | D38: =IF(C38=0,0,(COUNTIFS(Data!B2:B266,A38,Data!C2:C266,1,Data!P2:P266,"Yes"))/C38) -> 0
A39: test-sepolia | B39: =COUNTIF(Data!B2:B266,A39) -> 7 | C39: =COUNTIFS(Data!B2:B266,A39,Data!C2:C266,1) -> 7 | D39: =IF(C39=0,0,(COUNTIFS(Data!B2:B266,A39,Data!C2:C266,1,Data!P2:P266,"Yes"))/C39) -> 0

Sheet Agreement_Jaccard
A1: Axelar_Obfuscated — Tool Agreement (Jaccard Index)

Sheet Key_Findings
A1: Axelar_Obfuscated — Key Findings
A3: ="1. Bytecode resolution: "&SUM(Data!C2:C266)&" of "&COUNTA(Data!A2:A266)&" queried addresses ("&TEXT(SUM(Data!C2:C266)/COUNTA(Data!A2:A266),"0.0%")&") resolved to deployed bytecode; the rest are EOAs, unverified, or not found on-chain." -> 1. Bytecode resolution: 265 of 265 queried addresses (100.0%) resolved to deployed bytecode; the rest are EOAs, unverified, or not found on-chain.
A4: ="2. Detection coverage: only Mythril produced any detections. Reentrancy, Integer, Access Control, Delegatecall, Unchecked Call, Timestamp, TOD, Selfdestruct, Locked Ether, Ether Leak all show zero hits in this bytecode run." -> 2. Detection coverage: only Mythril produced any detections. Reentrancy, Integer, Access Control, Delegatecall, Unchecked Call, Timestamp, TOD, Selfdestruct, Locked Ether, Ether Leak all show zero hits in this bytecode run.
A5: ="5. "&Per_Vulnerability_Analysis!C15&" of "&Per_Vulnerability_Analysis!D15&" resolved contracts ("&TEXT(Per_Vulnerability_Analysis!C15/Per_Vulnerability_Analysis!D15,"0.0%")&") were flagged by at least one tool." -> 5. 19 of 265 resolved contracts (7.2%) were flagged by at least one tool.

Sheet Why_These_Results
A1: Axelar Obfuscated — Why These Results: Forensic Explanation of the Detection Pattern
A2: Findings below combine (a) direct inspection of the raw BOSC-obfuscated bytecode where available, and (b) matched-pair comparison against the ORIGINAL (unobfuscated) run on the same addresses.
A4: 1. WHY THE TOOL SET FIRING HERE IS Mythril
A5: Axelar's obfuscated run shows detections from Mythril only - MAIAN, Securify produced ZERO hits here, unlike the other protocols in this dataset. This is the single largest driver of Axelar's 7.2% overall vulnerable rate, independent of whether obfuscation actually changed the underlying code's exploitability.
A6: Axelar-obfuscated is the inverse case: ONLY Mythril fires (7.2% of contracts), and MAIAN - which flagged essentially 100% of Axelar's ORIGINAL bytecode - produces zero hits after obfuscation. This is the most dramatic tool-behavior swing in the entire 5-protocol dataset and is explored further in section 2 below.
A8: 2. WHAT CHANGED VERSUS THE ORIGINAL (UNOBFUSCATED) BYTECODE, SAME CONTRACTS
A9: On the 151 addresses successfully analyzed in BOTH the original and obfuscated runs: original vulnerable rate 100.0% -> obfuscated vulnerable rate 2.0%. 148 contracts that were flagged originally evaded ALL detection after obfuscation (98.0% evasion rate among originally-flagged contracts); 0 contracts that were clean originally were newly flagged after obfuscation.
A10: Axelar shows the most extreme evasion in the dataset: 148 of 151 originally-flagged matched contracts (98.0%) evaded detection entirely. Combined with section 1 (MAIAN going silent after obfuscation), this strongly suggests the obfuscation pipeline changed something MAIAN's static heuristic depends on for Axelar specifically - worth checking whether Axelar's obfuscation pass altered payable-function selectors or fallback/receive structure in a way the other 4 protocols' obfuscation did not.
A12: 3. BYTECODE-LEVEL OBSERVATIONS
A13: Bytecode text is available for 265 of 265 obfuscated contracts, ranging 5-1579 hex characters (median 135). Note: BOSC's obfuscated bytecode export in this dataset is not formatted identically to the raw eth_getCode output used for the original bytecode analysis (no 0x prefix, and apparent leading-zero/byte normalization), so direct length-for-length comparison against the original bytecode reports should be treated as illustrative rather than exact.
A14: Average CALLVALUE (opcode 0x34) occurrences per contract: 0.68.
A16: SUMMARY
A17: Axelar obfuscated is the dataset's clearest case of obfuscation defeating detection: MAIAN goes from ~100% to 0%, and 98.0% of originally-flagged contracts evade all detection. This is either a genuine obfuscation-robustness finding worth highlighting, or a tool-configuration artifact specific to this SmartBugs pass - the two are hard to distinguish from this data alone and it is the single most important result to verify manually before using it as a headline number.

Sheet Data
A1: Address | B1: Chain | C1: Has_Bytecode | D1: Bytecode_Length | E1: Reentrancy | F1: Integer | G1: Access_Control | H1: Delegatecall | I1: Unchecked_Call | J1: Timestamp | K1: TOD | L1: DoS | M1: Selfdestruct | N1: Locked_Ether | O1: Ether_Leak | P1: Vulnerable | Q1: Mythril_Flag
A2: arbitrum-sepolia_0x6513Aedb4D1593BA12e50644401D976aebDc90d8 | B2: arbitrum-sepolia | C2: 1 | D2: 77 | P2: No | Q2: 0
A3: arbitrum-sepolia_0x7Acbae6CBa67d78AAf69e47000884aE00F9B2525 | B3: arbitrum-sepolia | C3: 1 | D3: 5 | P3: No | Q3: 0
A4: arbitrum-sepolia_0x7F83F5cA2AE4206AbFf8a3C3668e88ce5F11C0B5 | B4: arbitrum-sepolia | C4: 1 | D4: 1579 | P4: No | Q4: 0
A5: arbitrum-sepolia_0x83a93500d23Fbc3e82B410aD07A6a9F7A0670D66 | B5: arbitrum-sepolia | C5: 1 | D5: 135 | P5: No | Q5: 0
A6: arbitrum-sepolia_0x98B2920D53612483F91F12Ed7754E51b4A77919e | B6: arbitrum-sepolia | C6: 1 | D6: 1391 | P6: No | Q6: 0
A7: arbitrum-sepolia_0xB5FB4BE02232B1bBA4dC8f81dc24C26980dE9e3C | B7: arbitrum-sepolia | C7: 1 | D7: 135 | P7: No | Q7: 0
A8: arbitrum-sepolia_0xCC940AE49C78F20E3F13F3cF37e996b98Ac3EC68 | B8: arbitrum-sepolia | C8: 1 | D8: 5 | P8: No | Q8: 0
A9: arbitrum-sepolia_0xbE406F0189A0B4cf3A05C286473D23791Dd44Cc6 | B9: arbitrum-sepolia | C9: 1 | D9: 135 | P9: No | Q9: 0
A10: arbitrum-sepolia_0xe1cE95479C84e9809269227C7F8524aE051Ae77a | B10: arbitrum-sepolia | C10: 1 | D10: 494 | L10: Mythril | P10: Yes | Q10: 1
A11: arbitrum_0x1f8A4d195B647647c7dD45650CBd553FD33cCAA6 | B11: arbitrum | C11: 1 | D11: 249 | P11: No | Q11: 0
A12: arbitrum_0x2d5d7d31F671F86C782533cc367F14109a082712 | B12: arbitrum | C12: 1 | D12: 135 | P12: No | Q12: 0
A13: arbitrum_0x6513Aedb4D1593BA12e50644401D976aebDc90d8 | B13: arbitrum | C13: 1 | D13: 77 | P13: No | Q13: 0
A14: arbitrum_0x7Acbae6CBa67d78AAf69e47000884aE00F9B2525 | B14: arbitrum | C14: 1 | D14: 5 | P14: No | Q14: 0
A15: arbitrum_0x7DdB2d76b80B0AA19bDEa48EB1301182F4CeefbC | B15: arbitrum | C15: 1 | D15: 1579 | P15: No | Q15: 0
A16: arbitrum_0x83a93500d23Fbc3e82B410aD07A6a9F7A0670D66 | B16: arbitrum | C16: 1 | D16: 135 | P16: No | Q16: 0
A17: arbitrum_0x98B2920D53612483F91F12Ed7754E51b4A77919e | B17: arbitrum | C17: 1 | D17: 1391 | P17: No | Q17: 0
A18: arbitrum_0xB5FB4BE02232B1bBA4dC8f81dc24C26980dE9e3C | B18: arbitrum | C18: 1 | D18: 135 | P18: No | Q18: 0
A19: arbitrum_0xCC940AE49C78F20E3F13F3cF37e996b98Ac3EC68 | B19: arbitrum | C19: 1 | D19: 5 | P19: No | Q19: 0
A20: arbitrum_0xc1DCb196BA862B337Aa23eDA1Cb9503C0801b955 | B20: arbitrum | C20: 1 | D20: 135 | P20: No | Q20: 0
A21: arbitrum_0xe432150cce91c13a887f7D836923d5597adD8E31 | B21: arbitrum | C21: 1 | D21: 494 | L21: Mythril | P21: Yes | Q21: 1
A22: avalanche_0x1f8A4d195B647647c7dD45650CBd553FD33cCAA6 | B22: avalanche | C22: 1 | D22: 105 | P22: No | Q22: 0
A23: avalanche_0x2d5d7d31F671F86C782533cc367F14109a082712 | B23: avalanche | C23: 1 | D23: 105 | P23: No | Q23: 0
A24: avalanche_0x5029C0EFf6C34351a0CEc334542cDb22c7928f78 | B24: avalanche | C24: 1 | D24: 105 | P24: No | Q24: 0
A25: avalanche_0x6513Aedb4D1593BA12e50644401D976aebDc90d8 | B25: avalanche | C25: 1 | D25: 105 | P25: No | Q25: 0
A26: avalanche_0x7Acbae6CBa67d78AAf69e47000884aE00F9B2525 | B26: avalanche | C26: 1 | D26: 105 | P26: No | Q26: 0
A27: avalanche_0x7DdB2d76b80B0AA19bDEa48EB1301182F4CeefbC | B27: avalanche | C27: 1 | D27: 105 | P27: No | Q27: 0
A28: avalanche_0x7F83F5cA2AE4206AbFf8a3C3668e88ce5F11C0B5 | B28: avalanche | C28: 1 | D28: 105 | P28: No | Q28: 0
A29: avalanche_0x83a93500d23Fbc3e82B410aD07A6a9F7A0670D66 | B29: avalanche | C29: 1 | D29: 105 | P29: No | Q29: 0
A30: avalanche_0x98B2920D53612483F91F12Ed7754E51b4A77919e | B30: avalanche | C30: 1 | D30: 105 | P30: No | Q30: 0
A31: avalanche_0xB5FB4BE02232B1bBA4dC8f81dc24C26980dE9e3C | B31: avalanche | C31: 1 | D31: 105 | P31: No | Q31: 0
A32: avalanche_0xC249632c2D40b9001FE907806902f63038B737Ab | B32: avalanche | C32: 1 | D32: 105 | P32: No | Q32: 0
A33: avalanche_0xCC940AE49C78F20E3F13F3cF37e996b98Ac3EC68 | B33: avalanche | C33: 1 | D33: 105 | P33: No | Q33: 0
... A43: base-sepolia_0xbE406F0189A0B4cf3A05C286473D23791Dd44Cc6 | B43: base-sepolia | C43: 1 | D43: 135 | P43: No | Q43: 0
A44: base-sepolia_0xe432150cce91c13a887f7D836923d5597adD8E31 | B44: base-sepolia | C44: 1 | D44: 494 | L44: Mythril | P44: Yes | Q44: 1
A45: base_0x1f8A4d195B647647c7dD45650CBd553FD33cCAA6 | B45: base | C45: 1 | D45: 105 | P45: No | Q45: 0
A46: base_0x2d5d7d31F671F86C782533cc367F14109a082712 | B46: base | C46: 1 | D46: 105 | P46: No | Q46: 0
A47: base_0x6513Aedb4D1593BA12e50644401D976aebDc90d8 | B47: base | C47: 1 | D47: 105 | P47: No | Q47: 0
A48: base_0x7Acbae6CBa67d78AAf69e47000884aE00F9B2525 | B48: base | C48: 1 | D48: 105 | P48: No | Q48: 0
A49: base_0x7DdB2d76b80B0AA19bDEa48EB1301182F4CeefbC | B49: base | C49: 1 | D49: 105 | P49: No | Q49: 0
...
