Workbook

Sheet Executive_Summary
A1: CCIP_Obfuscated — Bridge Bytecode Vulnerability Detection: Executive Summary
A3: KEY METRICS
A4: ="Addresses queried: "&COUNTA(Data!A2:A88)&" | Chains covered: 22" -> Addresses queried: 87 | Chains covered: 22
A5: ="Contracts with resolved bytecode: "&SUM(Data!C2:C88)&" | No bytecode (EOA/unverified): "&(COUNTA(Data!A2:A88)-SUM(Data!C2:C88)) -> Contracts with resolved bytecode: 87 | No bytecode (EOA/unverified): 0
A6: ="Overall vulnerable (>=1 tool): "&TEXT(Per_Vulnerability_Analysis!C15/Per_Vulnerability_Analysis!D15,"0.0%")&" of resolved contracts ("&Per_Vulnerability_Analysis!C15&"/"&Per_Vulnerability_Analysis!D15&")" -> Overall vulnerable (>=1 tool): 100.0% of resolved contracts (87/87)
A7: ="MAIAN flag rate: "&TEXT(Tool_Wise_Analysis!E4,"0.0%") -> MAIAN flag rate: 100.0%
A8: ="Securify flag rate: "&TEXT(Tool_Wise_Analysis!E5,"0.0%") -> Securify flag rate: 74.7%
A9: ="Tool agreement (Jaccard, MAIAN vs Securify): "&TEXT(Agreement_Jaccard!B11,"0.0000") -> Tool agreement (Jaccard, MAIAN vs Securify): 0.7471
A11: WHAT THE DATA SHOWS
A12: ="Highest-prevalence category: "&INDEX(Per_Vulnerability_Analysis!A4:A14,MATCH(MAX(Per_Vulnerability_Analysis!C4:C14),Per_Vulnerability_Analysis!C4:C14,0))&" ("&TEXT(MAX(Per_Vulnerability_Analysis!E4:E14),"0.0%")&" prevalence)" -> Highest-prevalence category: Ether Leak (100.0% prevalence)
A13: ="Only MAIAN and Securify returned detections in this run; 6 of 11 tracked categories show zero hits — see Formula_Definitions / Per_Vulnerability_Analysis." -> Only MAIAN and Securify returned detections in this run; 6 of 11 tracked categories show zero hits — see Formula_Definitions / Per_Vulnerability_Analysis.

Sheet Formula_Definitions
A1: Metric | B1: Formula | C1: Interpretation
A2: Detections D(v) | B2: COUNTIF(category_column, "<>") | C2: Number of contracts flagged for vulnerability v by its reporting tool
A3: Contracts w/ Bytecode | B3: SUM(Has_Bytecode) | C3: Denominator for prevalence; excludes EOA/unverified/no-code addresses
A4: Prevalence % | B4: D(v) / Contracts_w_Bytecode | C4: Share of resolved contracts flagged for category v
A5: Overall Vulnerable | B5: COUNTIFS(Has_Bytecode=1, Vulnerable="Yes") | C5: Contracts flagged by >=1 tool, among resolved contracts
A6: Flags per Contract | B6: COUNT of active categories triggered per row | C6: How many distinct categories fire on the same contract
A7: Tool Flag Rate % | B7: Tool-flagged contracts / Contracts w/ Bytecode | C7: Per-tool prevalence, independent of category breakdown
A8: Jaccard Index J(A,B) | B8: |A ∩ B| / |A ∪ B| | C8: Overlap between the two tools' flagged sets; 0=no overlap, 1=identical sets
A9: Vulnerable Rate % (chain) | B9: Vulnerable(chain) / With_Bytecode(chain) | C9: Per-chain share of resolved contracts flagged

Sheet Per_Vulnerability_Analysis
A1: CCIP_Obfuscated — Per-Vulnerability Analysis
A3: Category | B3: Detecting Tool | C3: Detections D(v) | D3: Contracts w/ Bytecode | E3: Prevalence % | F3: Note
A4: Reentrancy | B4: Securify | C4: =COUNTIF(Data!E2:E88,"<>") -> 65 | D4: =SUM(Data!C2:C88) -> 87 | E4: =IF(D4=0,0,C4/D4) -> 0.74712644 | F4: Bytecode-level detection
A5: Integer | B5: Not covered (0 detections) | C5: =COUNTIF(Data!F2:F88,"<>") -> 0 | D5: =SUM(Data!C2:C88) -> 87 | E5: =IF(D5=0,0,C5/D5) -> 0 | F5: Zero detections this run
A6: Access Control | B6: Securify | C6: =COUNTIF(Data!G2:G88,"<>") -> 65 | D6: =SUM(Data!C2:C88) -> 87 | E6: =IF(D6=0,0,C6/D6) -> 0.74712644 | F6: Bytecode-level detection
A7: Delegatecall | B7: Not covered (0 detections) | C7: =COUNTIF(Data!H2:H88,"<>") -> 0 | D7: =SUM(Data!C2:C88) -> 87 | E7: =IF(D7=0,0,C7/D7) -> 0 | F7: Zero detections this run
A8: Unchecked Call | B8: Securify | C8: =COUNTIF(Data!I2:I88,"<>") -> 65 | D8: =SUM(Data!C2:C88) -> 87 | E8: =IF(D8=0,0,C8/D8) -> 0.74712644 | F8: Bytecode-level detection
A9: Timestamp | B9: Not covered (0 detections) | C9: =COUNTIF(Data!J2:J88,"<>") -> 0 | D9: =SUM(Data!C2:C88) -> 87 | E9: =IF(D9=0,0,C9/D9) -> 0 | F9: Zero detections this run
A10: TOD | B10: Securify | C10: =COUNTIF(Data!K2:K88,"<>") -> 65 | D10: =SUM(Data!C2:C88) -> 87 | E10: =IF(D10=0,0,C10/D10) -> 0.74712644 | F10: Bytecode-level detection
A11: DoS | B11: Not covered (0 detections) | C11: =COUNTIF(Data!L2:L88,"<>") -> 0 | D11: =SUM(Data!C2:C88) -> 87 | E11: =IF(D11=0,0,C11/D11) -> 0 | F11: Zero detections this run
A12: Selfdestruct | B12: Not covered (0 detections) | C12: =COUNTIF(Data!M2:M88,"<>") -> 0 | D12: =SUM(Data!C2:C88) -> 87 | E12: =IF(D12=0,0,C12/D12) -> 0 | F12: Zero detections this run
A13: Locked Ether | B13: Not covered (0 detections) | C13: =COUNTIF(Data!N2:N88,"<>") -> 0 | D13: =SUM(Data!C2:C88) -> 87 | E13: =IF(D13=0,0,C13/D13) -> 0 | F13: Zero detections this run
A14: Ether Leak | B14: MAIAN | C14: =COUNTIF(Data!O2:O88,"<>") -> 87 | D14: =SUM(Data!C2:C88) -> 87 | E14: =IF(D14=0,0,C14/D14) -> 1 | F14: Bytecode-level detection
A15: OVERALL VULNERABLE | B15: Any tool | C15: =COUNTIFS(Data!C2:C88,1,Data!P2:P88,"Yes") -> 87 | D15: =SUM(Data!C2:C88) -> 87 | E15: =IF(D15=0,0,C15/D15) -> 1 | F15: Flagged by >=1 tool

Sheet Detection_Count_Analysis
A1: CCIP_Obfuscated — Detection Count Analysis
A3: Flags per contract = count of (Reentrancy, Access Control, Unchecked Call, TOD, Ether Leak) triggered on that contract
A5: Flags per Contract | B5: Contract Count | C5: % of Bytecode Contracts | D5: Note
A6: 0 categories flagged | B6: =SUMPRODUCT((Data!C2:C88=1)*(((Data!E2:E88<>"")+(Data!G2:G88<>"")+(Data!I2:I88<>"")+(Data!K2:K88<>"")+(Data!O2:O88<>""))=0)) -> 0 | C6: =IF(SUM(Data!C2:C88)=0,0,B6/SUM(Data!C2:C88)) -> 0
A7: 1 categories flagged | B7: =SUMPRODUCT((Data!C2:C88=1)*(((Data!E2:E88<>"")+(Data!G2:G88<>"")+(Data!I2:I88<>"")+(Data!K2:K88<>"")+(Data!O2:O88<>""))=1)) -> 22 | C7: =IF(SUM(Data!C2:C88)=0,0,B7/SUM(Data!C2:C88)) -> 0.25287356
A8: 2 categories flagged | B8: =SUMPRODUCT((Data!C2:C88=1)*(((Data!E2:E88<>"")+(Data!G2:G88<>"")+(Data!I2:I88<>"")+(Data!K2:K88<>"")+(Data!O2:O88<>""))=2)) -> 0 | C8: =IF(SUM(Data!C2:C88)=0,0,B8/SUM(Data!C2:C88)) -> 0
A9: 3 categories flagged | B9: =SUMPRODUCT((Data!C2:C88=1)*(((Data!E2:E88<>"")+(Data!G2:G88<>"")+(Data!I2:I88<>"")+(Data!K2:K88<>"")+(Data!O2:O88<>""))=3)) -> 0 | C9: =IF(SUM(Data!C2:C88)=0,0,B9/SUM(Data!C2:C88)) -> 0
A10: 4 categories flagged | B10: =SUMPRODUCT((Data!C2:C88=1)*(((Data!E2:E88<>"")+(Data!G2:G88<>"")+(Data!I2:I88<>"")+(Data!K2:K88<>"")+(Data!O2:O88<>""))=4)) -> 0 | C10: =IF(SUM(Data!C2:C88)=0,0,B10/SUM(Data!C2:C88)) -> 0
A11: 5 categories flagged | B11: =SUMPRODUCT((Data!C2:C88=1)*(((Data!E2:E88<>"")+(Data!G2:G88<>"")+(Data!I2:I88<>"")+(Data!K2:K88<>"")+(Data!O2:O88<>""))=5)) -> 65 | C11: =IF(SUM(Data!C2:C88)=0,0,B11/SUM(Data!C2:C88)) -> 0.74712644
A12: Total contracts w/ bytecode | B12: =SUM(B6:B11) -> 87
A14: Total raw detections (sum across all 11 categories) | B14: =COUNTIF(Data!E2:E88,"<>")+COUNTIF(Data!F2:F88,"<>")+COUNTIF(Data!G2:G88,"<>")+COUNTIF(Data!H2:H88,"<>")+COUNTIF(Data!I2:I88,"<>")+COUNTIF(Data!J2:J88,"<>")+COUNTIF(Data!K2:K88,"<>")+COUNTIF(Data!L2:L88,"<>")+COUNTIF(Data!M2:M88,"<>")+COUNTIF(Data!N2:N88,"<>")+COUNTIF(Data!O2:O88,"<>") -> 347
A15: Avg detections per bytecode-resolved contract | B15: =B14/SUM(Data!C2:C88) -> 3.9885057

Sheet Tool_Wise_Analysis
A1: CCIP_Obfuscated — Tool-wise Analysis
A3: Tool | B3: Categories Covered | C3: Contracts Flagged | D3: Contracts w/ Bytecode | E3: Flag Rate % | F3: Note
A4: MAIAN | B4: Ether Leak | C4: =SUM(Data!Q2:Q88) -> 87 | D4: =SUM(Data!C2:C88) -> 87 | E4: =IF(D4=0,0,C4/D4) -> 1 | F4: Symbolic execution, financial-flow analysis
A5: Securify | B5: Reentrancy, Access Control, Unchecked Call, TOD | C5: =SUM(Data!R2:R88) -> 65 | D5: =SUM(Data!C2:C88) -> 87 | E5: =IF(D5=0,0,C5/D5) -> 0.74712644
A6: Others (n/a) | B6: Integer, Delegatecall, Timestamp, DoS, Selfdestruct, Locked Ether | C6: 0 | D6: =SUM(Data!C2:C88) -> 87 | E6: 0 | F6: Zero detections in this run

Sheet Contract_Level_Statistics
A1: CCIP_Obfuscated — Contract-Level Statistics
A3: Addresses queried | B3: =COUNTA(Data!A2:A88) -> 87
A4: Chains covered | B4: 22
A5: Contracts analyzed (bytecode resolved / detection ran) | B5: =SUM(Data!C2:C88) -> 87
A6: Not analyzed (EOA / unverified / not found) | B6: =COUNTA(Data!A2:A88)-SUM(Data!C2:C88) -> 0
A7: ...of which bytecode text is blank in source export | B7: =SUMPRODUCT((Data!C2:C88=1)*(Data!D2:D88=0)) -> 87 | D7: Detections still recorded; only the raw bytecode string is missing from the export
A8: Avg bytecode length (hex chars, where text available) | B8: =IF(SUMPRODUCT((Data!C2:C88=1)*(Data!D2:D88>0))=0,0,SUMIF(Data!C2:C88,1,Data!D2:D88)/SUMPRODUCT((Data!C2:C88=1)*(Data!D2:D88>0))) -> 0 | D8: Rounded to nearest char; excludes blank-text rows
A9: Min bytecode length (where text available) | B9: =_xlfn.MINIFS(Data!D2:D88,Data!C2:C88,1,Data!D2:D88,">0") -> 0
A10: Max bytecode length | B10: =_xlfn.MAXIFS(Data!D2:D88,Data!C2:C88,1) -> 0
A12: Per-Chain Breakdown
A13: Chain | B13: Addresses | C13: With Bytecode | D13: Vulnerable Rate %
A14: abstract-mainnet | B14: =COUNTIF(Data!B2:B88,A14) -> 3 | C14: =COUNTIFS(Data!B2:B88,A14,Data!C2:C88,1) -> 3 | D14: =IF(C14=0,0,(COUNTIFS(Data!B2:B88,A14,Data!C2:C88,1,Data!P2:P88,"Yes"))/C14) -> 1
A15: apechain-mainnet | B15: =COUNTIF(Data!B2:B88,A15) -> 5 | C15: =COUNTIFS(Data!B2:B88,A15,Data!C2:C88,1) -> 5 | D15: =IF(C15=0,0,(COUNTIFS(Data!B2:B88,A15,Data!C2:C88,1,Data!P2:P88,"Yes"))/C15) -> 1
A16: avalanche-fuji-testnet | B16: =COUNTIF(Data!B2:B88,A16) -> 4 | C16: =COUNTIFS(Data!B2:B88,A16,Data!C2:C88,1) -> 4 | D16: =IF(C16=0,0,(COUNTIFS(Data!B2:B88,A16,Data!C2:C88,1,Data!P2:P88,"Yes"))/C16) -> 1
A17: berachain-mainnet | B17: =COUNTIF(Data!B2:B88,A17) -> 3 | C17: =COUNTIFS(Data!B2:B88,A17,Data!C2:C88,1) -> 3 | D17: =IF(C17=0,0,(COUNTIFS(Data!B2:B88,A17,Data!C2:C88,1,Data!P2:P88,"Yes"))/C17) -> 1
A18: celo-mainnet | B18: =COUNTIF(Data!B2:B88,A18) -> 4 | C18: =COUNTIFS(Data!B2:B88,A18,Data!C2:C88,1) -> 4 | D18: =IF(C18=0,0,(COUNTIFS(Data!B2:B88,A18,Data!C2:C88,1,Data!P2:P88,"Yes"))/C18) -> 1
A19: ethereum-mainnet-arbitrum-1 | B19: =COUNTIF(Data!B2:B88,A19) -> 4 | C19: =COUNTIFS(Data!B2:B88,A19,Data!C2:C88,1) -> 4 | D19: =IF(C19=0,0,(COUNTIFS(Data!B2:B88,A19,Data!C2:C88,1,Data!P2:P88,"Yes"))/C19) -> 1
A20: ethereum-mainnet-linea-1 | B20: =COUNTIF(Data!B2:B88,A20) -> 3 | C20: =COUNTIFS(Data!B2:B88,A20,Data!C2:C88,1) -> 3 | D20: =IF(C20=0,0,(COUNTIFS(Data!B2:B88,A20,Data!C2:C88,1,Data!P2:P88,"Yes"))/C20) -> 1
A21: ethereum-mainnet-mantle-1 | B21: =COUNTIF(Data!B2:B88,A21) -> 4 | C21: =COUNTIFS(Data!B2:B88,A21,Data!C2:C88,1) -> 4 | D21: =IF(C21=0,0,(COUNTIFS(Data!B2:B88,A21,Data!C2:C88,1,Data!P2:P88,"Yes"))/C21) -> 1
A22: ethereum-mainnet-taiko-1 | B22: =COUNTIF(Data!B2:B88,A22) -> 5 | C22: =COUNTIFS(Data!B2:B88,A22,Data!C2:C88,1) -> 5 | D22: =IF(C22=0,0,(COUNTIFS(Data!B2:B88,A22,Data!C2:C88,1,Data!P2:P88,"Yes"))/C22) -> 1
A23: ethereum-mainnet-unichain-1 | B23: =COUNTIF(Data!B2:B88,A23) -> 4 | C23: =COUNTIFS(Data!B2:B88,A23,Data!C2:C88,1) -> 4 | D23: =IF(C23=0,0,(COUNTIFS(Data!B2:B88,A23,Data!C2:C88,1,Data!P2:P88,"Yes"))/C23) -> 1
A24: ethereum-mainnet-worldchain-1 | B24: =COUNTIF(Data!B2:B88,A24) -> 4 | C24: =COUNTIFS(Data!B2:B88,A24,Data!C2:C88,1) -> 4 | D24: =IF(C24=0,0,(COUNTIFS(Data!B2:B88,A24,Data!C2:C88,1,Data!P2:P88,"Yes"))/C24) -> 1
A25: ethereum-testnet-sepolia-arbitrum-1 | B25: =COUNTIF(Data!B2:B88,A25) -> 4 | C25: =COUNTIFS(Data!B2:B88,A25,Data!C2:C88,1) -> 4 | D25: =IF(C25=0,0,(COUNTIFS(Data!B2:B88,A25,Data!C2:C88,1,Data!P2:P88,"Yes"))/C25) -> 1
A26: ethereum-testnet-sepolia-base-1 | B26: =COUNTIF(Data!B2:B88,A26) -> 5 | C26: =COUNTIFS(Data!B2:B88,A26,Data!C2:C88,1) -> 5 | D26: =IF(C26=0,0,(COUNTIFS(Data!B2:B88,A26,Data!C2:C88,1,Data!P2:P88,"Yes"))/C26) -> 1
A27: ethereum-testnet-sepolia-linea-1 | B27: =COUNTIF(Data!B2:B88,A27) -> 5 | C27: =COUNTIFS(Data!B2:B88,A27,Data!C2:C88,1) -> 5 | D27: =IF(C27=0,0,(COUNTIFS(Data!B2:B88,A27,Data!C2:C88,1,Data!P2:P88,"Yes"))/C27) -> 1
A28: ethereum-testnet-sepolia-optimism-1 | B28: =COUNTIF(Data!B2:B88,A28) -> 4 | C28: =COUNTIFS(Data!B2:B88,A28,Data!C2:C88,1) -> 4 | D28: =IF(C28=0,0,(COUNTIFS(Data!B2:B88,A28,Data!C2:C88,1,Data!P2:P88,"Yes"))/C28) -> 1
A29: ethereum-testnet-sepolia-worldchain-1 | B29: =COUNTIF(Data!B2:B88,A29) -> 5 | C29: =COUNTIFS(Data!B2:B88,A29,Data!C2:C88,1) -> 5 | D29: =IF(C29=0,0,(COUNTIFS(Data!B2:B88,A29,Data!C2:C88,1,Data!P2:P88,"Yes"))/C29) -> 1
A30: fraxtal-mainnet | B30: =COUNTIF(Data!B2:B88,A30) -> 5 | C30: =COUNTIFS(Data!B2:B88,A30,Data!C2:C88,1) -> 5 | D30: =IF(C30=0,0,(COUNTIFS(Data!B2:B88,A30,Data!C2:C88,1,Data!P2:P88,"Yes"))/C30) -> 1
A31: matic-mainnet | B31: =COUNTIF(Data!B2:B88,A31) -> 2 | C31: =COUNTIFS(Data!B2:B88,A31,Data!C2:C88,1) -> 2 | D31: =IF(C31=0,0,(COUNTIFS(Data!B2:B88,A31,Data!C2:C88,1,Data!P2:P88,"Yes"))/C31) -> 1
A32: plasma-mainnet | B32: =COUNTIF(Data!B2:B88,A32) -> 4 | C32: =COUNTIFS(Data!B2:B88,A32,Data!C2:C88,1) -> 4 | D32: =IF(C32=0,0,(COUNTIFS(Data!B2:B88,A32,Data!C2:C88,1,Data!P2:P88,"Yes"))/C32) -> 1
A33: sei-mainnet | B33: =COUNTIF(Data!B2:B88,A33) -> 4 | C33: =COUNTIFS(Data!B2:B88,A33,Data!C2:C88,1) -> 4 | D33: =IF(C33=0,0,(COUNTIFS(Data!B2:B88,A33,Data!C2:C88,1,Data!P2:P88,"Yes"))/C33) -> 1
A34: sonic-mainnet | B34: =COUNTIF(Data!B2:B88,A34) -> 3 | C34: =COUNTIFS(Data!B2:B88,A34,Data!C2:C88,1) -> 3 | D34: =IF(C34=0,0,(COUNTIFS(Data!B2:B88,A34,Data!C2:C88,1,Data!P2:P88,"Yes"))/C34) -> 1
A35: xdai-mainnet | B35: =COUNTIF(Data!B2:B88,A35) -> 3 | C35: =COUNTIFS(Data!B2:B88,A35,Data!C2:C88,1) -> 3 | D35: =IF(C35=0,0,(COUNTIFS(Data!B2:B88,A35,Data!C2:C88,1,Data!P2:P88,"Yes"))/C35) -> 1

Sheet Agreement_Jaccard
A1: CCIP_Obfuscated — Tool Agreement (Jaccard Index)
A2: Pairwise agreement among 2 tools (MAIAN, Securify), among contracts with bytecode.
A4: MAIAN vs Securify
A5: Set | B5: Count | C5: % of Bytecode Contracts | D5: Definition
A6: Both flag (A ∩ B) | B6: =SUMPRODUCT((Data!C2:C88=1)*(Data!Q2:Q88=1)*(Data!R2:R88=1)) -> 65 | C6: =IF(SUM(Data!C2:C88)=0,0,B6/SUM(Data!C2:C88)) -> 0.74712644 | D6: MAIAN AND Securify
A7: Only MAIAN flags (A \ B) | B7: =SUMPRODUCT((Data!C2:C88=1)*(Data!Q2:Q88=1)*(Data!R2:R88=0)) -> 22 | C7: =IF(SUM(Data!C2:C88)=0,0,B7/SUM(Data!C2:C88)) -> 0.25287356 | D7: MAIAN only
A8: Only Securify flags (B \ A) | B8: =SUMPRODUCT((Data!C2:C88=1)*(Data!Q2:Q88=0)*(Data!R2:R88=1)) -> 0 | C8: =IF(SUM(Data!C2:C88)=0,0,B8/SUM(Data!C2:C88)) -> 0 | D8: Securify only
A9: Neither flags | B9: =SUMPRODUCT((Data!C2:C88=1)*(Data!Q2:Q88=0)*(Data!R2:R88=0)) -> 0 | C9: =IF(SUM(Data!C2:C88)=0,0,B9/SUM(Data!C2:C88)) -> 0 | D9: Resolved contract, no flag from either tool
A10: Union (A ∪ B) | B10: =B6+B7+B8 -> 87
A11: Jaccard Index J(MAIAN,Securify) = |A∩B| / |A∪B| | B11: =IF(B10=0,0,B6/B10) -> 0.74712644

Sheet Key_Findings
A1: CCIP_Obfuscated — Key Findings
A3: ="1. Bytecode resolution: "&SUM(Data!C2:C88)&" of "&COUNTA(Data!A2:A88)&" queried addresses ("&TEXT(SUM(Data!C2:C88)/COUNTA(Data!A2:A88),"0.0%")&") resolved to deployed bytecode; the rest are EOAs, unverified, or not found on-chain." -> 1. Bytecode resolution: 87 of 87 queried addresses (100.0%) resolved to deployed bytecode; the rest are EOAs, unverified, or not found on-chain.
A4: ="2. Detection coverage: only MAIAN and Securify produced any detections. Integer, Delegatecall, Timestamp, DoS, Selfdestruct, Locked Ether all show zero hits in this bytecode run." -> 2. Detection coverage: only MAIAN and Securify produced any detections. Integer, Delegatecall, Timestamp, DoS, Selfdestruct, Locked Ether all show zero hits in this bytecode run.
A5: ="3. Securify flag rate ("&TEXT(Tool_Wise_Analysis!E5,"0.0%")&") vs MAIAN flag rate ("&TEXT(Tool_Wise_Analysis!E4,"0.0%")&") among resolved contracts." -> 3. Securify flag rate (74.7%) vs MAIAN flag rate (100.0%) among resolved contracts.
A6: ="4. Tool overlap: Jaccard(MAIAN, Securify) = "&TEXT(Agreement_Jaccard!B11,"0.0000")&" — "&Agreement_Jaccard!B6&" contracts triggered both tools, "&Agreement_Jaccard!B7&" only MAIAN, "&Agreement_Jaccard!B8&" only Securify." -> 4. Tool overlap: Jaccard(MAIAN, Securify) = 0.7471 — 65 contracts triggered both tools, 22 only MAIAN, 0 only Securify.
A7: ="5. "&Per_Vulnerability_Analysis!C15&" of "&Per_Vulnerability_Analysis!D15&" resolved contracts ("&TEXT(Per_Vulnerability_Analysis!C15/Per_Vulnerability_Analysis!D15,"0.0%")&") were flagged by at least one tool." -> 5. 87 of 87 resolved contracts (100.0%) were flagged by at least one tool.

Sheet Why_These_Results
A1: CCIP Obfuscated — Why These Results: Forensic Explanation of the Detection Pattern
A2: Findings below combine (a) direct inspection of the raw BOSC-obfuscated bytecode where available, and (b) matched-pair comparison against the ORIGINAL (unobfuscated) run on the same addresses.
A4: 1. WHY THE TOOL SET FIRING HERE IS MAIAN/Securify
A5: CCIP's obfuscated run shows detections from MAIAN, Securify only - Mythril produced ZERO hits here, unlike the other protocols in this dataset. This is the single largest driver of CCIP's 100.0% overall vulnerable rate, independent of whether obfuscation actually changed the underlying code's exploitability.
A6: CCIP-obfuscated has no Mythril detections at all, but MAIAN alone still flags 100% of contracts (via Ether_Leak) - meaning MAIAN's heuristic is unaffected by identifier renaming, struct-packing or flat-filing, which makes sense: MAIAN reasons about control-flow reachability to a value-sending opcode, a property obfuscation does not change. The near-total absence of Mythril here should be checked against the SmartBugs run logs before concluding CCIP's obfuscated code is genuinely free of integer-overflow patterns.
A8: 2. WHAT CHANGED VERSUS THE ORIGINAL (UNOBFUSCATED) BYTECODE, SAME CONTRACTS
A9: On the 70 addresses successfully analyzed in BOTH the original and obfuscated runs: original vulnerable rate 100.0% -> obfuscated vulnerable rate 100.0%. 0 contracts that were flagged originally evaded ALL detection after obfuscation (0.0% evasion rate among originally-flagged contracts); 0 contracts that were clean originally were newly flagged after obfuscation.
A10: CCIP shows 0% evasion and 0 new detections - every one of the 70 matched contracts stayed Vulnerable=Yes on both sides. Given section 1, this is consistent with MAIAN's Ether_Leak heuristic being a structural property of the contract (payable, no provably-safe exit) that obfuscation techniques like identifier renaming or struct-packing cannot remove, since they preserve control flow.
A12: 3. BYTECODE-LEVEL OBSERVATIONS
A13: No raw bytecode text is present in CCIP's obfuscated export (all 87 rows have detection results but a blank Bytecode field) - the same data-export quirk documented for Hyperlane's original run. Bytecode-level forensics (length, opcode counts) cannot be performed for this protocol's obfuscated dataset; conclusions here rely on the tool-output and matched-pair analysis above only.
A15: SUMMARY
A16: CCIP obfuscated shows NO change from its original 100% vulnerable rate. The likely explanation is that MAIAN's Ether_Leak heuristic depends on control-flow/reachability properties that identifier renaming, struct-packing and flat-filing do not alter - obfuscation changed the code's surface form but not the property MAIAN is actually testing for.

Sheet Data
A1: Address | B1: Chain | C1: Has_Bytecode | D1: Bytecode_Length | E1: Reentrancy | F1: Integer | G1: Access_Control | H1: Delegatecall | I1: Unchecked_Call | J1: Timestamp | K1: TOD | L1: DoS | M1: Selfdestruct | N1: Locked_Ether | O1: Ether_Leak | P1: Vulnerable | Q1: MAIAN_Flag | R1: Securify_Flag
A2: abstract-mainnet_0x09521B0B5BB2d4406124c0207Cf551829B45f84d | B2: abstract-mainnet | C2: 1 | D2: 0 | O2: MAIAN | P2: Yes | Q2: 1 | R2: 0
A3: abstract-mainnet_0x7EEdf2DBC74924Cb1f23fC8845CD35bF18b697de | B3: abstract-mainnet | C3: 1 | D3: 0 | E3: Securify | G3: Securify | I3: Securify | K3: Securify | O3: MAIAN | P3: Yes | Q3: 1 | R3: 1
A4: abstract-mainnet_0xB79791184973589c38e114D43Eb8E4588C283A18 | B4: abstract-mainnet | C4: 1 | D4: 0 | E4: Securify | G4: Securify | I4: Securify | K4: Securify | O4: MAIAN | P4: Yes | Q4: 1 | R4: 1
A5: apechain-mainnet_0x1c2F528e3BEeFF81Bc03CC63E64dB131d18be7fA | B5: apechain-mainnet | C5: 1 | D5: 0 | E5: Securify | G5: Securify | I5: Securify | K5: Securify | O5: MAIAN | P5: Yes | Q5: 1 | R5: 1
A6: apechain-mainnet_0x768a1a3B321126A8B214d7376D48465C7f6Fa061 | B6: apechain-mainnet | C6: 1 | D6: 0 | E6: Securify | G6: Securify | I6: Securify | K6: Securify | O6: MAIAN | P6: Yes | Q6: 1 | R6: 1
A7: apechain-mainnet_0xABF586910586b8dcbdF92f1C5e2Ae14106f3DD16 | B7: apechain-mainnet | C7: 1 | D7: 0 | E7: Securify | G7: Securify | I7: Securify | K7: Securify | O7: MAIAN | P7: Yes | Q7: 1 | R7: 1
A8: apechain-mainnet_0xD3ED6fC9fd22412764ac2Ef64fB664b9393dF9F2 | B8: apechain-mainnet | C8: 1 | D8: 0 | E8: Securify | G8: Securify | I8: Securify | K8: Securify | O8: MAIAN | P8: Yes | Q8: 1 | R8: 1
A9: apechain-mainnet_0xe9c6945281028cb6530d43F998eE539dFE2a9191 | B9: apechain-mainnet | C9: 1 | D9: 0 | E9: Securify | G9: Securify | I9: Securify | K9: Securify | O9: MAIAN | P9: Yes | Q9: 1 | R9: 1
A10: avalanche-fuji-testnet_0x8E9066E66bF1B8A4eAF2344589De9ff82CE47C2d | B10: avalanche-fuji-testnet | C10: 1 | D10: 0 | E10: Securify | G10: Securify | I10: Securify | K10: Securify | O10: MAIAN | P10: Yes | Q10: 1 | R10: 1
A11: avalanche-fuji-testnet_0xAc8CFc3762a979628334a0E4C1026244498E821b | B11: avalanche-fuji-testnet | C11: 1 | D11: 0 | O11: MAIAN | P11: Yes | Q11: 1 | R11: 0
A12: avalanche-fuji-testnet_0xF694E193200268f9a4868e4Aa017A0118C9a8177 | B12: avalanche-fuji-testnet | C12: 1 | D12: 0 | E12: Securify | G12: Securify | I12: Securify | K12: Securify | O12: MAIAN | P12: Yes | Q12: 1 | R12: 1
A13: avalanche-fuji-testnet_0xefa93f3312840683893DbdeB3d53359b2d948F50 | B13: avalanche-fuji-testnet | C13: 1 | D13: 0 | E13: Securify | G13: Securify | I13: Securify | K13: Securify | O13: MAIAN | P13: Yes | Q13: 1 | R13: 1
A14: berachain-mainnet_0x160603D7C0Ac00409276bf6707430712Caf5b555 | B14: berachain-mainnet | C14: 1 | D14: 0 | E14: Securify | G14: Securify | I14: Securify | K14: Securify | O14: MAIAN | P14: Yes | Q14: 1 | R14: 1
A15: berachain-mainnet_0x25943b8C30C47F4eF09CcF2BAE315EbaF591881d | B15: berachain-mainnet | C15: 1 | D15: 0 | O15: MAIAN | P15: Yes | Q15: 1 | R15: 0
A16: berachain-mainnet_0x76159c2b43ff6F630193e37EC68452169914C1Bb | B16: berachain-mainnet | C16: 1 | D16: 0 | E16: Securify | G16: Securify | I16: Securify | K16: Securify | O16: MAIAN | P16: Yes | Q16: 1 | R16: 1
A17: celo-mainnet_0x56e0507d4E69D98bE7Eb4ada01d2315596F9f281 | B17: celo-mainnet | C17: 1 | D17: 0 | O17: MAIAN | P17: Yes | Q17: 1 | R17: 0
A18: celo-mainnet_0x9fCd83bC7F67ADa1fB51a4caBEa333c72B641bd1 | B18: celo-mainnet | C18: 1 | D18: 0 | E18: Securify | G18: Securify | I18: Securify | K18: Securify | O18: MAIAN | P18: Yes | Q18: 1 | R18: 1
A19: celo-mainnet_0xf19e0555fAA9051e277eeD5A0DcdB13CDaca39a9 | B19: celo-mainnet | C19: 1 | D19: 0 | O19: MAIAN | P19: Yes | Q19: 1 | R19: 0
A20: celo-mainnet_0xfB48f15480926A4ADf9116Dca468bDd2EE6C5F62 | B20: celo-mainnet | C20: 1 | D20: 0 | E20: Securify | G20: Securify | I20: Securify | K20: Securify | O20: MAIAN | P20: Yes | Q20: 1 | R20: 1
A21: ethereum-mainnet-arbitrum-1_0x141fa059441E0ca23ce184B6A78bafD2A517DdE8 | B21: ethereum-mainnet-arbitrum-1 | C21: 1 | D21: 0 | E21: Securify | G21: Securify | I21: Securify | K21: Securify | O21: MAIAN | P21: Yes | Q21: 1 | R21: 1
A22: ethereum-mainnet-arbitrum-1_0x39AE1032cF4B334a1Ed41cdD0833bdD7c7E7751E | B22: ethereum-mainnet-arbitrum-1 | C22: 1 | D22: 0 | E22: Securify | G22: Securify | I22: Securify | K22: Securify | O22: MAIAN | P22: Yes | Q22: 1 | R22: 1
A23: ethereum-mainnet-arbitrum-1_0x8A76fe7fA6da27f85a626c5C53730B38D13603d7 | B23: ethereum-mainnet-arbitrum-1 | C23: 1 | D23: 0 | E23: Securify | G23: Securify | I23: Securify | K23: Securify | O23: MAIAN | P23: Yes | Q23: 1 | R23: 1
A24: ethereum-mainnet-arbitrum-1_0xC311a21e6fEf769344EB1515588B9d535662a145 | B24: ethereum-mainnet-arbitrum-1 | C24: 1 | D24: 0 | O24: MAIAN | P24: Yes | Q24: 1 | R24: 0
A25: ethereum-mainnet-linea-1_0x1F8fbCf559f08FE7c4076f0d68DB861e1E27f95b | B25: ethereum-mainnet-linea-1 | C25: 1 | D25: 0 | O25: MAIAN | P25: Yes | Q25: 1 | R25: 0
A26: ethereum-mainnet-linea-1_0xBc933cEE67d2b1c08490ee8C51E2dF653a713534 | B26: ethereum-mainnet-linea-1 | C26: 1 | D26: 0 | E26: Securify | G26: Securify | I26: Securify | K26: Securify | O26: MAIAN | P26: Yes | Q26: 1 | R26: 1
A27: ethereum-mainnet-linea-1_0xb0B4b5847E35033766d5B49CD9C0fC40F459321F | B27: ethereum-mainnet-linea-1 | C27: 1 | D27: 0 | E27: Securify | G27: Securify | I27: Securify | K27: Securify | O27: MAIAN | P27: Yes | Q27: 1 | R27: 1
A28: ethereum-mainnet-mantle-1_0x000A744940eB5D857c0d61d97015DFc83107404F | B28: ethereum-mainnet-mantle-1 | C28: 1 | D28: 0 | E28: Securify | G28: Securify | I28: Securify | K28: Securify | O28: MAIAN | P28: Yes | Q28: 1 | R28: 1
A29: ethereum-mainnet-mantle-1_0x670052635a9850bb45882Cb2eCcF66bCff0F41B7 | B29: ethereum-mainnet-mantle-1 | C29: 1 | D29: 0 | E29: Securify | G29: Securify | I29: Securify | K29: Securify | O29: MAIAN | P29: Yes | Q29: 1 | R29: 1
A30: ethereum-mainnet-mantle-1_0x91E2186E93F0ECeDDCdf9850078F104daB085E79 | B30: ethereum-mainnet-mantle-1 | C30: 1 | D30: 0 | E30: Securify | G30: Securify | I30: Securify | K30: Securify | O30: MAIAN | P30: Yes | Q30: 1 | R30: 1
A31: ethereum-mainnet-mantle-1_0xc2e3A3C18ccb634622B57fF119a1C8C7f12e8C0c | B31: ethereum-mainnet-mantle-1 | C31: 1 | D31: 0 | E31: Securify | G31: Securify | I31: Securify | K31: Securify | O31: MAIAN | P31: Yes | Q31: 1 | R31: 1
A32: ethereum-mainnet-taiko-1_0x01f66BA71474d30De43d3c7B389F4019505B7F59 | B32: ethereum-mainnet-taiko-1 | C32: 1 | D32: 0 | O32: MAIAN | P32: Yes | Q32: 1 | R32: 0
A33: ethereum-mainnet-taiko-1_0x308a2A7d13B12ba26649F381C53F7e7C60d0D9c6 | B33: ethereum-mainnet-taiko-1 | C33: 1 | D33: 0 | E33: Securify | G33: Securify | I33: Securify | K33: Securify | O33: MAIAN | P33: Yes | Q33: 1 | R33: 1
A34: ethereum-mainnet-taiko-1_0x43DB2E5d6A83399e0530DC652286F655B18a2b07 | B34: ethereum-mainnet-taiko-1 | C34: 1 | D34: 0 | O34: MAIAN | P34: Yes | Q34: 1 | R34: 0
A35: ethereum-mainnet-taiko-1_0x4e52dD94e9BCfeFE3C78153bDfB0AB1d30687297 | B35: ethereum-mainnet-taiko-1 | C35: 1 | D35: 0 | E35: Securify | G35: Securify | I35: Securify | K35: Securify | O35: MAIAN | P35: Yes | Q35: 1 | R35: 1
A36: ethereum-mainnet-taiko-1_0xeb2502AeD3Cfd6E37e292c6B837a8FFF9a042367 | B36: ethereum-mainnet-taiko-1 | C36: 1 | D36: 0 | E36: Securify | G36: Securify | I36: Securify | K36: Securify | O36: MAIAN | P36: Yes | Q36: 1 | R36: 1
A37: ethereum-mainnet-unichain-1_0x68891f5F96695ECd7dEdBE2289D1b73426ae7864 | B37: ethereum-mainnet-unichain-1 | C37: 1 | D37: 0 | E37: Securify | G37: Securify | I37: Securify | K37: Securify | O37: MAIAN | P37: Yes | Q37: 1 | R37: 1
A38: ethereum-mainnet-unichain-1_0xAB3Ee2e897cf23c10e76d26aB4674fEFA376bc0d | B38: ethereum-mainnet-unichain-1 | C38: 1 | D38: 0 | E38: Securify | G38: Securify | I38: Securify | K38: Securify | O38: MAIAN | P38: Yes | Q38: 1 | R38: 1
A39: ethereum-mainnet-unichain-1_0xB79791184973589c38e114D43Eb8E4588C283A18 | B39: ethereum-mainnet-unichain-1 | C39: 1 | D39: 0 | E39: Securify | G39: Securify | I39: Securify | K39: Securify | O39: MAIAN | P39: Yes | Q39: 1 | R39: 1
A40: ethereum-mainnet-unichain-1_0xd8F5e7FAc317c638d2Fe4d07ab3f436ca6b5e5c7 | B40: ethereum-mainnet-unichain-1 | C40: 1 | D40: 0 | E40: Securify | G40: Securify | I40: Securify | K40: Securify | O40: MAIAN | P40: Yes | Q40: 1 | R40: 1
...
