Workbook

Sheet Executive_Summary
A1: LayerZero_Obfuscated — Bridge Bytecode Vulnerability Detection: Executive Summary
A3: KEY METRICS
A4: ="Addresses queried: "&COUNTA(Data!A2:A89)&" | Chains covered: 1" -> Addresses queried: 88 | Chains covered: 1
A5: ="Contracts with resolved bytecode: "&SUM(Data!C2:C89)&" | No bytecode (EOA/unverified): "&(COUNTA(Data!A2:A89)-SUM(Data!C2:C89)) -> Contracts with resolved bytecode: 88 | No bytecode (EOA/unverified): 0
A6: ="Overall vulnerable (>=1 tool): "&TEXT(Per_Vulnerability_Analysis!C15/Per_Vulnerability_Analysis!D15,"0.0%")&" of resolved contracts ("&Per_Vulnerability_Analysis!C15&"/"&Per_Vulnerability_Analysis!D15&")" -> Overall vulnerable (>=1 tool): 53.4% of resolved contracts (47/88)
A7: ="MAIAN flag rate: "&TEXT(Tool_Wise_Analysis!E4,"0.0%") -> MAIAN flag rate: 40.9%
A8: ="Mythril flag rate: "&TEXT(Tool_Wise_Analysis!E5,"0.0%") -> Mythril flag rate: 13.6%
A9: ="Securify flag rate: "&TEXT(Tool_Wise_Analysis!E6,"0.0%") -> Securify flag rate: 17.0%
A10: ="Tool agreement (Jaccard, MAIAN vs Securify): "&TEXT(Agreement_Jaccard!B20,"0.0000") -> Tool agreement (Jaccard, MAIAN vs Securify): 0.0851
A12: WHAT THE DATA SHOWS
A13: ="Highest-prevalence category: "&INDEX(Per_Vulnerability_Analysis!A4:A14,MATCH(MAX(Per_Vulnerability_Analysis!C4:C14),Per_Vulnerability_Analysis!C4:C14,0))&" ("&TEXT(MAX(Per_Vulnerability_Analysis!E4:E14),"0.0%")&" prevalence)" -> Highest-prevalence category: Ether Leak (40.9% prevalence)
A14: ="Only MAIAN, Mythril, Securify returned detections in this run; 4 of 11 tracked categories show zero hits — see Formula_Definitions / Per_Vulnerability_Analysis." -> Only MAIAN, Mythril, Securify returned detections in this run; 4 of 11 tracked categories show zero hits — see Formula_Definitions / Per_Vulnerability_Analysis.

Sheet Formula_Definitions
A1: Metric | B1: Formula | C1: Interpretation
A2: Detections D(v) | B2: COUNTIF(category_column, "<>") | C2: Number of contracts flagged for vulnerability v by its reporting tool
A3: Contracts w/ Bytecode | B3: SUM(Has_Bytecode) | C3: Denominator for prevalence; excludes EOA/unverified/no-code addresses
A4: Prevalence % | B4: D(v) / Contracts_w_Bytecode | C4: Share of resolved contracts flagged for category v
A5: Overall Vulnerable | B5: COUNTIFS(Has_Bytecode=1, Vulnerable="Yes") | C5: Contracts flagged by >=1 tool, among resolved contracts
A6: Flags per Contract | B6: COUNT of active categories triggered per row | C6: How many distinct categories fire on the same contract
A7: Tool Flag Rate % | B7: Tool-flagged contracts / Contracts w/ Bytecode | C7: Per-tool prevalence, independent of category breakdown
A8: Jaccard Index J(A,B) | B8: |A ∩ B| / |A ∪ B| | C8: Overlap between the two tools' flagged sets; 0=no overlap, 1=identical sets
A9: Vulnerable Rate % (chain) | B9: Vulnerable(chain) / With_Bytecode(chain) | C9: Per-chain share of resolved contracts flagged

Sheet Per_Vulnerability_Analysis
A1: LayerZero_Obfuscated — Per-Vulnerability Analysis
A3: Category | B3: Detecting Tool | C3: Detections D(v) | D3: Contracts w/ Bytecode | E3: Prevalence % | F3: Note
A4: Reentrancy | B4: Securify | C4: =COUNTIF(Data!E2:E89,"<>") -> 15 | D4: =SUM(Data!C2:C89) -> 88 | E4: =IF(D4=0,0,C4/D4) -> 0.17045455 | F4: Bytecode-level detection
A5: Integer | B5: Not covered (0 detections) | C5: =COUNTIF(Data!F2:F89,"<>") -> 0 | D5: =SUM(Data!C2:C89) -> 88 | E5: =IF(D5=0,0,C5/D5) -> 0 | F5: Zero detections this run
A6: Access Control | B6: Securify | C6: =COUNTIF(Data!G2:G89,"<>") -> 15 | D6: =SUM(Data!C2:C89) -> 88 | E6: =IF(D6=0,0,C6/D6) -> 0.17045455 | F6: Bytecode-level detection
A7: Delegatecall | B7: Not covered (0 detections) | C7: =COUNTIF(Data!H2:H89,"<>") -> 0 | D7: =SUM(Data!C2:C89) -> 88 | E7: =IF(D7=0,0,C7/D7) -> 0 | F7: Zero detections this run
A8: Unchecked Call | B8: Securify | C8: =COUNTIF(Data!I2:I89,"<>") -> 15 | D8: =SUM(Data!C2:C89) -> 88 | E8: =IF(D8=0,0,C8/D8) -> 0.17045455 | F8: Bytecode-level detection
A9: Timestamp | B9: Not covered (0 detections) | C9: =COUNTIF(Data!J2:J89,"<>") -> 0 | D9: =SUM(Data!C2:C89) -> 88 | E9: =IF(D9=0,0,C9/D9) -> 0 | F9: Zero detections this run
A10: TOD | B10: Securify | C10: =COUNTIF(Data!K2:K89,"<>") -> 15 | D10: =SUM(Data!C2:C89) -> 88 | E10: =IF(D10=0,0,C10/D10) -> 0.17045455 | F10: Bytecode-level detection
A11: DoS | B11: Mythril | C11: =COUNTIF(Data!L2:L89,"<>") -> 12 | D11: =SUM(Data!C2:C89) -> 88 | E11: =IF(D11=0,0,C11/D11) -> 0.13636364 | F11: Bytecode-level detection
A12: Selfdestruct | B12: Not covered (0 detections) | C12: =COUNTIF(Data!M2:M89,"<>") -> 0 | D12: =SUM(Data!C2:C89) -> 88 | E12: =IF(D12=0,0,C12/D12) -> 0 | F12: Zero detections this run
A13: Locked Ether | B13: MAIAN | C13: =COUNTIF(Data!N2:N89,"<>") -> 2 | D13: =SUM(Data!C2:C89) -> 88 | E13: =IF(D13=0,0,C13/D13) -> 0.022727273 | F13: Bytecode-level detection
A14: Ether Leak | B14: MAIAN | C14: =COUNTIF(Data!O2:O89,"<>") -> 36 | D14: =SUM(Data!C2:C89) -> 88 | E14: =IF(D14=0,0,C14/D14) -> 0.40909091 | F14: Bytecode-level detection
A15: OVERALL VULNERABLE | B15: Any tool | C15: =COUNTIFS(Data!C2:C89,1,Data!P2:P89,"Yes") -> 47 | D15: =SUM(Data!C2:C89) -> 88 | E15: =IF(D15=0,0,C15/D15) -> 0.53409091 | F15: Flagged by >=1 tool

Sheet Detection_Count_Analysis
A1: LayerZero_Obfuscated — Detection Count Analysis
A3: Flags per contract = count of (Reentrancy, Access Control, Unchecked Call, TOD, DoS, Locked Ether, Ether Leak) triggered on that contract
A5: Flags per Contract | B5: Contract Count | C5: % of Bytecode Contracts | D5: Note
A6: 0 categories flagged | B6: =SUMPRODUCT((Data!C2:C89=1)*(((Data!E2:E89<>"")+(Data!G2:G89<>"")+(Data!I2:I89<>"")+(Data!K2:K89<>"")+(Data!L2:L89<>"")+(Data!N2:N89<>"")+(Data!O2:O89<>""))=0)) -> 41 | C6: =IF(SUM(Data!C2:C89)=0,0,B6/SUM(Data!C2:C89)) -> 0.46590909
A7: 1 categories flagged | B7: =SUMPRODUCT((Data!C2:C89=1)*(((Data!E2:E89<>"")+(Data!G2:G89<>"")+(Data!I2:I89<>"")+(Data!K2:K89<>"")+(Data!L2:L89<>"")+(Data!N2:N89<>"")+(Data!O2:O89<>""))=1)) -> 30 | C7: =IF(SUM(Data!C2:C89)=0,0,B7/SUM(Data!C2:C89)) -> 0.34090909
A8: 2 categories flagged | B8: =SUMPRODUCT((Data!C2:C89=1)*(((Data!E2:E89<>"")+(Data!G2:G89<>"")+(Data!I2:I89<>"")+(Data!K2:K89<>"")+(Data!L2:L89<>"")+(Data!N2:N89<>"")+(Data!O2:O89<>""))=2)) -> 2 | C8: =IF(SUM(Data!C2:C89)=0,0,B8/SUM(Data!C2:C89)) -> 0.022727273
A9: 3 categories flagged | B9: =SUMPRODUCT((Data!C2:C89=1)*(((Data!E2:E89<>"")+(Data!G2:G89<>"")+(Data!I2:I89<>"")+(Data!K2:K89<>"")+(Data!L2:L89<>"")+(Data!N2:N89<>"")+(Data!O2:O89<>""))=3)) -> 0 | C9: =IF(SUM(Data!C2:C89)=0,0,B9/SUM(Data!C2:C89)) -> 0
A10: 4 categories flagged | B10: =SUMPRODUCT((Data!C2:C89=1)*(((Data!E2:E89<>"")+(Data!G2:G89<>"")+(Data!I2:I89<>"")+(Data!K2:K89<>"")+(Data!L2:L89<>"")+(Data!N2:N89<>"")+(Data!O2:O89<>""))=4)) -> 3 | C10: =IF(SUM(Data!C2:C89)=0,0,B10/SUM(Data!C2:C89)) -> 0.034090909
A11: 5 categories flagged | B11: =SUMPRODUCT((Data!C2:C89=1)*(((Data!E2:E89<>"")+(Data!G2:G89<>"")+(Data!I2:I89<>"")+(Data!K2:K89<>"")+(Data!L2:L89<>"")+(Data!N2:N89<>"")+(Data!O2:O89<>""))=5)) -> 8 | C11: =IF(SUM(Data!C2:C89)=0,0,B11/SUM(Data!C2:C89)) -> 0.090909091
A12: 6 categories flagged | B12: =SUMPRODUCT((Data!C2:C89=1)*(((Data!E2:E89<>"")+(Data!G2:G89<>"")+(Data!I2:I89<>"")+(Data!K2:K89<>"")+(Data!L2:L89<>"")+(Data!N2:N89<>"")+(Data!O2:O89<>""))=6)) -> 4 | C12: =IF(SUM(Data!C2:C89)=0,0,B12/SUM(Data!C2:C89)) -> 0.045454545
A13: 7 categories flagged | B13: =SUMPRODUCT((Data!C2:C89=1)*(((Data!E2:E89<>"")+(Data!G2:G89<>"")+(Data!I2:I89<>"")+(Data!K2:K89<>"")+(Data!L2:L89<>"")+(Data!N2:N89<>"")+(Data!O2:O89<>""))=7)) -> 0 | C13: =IF(SUM(Data!C2:C89)=0,0,B13/SUM(Data!C2:C89)) -> 0
A14: Total contracts w/ bytecode | B14: =SUM(B6:B13) -> 88
A16: Total raw detections (sum across all 11 categories) | B16: =COUNTIF(Data!E2:E89,"<>")+COUNTIF(Data!F2:F89,"<>")+COUNTIF(Data!G2:G89,"<>")+COUNTIF(Data!H2:H89,"<>")+COUNTIF(Data!I2:I89,"<>")+COUNTIF(Data!J2:J89,"<>")+COUNTIF(Data!K2:K89,"<>")+COUNTIF(Data!L2:L89,"<>")+COUNTIF(Data!M2:M89,"<>")+COUNTIF(Data!N2:N89,"<>")+COUNTIF(Data!O2:O89,"<>") -> 110
A17: Avg detections per bytecode-resolved contract | B17: =B16/SUM(Data!C2:C89) -> 1.25

Sheet Tool_Wise_Analysis
A1: LayerZero_Obfuscated — Tool-wise Analysis
A3: Tool | B3: Categories Covered | C3: Contracts Flagged | D3: Contracts w/ Bytecode | E3: Flag Rate % | F3: Note
A4: MAIAN | B4: Locked Ether, Ether Leak | C4: =SUM(Data!Q2:Q89) -> 36 | D4: =SUM(Data!C2:C89) -> 88 | E4: =IF(D4=0,0,C4/D4) -> 0.40909091 | F4: Symbolic execution, financial-flow analysis
A5: Mythril | B5: DoS | C5: =SUM(Data!R2:R89) -> 12 | D5: =SUM(Data!C2:C89) -> 88 | E5: =IF(D5=0,0,C5/D5) -> 0.13636364 | F5: Bytecode symbolic execution
A6: Securify | B6: Reentrancy, Access Control, Unchecked Call, TOD | C6: =SUM(Data!S2:S89) -> 15 | D6: =SUM(Data!C2:C89) -> 88 | E6: =IF(D6=0,0,C6/D6) -> 0.17045455
A7: Others (n/a) | B7: Integer, Delegatecall, Timestamp, Selfdestruct | C7: 0 | D7: =SUM(Data!C2:C89) -> 88 | E7: 0 | F7: Zero detections in this run

Sheet Contract_Level_Statistics
A1: LayerZero_Obfuscated — Contract-Level Statistics
A3: Addresses queried | B3: =COUNTA(Data!A2:A89) -> 88
A4: Chains covered | B4: 1
A5: Contracts analyzed (bytecode resolved / detection ran) | B5: =SUM(Data!C2:C89) -> 88
A6: Not analyzed (EOA / unverified / not found) | B6: =COUNTA(Data!A2:A89)-SUM(Data!C2:C89) -> 0
A7: ...of which bytecode text is blank in source export | B7: =SUMPRODUCT((Data!C2:C89=1)*(Data!D2:D89=0)) -> 0 | D7: Detections still recorded; only the raw bytecode string is missing from the export
A8: Avg bytecode length (hex chars, where text available) | B8: =IF(SUMPRODUCT((Data!C2:C89=1)*(Data!D2:D89>0))=0,0,SUMIF(Data!C2:C89,1,Data!D2:D89)/SUMPRODUCT((Data!C2:C89=1)*(Data!D2:D89>0))) -> 1380.1136 | D8: Rounded to nearest char; excludes blank-text rows
A9: Min bytecode length (where text available) | B9: =_xlfn.MINIFS(Data!D2:D89,Data!C2:C89,1,Data!D2:D89,">0") -> 127
A10: Max bytecode length | B10: =_xlfn.MAXIFS(Data!D2:D89,Data!C2:C89,1) -> 35437
A12: Per-Chain Breakdown
A13: Chain | B13: Addresses | C13: With Bytecode | D13: Vulnerable Rate %
A14: All (chain not encoded in address) | B14: =COUNTIF(Data!B2:B89,A14) -> 88 | C14: =COUNTIFS(Data!B2:B89,A14,Data!C2:C89,1) -> 88 | D14: =IF(C14=0,0,(COUNTIFS(Data!B2:B89,A14,Data!C2:C89,1,Data!P2:P89,"Yes"))/C14) -> 0.53409091

Sheet Agreement_Jaccard
A1: LayerZero_Obfuscated — Tool Agreement (Jaccard Index)
A2: Pairwise agreement among 3 tools (MAIAN, Mythril, Securify), among contracts with bytecode.
A4: MAIAN vs Mythril
A5: Set | B5: Count | C5: % of Bytecode Contracts | D5: Definition
A6: Both flag (A ∩ B) | B6: =SUMPRODUCT((Data!C2:C89=1)*(Data!Q2:Q89=1)*(Data!R2:R89=1)) -> 4 | C6: =IF(SUM(Data!C2:C89)=0,0,B6/SUM(Data!C2:C89)) -> 0.045454545 | D6: MAIAN AND Mythril
A7: Only MAIAN flags (A \ B) | B7: =SUMPRODUCT((Data!C2:C89=1)*(Data!Q2:Q89=1)*(Data!R2:R89=0)) -> 32 | C7: =IF(SUM(Data!C2:C89)=0,0,B7/SUM(Data!C2:C89)) -> 0.36363636 | D7: MAIAN only
A8: Only Mythril flags (B \ A) | B8: =SUMPRODUCT((Data!C2:C89=1)*(Data!Q2:Q89=0)*(Data!R2:R89=1)) -> 8 | C8: =IF(SUM(Data!C2:C89)=0,0,B8/SUM(Data!C2:C89)) -> 0.090909091 | D8: Mythril only
A9: Neither flags | B9: =SUMPRODUCT((Data!C2:C89=1)*(Data!Q2:Q89=0)*(Data!R2:R89=0)) -> 44 | C9: =IF(SUM(Data!C2:C89)=0,0,B9/SUM(Data!C2:C89)) -> 0.5 | D9: Resolved contract, no flag from either tool
A10: Union (A ∪ B) | B10: =B6+B7+B8 -> 44
A11: Jaccard Index J(MAIAN,Mythril) = |A∩B| / |A∪B| | B11: =IF(B10=0,0,B6/B10) -> 0.090909091
A13: MAIAN vs Securify
A14: Set | B14: Count | C14: % of Bytecode Contracts | D14: Definition
A15: Both flag (A ∩ B) | B15: =SUMPRODUCT((Data!C2:C89=1)*(Data!Q2:Q89=1)*(Data!S2:S89=1)) -> 4 | C15: =IF(SUM(Data!C2:C89)=0,0,B15/SUM(Data!C2:C89)) -> 0.045454545 | D15: MAIAN AND Securify
A16: Only MAIAN flags (A \ B) | B16: =SUMPRODUCT((Data!C2:C89=1)*(Data!Q2:Q89=1)*(Data!S2:S89=0)) -> 32 | C16: =IF(SUM(Data!C2:C89)=0,0,B16/SUM(Data!C2:C89)) -> 0.36363636 | D16: MAIAN only
A17: Only Securify flags (B \ A) | B17: =SUMPRODUCT((Data!C2:C89=1)*(Data!Q2:Q89=0)*(Data!S2:S89=1)) -> 11 | C17: =IF(SUM(Data!C2:C89)=0,0,B17/SUM(Data!C2:C89)) -> 0.125 | D17: Securify only
A18: Neither flags | B18: =SUMPRODUCT((Data!C2:C89=1)*(Data!Q2:Q89=0)*(Data!S2:S89=0)) -> 41 | C18: =IF(SUM(Data!C2:C89)=0,0,B18/SUM(Data!C2:C89)) -> 0.46590909 | D18: Resolved contract, no flag from either tool
A19: Union (A ∪ B) | B19: =B15+B16+B17 -> 47
A20: Jaccard Index J(MAIAN,Securify) = |A∩B| / |A∪B| | B20: =IF(B19=0,0,B15/B19) -> 0.085106383
A22: Mythril vs Securify
A23: Set | B23: Count | C23: % of Bytecode Contracts | D23: Definition
A24: Both flag (A ∩ B) | B24: =SUMPRODUCT((Data!C2:C89=1)*(Data!R2:R89=1)*(Data!S2:S89=1)) -> 12 | C24: =IF(SUM(Data!C2:C89)=0,0,B24/SUM(Data!C2:C89)) -> 0.13636364 | D24: Mythril AND Securify
A25: Only Mythril flags (A \ B) | B25: =SUMPRODUCT((Data!C2:C89=1)*(Data!R2:R89=1)*(Data!S2:S89=0)) -> 0 | C25: =IF(SUM(Data!C2:C89)=0,0,B25/SUM(Data!C2:C89)) -> 0 | D25: Mythril only
A26: Only Securify flags (B \ A) | B26: =SUMPRODUCT((Data!C2:C89=1)*(Data!R2:R89=0)*(Data!S2:S89=1)) -> 3 | C26: =IF(SUM(Data!C2:C89)=0,0,B26/SUM(Data!C2:C89)) -> 0.034090909 | D26: Securify only
A27: Neither flags | B27: =SUMPRODUCT((Data!C2:C89=1)*(Data!R2:R89=0)*(Data!S2:S89=0)) -> 73 | C27: =IF(SUM(Data!C2:C89)=0,0,B27/SUM(Data!C2:C89)) -> 0.82954545 | D27: Resolved contract, no flag from either tool
A28: Union (A ∪ B) | B28: =B24+B25+B26 -> 15
A29: Jaccard Index J(Mythril,Securify) = |A∩B| / |A∪B| | B29: =IF(B28=0,0,B24/B28) -> 0.8

Sheet Key_Findings
A1: LayerZero_Obfuscated — Key Findings
A3: ="1. Bytecode resolution: "&SUM(Data!C2:C89)&" of "&COUNTA(Data!A2:A89)&" queried addresses ("&TEXT(SUM(Data!C2:C89)/COUNTA(Data!A2:A89),"0.0%")&") resolved to deployed bytecode; the rest are EOAs, unverified, or not found on-chain." -> 1. Bytecode resolution: 88 of 88 queried addresses (100.0%) resolved to deployed bytecode; the rest are EOAs, unverified, or not found on-chain.
A4: ="2. Detection coverage: only MAIAN, Mythril, Securify produced any detections. Integer, Delegatecall, Timestamp, Selfdestruct all show zero hits in this bytecode run." -> 2. Detection coverage: only MAIAN, Mythril, Securify produced any detections. Integer, Delegatecall, Timestamp, Selfdestruct all show zero hits in this bytecode run.
A5: ="3. Securify flag rate ("&TEXT(Tool_Wise_Analysis!E6,"0.0%")&") vs MAIAN flag rate ("&TEXT(Tool_Wise_Analysis!E4,"0.0%")&") among resolved contracts." -> 3. Securify flag rate (17.0%) vs MAIAN flag rate (40.9%) among resolved contracts.
A6: ="4. Tool overlap: Jaccard(MAIAN, Securify) = "&TEXT(Agreement_Jaccard!B20,"0.0000")&" — "&Agreement_Jaccard!B15&" contracts triggered both tools, "&Agreement_Jaccard!B16&" only MAIAN, "&Agreement_Jaccard!B17&" only Securify." -> 4. Tool overlap: Jaccard(MAIAN, Securify) = 0.0851 — 4 contracts triggered both tools, 32 only MAIAN, 11 only Securify.
A7: ="5. "&Per_Vulnerability_Analysis!C15&" of "&Per_Vulnerability_Analysis!D15&" resolved contracts ("&TEXT(Per_Vulnerability_Analysis!C15/Per_Vulnerability_Analysis!D15,"0.0%")&") were flagged by at least one tool." -> 5. 47 of 88 resolved contracts (53.4%) were flagged by at least one tool.

Sheet Why_These_Results
A1: LayerZero Obfuscated — Why These Results: Forensic Explanation of the Detection Pattern
A2: Findings below combine (a) direct inspection of the raw BOSC-obfuscated bytecode where available, and (b) matched-pair comparison against the ORIGINAL (unobfuscated) run on the same addresses.
A4: 1. WHY THE TOOL SET FIRING HERE IS Mythril/MAIAN/Securify
A5: LayerZero's obfuscated run retains all three tools (Mythril, MAIAN, Securify) actually firing, unlike CCIP (no Mythril) and Axelar (Mythril only). This makes LayerZero one of the more complete obfuscated datasets for a fair category-level comparison against its original run.
A7: 2. WHAT CHANGED VERSUS THE ORIGINAL (UNOBFUSCATED) BYTECODE, SAME CONTRACTS
A8: On the 72 addresses successfully analyzed in BOTH the original and obfuscated runs: original vulnerable rate 59.7% -> obfuscated vulnerable rate 43.1%. 25 contracts that were flagged originally evaded ALL detection after obfuscation (58.1% evasion rate among originally-flagged contracts); 13 contracts that were clean originally were newly flagged after obfuscation.
A9: LayerZero is one of the protocols where obfuscation also produced NEW detections (13 contracts flagged that were clean originally) - not just hidden ones. This suggests obfuscation transformations here (e.g. struct-packing or flat-filing) can introduce code patterns that trip a tool's heuristic without there being a new genuine bug, which is itself evidence that these detectors respond to surface code structure rather than purely semantic vulnerability.
A11: 3. BYTECODE-LEVEL OBSERVATIONS
A12: Bytecode text is available for 88 of 88 obfuscated contracts, ranging 127-35437 hex characters (median 298). Note: BOSC's obfuscated bytecode export in this dataset is not formatted identically to the raw eth_getCode output used for the original bytecode analysis (no 0x prefix, and apparent leading-zero/byte normalization), so direct length-for-length comparison against the original bytecode reports should be treated as illustrative rather than exact.
A13: Average CALLVALUE (opcode 0x34) occurrences per contract: 1.77.
A15: SUMMARY
A16: LayerZero obfuscated shows a 16.7% point drop in matched-contract vulnerable rate, with both evasion (25 contracts) and some new detections (13 contracts) - consistent with obfuscation partially, not completely, defeating this dataset's bytecode-level tools.

Sheet Data
A1: Address | B1: Chain | C1: Has_Bytecode | D1: Bytecode_Length | E1: Reentrancy | F1: Integer | G1: Access_Control | H1: Delegatecall | I1: Unchecked_Call | J1: Timestamp | K1: TOD | L1: DoS | M1: Selfdestruct | N1: Locked_Ether | O1: Ether_Leak | P1: Vulnerable | Q1: MAIAN_Flag | R1: Mythril_Flag | S1: Securify_Flag
A2: 0x0171830E6C8d7f28cbE35A2045919a415B04a5fF | B2: All (chain not encoded in address) | C2: 1 | D2: 127 | P2: No | Q2: 0 | R2: 0 | S2: 0
A3: 0x0408804C5dcD9796F22558464E6fE5bDdF16A7c7 | B3: All (chain not encoded in address) | C3: 1 | D3: 297 | P3: No | Q3: 0 | R3: 0 | S3: 0
A4: 0x05B52859Adb077a7b7D6277a512aEfEFbaDDc9C8 | B4: All (chain not encoded in address) | C4: 1 | D4: 297 | O4: MAIAN | P4: Yes | Q4: 1 | R4: 0 | S4: 0
A5: 0x068EC1f0bd53cf86923BbB0986046be6af3f5922 | B5: All (chain not encoded in address) | C5: 1 | D5: 271 | P5: No | Q5: 0 | R5: 0 | S5: 0
A6: 0x06e56abD0cb3C88880644bA3C534A498cA18E5C8 | B6: All (chain not encoded in address) | C6: 1 | D6: 2415 | P6: No | Q6: 0 | R6: 0 | S6: 0
A7: 0x14a6A3d612A04225df4825A365688F33DA4969De | B7: All (chain not encoded in address) | C7: 1 | D7: 127 | P7: No | Q7: 0 | R7: 0 | S7: 0
A8: 0x1641D737e97916f1400CB6BA032eceE765484D9C | B8: All (chain not encoded in address) | C8: 1 | D8: 127 | P8: No | Q8: 0 | R8: 0 | S8: 0
A9: 0x166CAb679EBDB0853055522D3B523621b94029a1 | B9: All (chain not encoded in address) | C9: 1 | D9: 26349 | O9: MAIAN | P9: Yes | Q9: 1 | R9: 0 | S9: 0
A10: 0x173272739Bd7Aa6e4e214714048a9fE699453059 | B10: All (chain not encoded in address) | C10: 1 | D10: 297 | O10: MAIAN | P10: Yes | Q10: 1 | R10: 0 | S10: 0
A11: 0x1BAcC2205312534375c8d1801C27D28370656cFf | B11: All (chain not encoded in address) | C11: 1 | D11: 1180 | E11: Securify | G11: Securify | I11: Securify | K11: Securify | P11: Yes | Q11: 0 | R11: 0 | S11: 1
A12: 0x1Bef2d7C5c60fD826Cc1b1f29cA357Af2d0Ae2c6 | B12: All (chain not encoded in address) | C12: 1 | D12: 297 | O12: MAIAN | P12: Yes | Q12: 1 | R12: 0 | S12: 0
A13: 0x1E1E9A04735B9ca509eF8a46255f5104C10C6e99 | B13: All (chain not encoded in address) | C13: 1 | D13: 298 | E13: Securify | G13: Securify | I13: Securify | K13: Securify | L13: Mythril | O13: MAIAN | P13: Yes | Q13: 1 | R13: 1 | S13: 1
A14: 0x1b368a0d7c57080a01054862114B5a42e54CBb98 | B14: All (chain not encoded in address) | C14: 1 | D14: 1521 | O14: MAIAN | P14: Yes | Q14: 1 | R14: 0 | S14: 0
A15: 0x1ccBf0db9C192d969de57E25B3fF09A25bb1D862 | B15: All (chain not encoded in address) | C15: 1 | D15: 806 | O15: MAIAN | P15: Yes | Q15: 1 | R15: 0 | S15: 0
A16: 0x1dDbaF8b75F2291A97C22428afEf411b7bB19e28 | B16: All (chain not encoded in address) | C16: 1 | D16: 297 | O16: MAIAN | P16: Yes | Q16: 1 | R16: 0 | S16: 0
A17: 0x24D7ff228a81e827Efc29ec45E7b30a99B96C653 | B17: All (chain not encoded in address) | C17: 1 | D17: 1520 | O17: MAIAN | P17: Yes | Q17: 1 | R17: 0 | S17: 0
A18: 0x28eEE23B2b6C5582112037FD43A4d8C359F54D4D | B18: All (chain not encoded in address) | C18: 1 | D18: 1522 | O18: MAIAN | P18: Yes | Q18: 1 | R18: 0 | S18: 0
A19: 0x2B79f3C2EE059E465a24bf5A2F4FE989546053B1 | B19: All (chain not encoded in address) | C19: 1 | D19: 737 | O19: MAIAN | P19: Yes | Q19: 1 | R19: 0 | S19: 0
A20: 0x2F0788fFbf8fCa58B2ea10c05F0CA9931ffC8978 | B20: All (chain not encoded in address) | C20: 1 | D20: 297 | O20: MAIAN | P20: Yes | Q20: 1 | R20: 0 | S20: 0
A21: 0x2F4C6eeA955e95e6d65E08620D980C0e0e92211F | B21: All (chain not encoded in address) | C21: 1 | D21: 575 | P21: No | Q21: 0 | R21: 0 | S21: 0
A22: 0x2F64656569c098fdfb0bD0ab2f3616005E295810 | B22: All (chain not encoded in address) | C22: 1 | D22: 297 | P22: No | Q22: 0 | R22: 0 | S22: 0
A23: 0x2c83731aa397cd8E6bF8C77d9090b8845581d08c | B23: All (chain not encoded in address) | C23: 1 | D23: 298 | E23: Securify | G23: Securify | I23: Securify | K23: Securify | L23: Mythril | O23: MAIAN | P23: Yes | Q23: 1 | R23: 1 | S23: 1
A24: 0x2e2AF282E98bfADed5dd6EC51c7240D818DDBBD9 | B24: All (chain not encoded in address) | C24: 1 | D24: 1520 | O24: MAIAN | P24: Yes | Q24: 1 | R24: 0 | S24: 0
A25: 0x30F776548f9Aaad0935E2c03e930d10F15cE558f | B25: All (chain not encoded in address) | C25: 1 | D25: 127 | P25: No | Q25: 0 | R25: 0 | S25: 0
A26: 0x31CAe3B7fB82d847621859fb1585353c5720660D | B26: All (chain not encoded in address) | C26: 1 | D26: 297 | P26: No | Q26: 0 | R26: 0 | S26: 0
A27: 0x32042142DD551b4EbE17B6FEd53131dd4b4eEa06 | B27: All (chain not encoded in address) | C27: 1 | D27: 1180 | E27: Securify | G27: Securify | I27: Securify | K27: Securify | L27: Mythril | P27: Yes | Q27: 0 | R27: 1 | S27: 1
A28: 0x3258287147FB7887d8A643006e26E19368057377 | B28: All (chain not encoded in address) | C28: 1 | D28: 2494 | O28: MAIAN | P28: Yes | Q28: 1 | R28: 0 | S28: 0
A29: 0x377530cdA84DFb2673bF4d145DCF0C4D7fdcB5b6 | B29: All (chain not encoded in address) | C29: 1 | D29: 575 | P29: No | Q29: 0 | R29: 0 | S29: 0
A30: 0x38340337f9ADF5D76029Ab3A667d34E5a032F7BA | B30: All (chain not encoded in address) | C30: 1 | D30: 297 | P30: No | Q30: 0 | R30: 0 | S30: 0
A31: 0x3C156b1f625D2B4E004D43E91aC2c3a719C29c7B | B31: All (chain not encoded in address) | C31: 1 | D31: 1180 | E31: Securify | G31: Securify | I31: Securify | K31: Securify | L31: Mythril | P31: Yes | Q31: 0 | R31: 1 | S31: 1
A32: 0x3b4453D9e884dA5A8C917Ab7679D66c92069e7F7 | B32: All (chain not encoded in address) | C32: 1 | D32: 127 | P32: No | Q32: 0 | R32: 0 | S32: 0
A33: 0x42b4E9C6495B4cFDaE024B1eC32E09F28027620e | B33: All (chain not encoded in address) | C33: 1 | D33: 1180 | E33: Securify | G33: Securify | I33: Securify | K33: Securify | P33: Yes | Q33: 0 | R33: 0 | S33: 1
A34: 0x43CFcc293CdF99F7D021F21FfD443f174AB0e843 | B34: All (chain not encoded in address) | C34: 1 | D34: 1520 | O34: MAIAN | P34: Yes | Q34: 1 | R34: 0 | S34: 0
A35: 0x44289609cc6781fa2C665796b6c5AAbf9FFceDC5 | B35: All (chain not encoded in address) | C35: 1 | D35: 1180 | E35: Securify | G35: Securify | I35: Securify | K35: Securify | L35: Mythril | P35: Yes | Q35: 0 | R35: 1 | S35: 1
A36: 0x4E341b9Cf90514A5b7dfec2c9A1f20AA4514C260 | B36: All (chain not encoded in address) | C36: 1 | D36: 298 | E36: Securify | G36: Securify | I36: Securify | K36: Securify | L36: Mythril | O36: MAIAN | P36: Yes | Q36: 1 | R36: 1 | S36: 1
A37: 0x4Fc3f4A38Acd6E4cC0ccBc04B3Dd1CCAeFd7F3Cd | B37: All (chain not encoded in address) | C37: 1 | D37: 297 | P37: No | Q37: 0 | R37: 0 | S37: 0
A38: 0x52fFEeaE5Ffa89D4b31c72F87ead3699FCB79e40 | B38: All (chain not encoded in address) | C38: 1 | D38: 271 | P38: No | Q38: 0 | R38: 0 | S38: 0
A39: 0x5440E2097C41F8e0a8551521d569c71de70fDe23 | B39: All (chain not encoded in address) | C39: 1 | D39: 297 | P39: No | Q39: 0 | R39: 0 | S39: 0
A40: 0x552661d1C85F256E008eE2315103c80fd1E298DF | B40: All (chain not encoded in address) | C40: 1 | D40: 297 | P40: No | Q40: 0 | R40: 0 | S40: 0
...
