Workbook

Sheet Executive_Summary
A1: Wormhole_Obfuscated — Bridge Bytecode Vulnerability Detection: Executive Summary
A3: KEY METRICS
A4: ="Addresses queried: "&COUNTA(Data!A2:A87)&" | Chains covered: 12" -> Addresses queried: 86 | Chains covered: 12
A5: ="Contracts with resolved bytecode: "&SUM(Data!C2:C87)&" | No bytecode (EOA/unverified): "&(COUNTA(Data!A2:A87)-SUM(Data!C2:C87)) -> Contracts with resolved bytecode: 86 | No bytecode (EOA/unverified): 0
A6: ="Overall vulnerable (>=1 tool): "&TEXT(Per_Vulnerability_Analysis!C15/Per_Vulnerability_Analysis!D15,"0.0%")&" of resolved contracts ("&Per_Vulnerability_Analysis!C15&"/"&Per_Vulnerability_Analysis!D15&")" -> Overall vulnerable (>=1 tool): 16.3% of resolved contracts (14/86)
A7: ="MAIAN flag rate: "&TEXT(Tool_Wise_Analysis!E4,"0.0%") -> MAIAN flag rate: 15.1%
A8: ="Mythril flag rate: "&TEXT(Tool_Wise_Analysis!E5,"0.0%") -> Mythril flag rate: 5.8%
A9: ="Securify flag rate: "&TEXT(Tool_Wise_Analysis!E6,"0.0%") -> Securify flag rate: 5.8%
A10: ="Tool agreement (Jaccard, MAIAN vs Mythril): "&TEXT(Agreement_Jaccard!B11,"0.0000") -> Tool agreement (Jaccard, MAIAN vs Mythril): 0.2857
A12: WHAT THE DATA SHOWS
A13: ="Highest-prevalence category: "&INDEX(Per_Vulnerability_Analysis!A4:A14,MATCH(MAX(Per_Vulnerability_Analysis!C4:C14),Per_Vulnerability_Analysis!C4:C14,0))&" ("&TEXT(MAX(Per_Vulnerability_Analysis!E4:E14),"0.0%")&" prevalence)" -> Highest-prevalence category: Ether Leak (15.1% prevalence)
A14: ="Only MAIAN, Mythril, Securify returned detections in this run; 5 of 11 tracked categories show zero hits — see Formula_Definitions / Per_Vulnerability_Analysis." -> Only MAIAN, Mythril, Securify returned detections in this run; 5 of 11 tracked categories show zero hits — see Formula_Definitions / Per_Vulnerability_Analysis.

Sheet Formula_Definitions
A1: Metric | B1: Formula | C1: Interpretation
A2: Detections D(v) | B2: COUNTIF(category_column, "<>") | C2: Number of contracts flagged for vulnerability v by its reporting tool
A3: Contracts w/ Bytecode | B3: SUM(Has_Bytecode) | C3: Denominator for prevalence; excludes EOA/unverified/no-code addresses
A4: Prevalence % | B4: D(v) / Contracts_w_Bytecode | C4: Share of resolved contracts flagged for category v
A5: Overall Vulnerable | B5: COUNTIFS(Has_Bytecode=1, Vulnerable="Yes") | C5: Contracts flagged by >=1 tool, among resolved contracts
A6: Flags per Contract | B6: COUNT of active categories triggered per row | C6: How many distinct categories fire on the same contract
A7: Tool Flag Rate % | B7: Tool-flagged contracts / Contracts w/ Bytecode | C7: Per-tool prevalence, independent of category breakdown
A8: Jaccard Index J(A,B) | B8: |A ∩ B| / |A ∪ B| | C8: Overlap between the two tools' flagged sets; 0=no overlap, 1=identical sets
A9: Vulnerable Rate % (chain) | B9: Vulnerable(chain) / With_Bytecode(chain) | C9: Per-chain share of resolved contracts flagged

Sheet Per_Vulnerability_Analysis
A1: Wormhole_Obfuscated — Per-Vulnerability Analysis
A3: Category | B3: Detecting Tool | C3: Detections D(v) | D3: Contracts w/ Bytecode | E3: Prevalence % | F3: Note
A4: Reentrancy | B4: Securify | C4: =COUNTIF(Data!E2:E87,"<>") -> 5 | D4: =SUM(Data!C2:C87) -> 86 | E4: =IF(D4=0,0,C4/D4) -> 0.058139535 | F4: Bytecode-level detection
A5: Integer | B5: Not covered (0 detections) | C5: =COUNTIF(Data!F2:F87,"<>") -> 0 | D5: =SUM(Data!C2:C87) -> 86 | E5: =IF(D5=0,0,C5/D5) -> 0 | F5: Zero detections this run
A6: Access Control | B6: Securify | C6: =COUNTIF(Data!G2:G87,"<>") -> 5 | D6: =SUM(Data!C2:C87) -> 86 | E6: =IF(D6=0,0,C6/D6) -> 0.058139535 | F6: Bytecode-level detection
A7: Delegatecall | B7: Not covered (0 detections) | C7: =COUNTIF(Data!H2:H87,"<>") -> 0 | D7: =SUM(Data!C2:C87) -> 86 | E7: =IF(D7=0,0,C7/D7) -> 0 | F7: Zero detections this run
A8: Unchecked Call | B8: Securify | C8: =COUNTIF(Data!I2:I87,"<>") -> 5 | D8: =SUM(Data!C2:C87) -> 86 | E8: =IF(D8=0,0,C8/D8) -> 0.058139535 | F8: Bytecode-level detection
A9: Timestamp | B9: Not covered (0 detections) | C9: =COUNTIF(Data!J2:J87,"<>") -> 0 | D9: =SUM(Data!C2:C87) -> 86 | E9: =IF(D9=0,0,C9/D9) -> 0 | F9: Zero detections this run
A10: TOD | B10: Securify | C10: =COUNTIF(Data!K2:K87,"<>") -> 5 | D10: =SUM(Data!C2:C87) -> 86 | E10: =IF(D10=0,0,C10/D10) -> 0.058139535 | F10: Bytecode-level detection
A11: DoS | B11: Mythril | C11: =COUNTIF(Data!L2:L87,"<>") -> 5 | D11: =SUM(Data!C2:C87) -> 86 | E11: =IF(D11=0,0,C11/D11) -> 0.058139535 | F11: Bytecode-level detection
A12: Selfdestruct | B12: Not covered (0 detections) | C12: =COUNTIF(Data!M2:M87,"<>") -> 0 | D12: =SUM(Data!C2:C87) -> 86 | E12: =IF(D12=0,0,C12/D12) -> 0 | F12: Zero detections this run
A13: Locked Ether | B13: Not covered (0 detections) | C13: =COUNTIF(Data!N2:N87,"<>") -> 0 | D13: =SUM(Data!C2:C87) -> 86 | E13: =IF(D13=0,0,C13/D13) -> 0 | F13: Zero detections this run
A14: Ether Leak | B14: MAIAN | C14: =COUNTIF(Data!O2:O87,"<>") -> 13 | D14: =SUM(Data!C2:C87) -> 86 | E14: =IF(D14=0,0,C14/D14) -> 0.15116279 | F14: Bytecode-level detection
A15: OVERALL VULNERABLE | B15: Any tool | C15: =COUNTIFS(Data!C2:C87,1,Data!P2:P87,"Yes") -> 14 | D15: =SUM(Data!C2:C87) -> 86 | E15: =IF(D15=0,0,C15/D15) -> 0.1627907 | F15: Flagged by >=1 tool

Sheet Detection_Count_Analysis
A1: Wormhole_Obfuscated — Detection Count Analysis
A3: Flags per contract = count of (Reentrancy, Access Control, Unchecked Call, TOD, DoS, Ether Leak) triggered on that contract
A5: Flags per Contract | B5: Contract Count | C5: % of Bytecode Contracts | D5: Note
A6: 0 categories flagged | B6: =SUMPRODUCT((Data!C2:C87=1)*(((Data!E2:E87<>"")+(Data!G2:G87<>"")+(Data!I2:I87<>"")+(Data!K2:K87<>"")+(Data!L2:L87<>"")+(Data!O2:O87<>""))=0)) -> 72 | C6: =IF(SUM(Data!C2:C87)=0,0,B6/SUM(Data!C2:C87)) -> 0.8372093
A7: 1 categories flagged | B7: =SUMPRODUCT((Data!C2:C87=1)*(((Data!E2:E87<>"")+(Data!G2:G87<>"")+(Data!I2:I87<>"")+(Data!K2:K87<>"")+(Data!L2:L87<>"")+(Data!O2:O87<>""))=1)) -> 9 | C7: =IF(SUM(Data!C2:C87)=0,0,B7/SUM(Data!C2:C87)) -> 0.10465116
A8: 2 categories flagged | B8: =SUMPRODUCT((Data!C2:C87=1)*(((Data!E2:E87<>"")+(Data!G2:G87<>"")+(Data!I2:I87<>"")+(Data!K2:K87<>"")+(Data!L2:L87<>"")+(Data!O2:O87<>""))=2)) -> 0 | C8: =IF(SUM(Data!C2:C87)=0,0,B8/SUM(Data!C2:C87)) -> 0
A9: 3 categories flagged | B9: =SUMPRODUCT((Data!C2:C87=1)*(((Data!E2:E87<>"")+(Data!G2:G87<>"")+(Data!I2:I87<>"")+(Data!K2:K87<>"")+(Data!L2:L87<>"")+(Data!O2:O87<>""))=3)) -> 0 | C9: =IF(SUM(Data!C2:C87)=0,0,B9/SUM(Data!C2:C87)) -> 0
A10: 4 categories flagged | B10: =SUMPRODUCT((Data!C2:C87=1)*(((Data!E2:E87<>"")+(Data!G2:G87<>"")+(Data!I2:I87<>"")+(Data!K2:K87<>"")+(Data!L2:L87<>"")+(Data!O2:O87<>""))=4)) -> 0 | C10: =IF(SUM(Data!C2:C87)=0,0,B10/SUM(Data!C2:C87)) -> 0
A11: 5 categories flagged | B11: =SUMPRODUCT((Data!C2:C87=1)*(((Data!E2:E87<>"")+(Data!G2:G87<>"")+(Data!I2:I87<>"")+(Data!K2:K87<>"")+(Data!L2:L87<>"")+(Data!O2:O87<>""))=5)) -> 1 | C11: =IF(SUM(Data!C2:C87)=0,0,B11/SUM(Data!C2:C87)) -> 0.011627907
A12: 6 categories flagged | B12: =SUMPRODUCT((Data!C2:C87=1)*(((Data!E2:E87<>"")+(Data!G2:G87<>"")+(Data!I2:I87<>"")+(Data!K2:K87<>"")+(Data!L2:L87<>"")+(Data!O2:O87<>""))=6)) -> 4 | C12: =IF(SUM(Data!C2:C87)=0,0,B12/SUM(Data!C2:C87)) -> 0.046511628
A13: Total contracts w/ bytecode | B13: =SUM(B6:B12) -> 86
A15: Total raw detections (sum across all 11 categories) | B15: =COUNTIF(Data!E2:E87,"<>")+COUNTIF(Data!F2:F87,"<>")+COUNTIF(Data!G2:G87,"<>")+COUNTIF(Data!H2:H87,"<>")+COUNTIF(Data!I2:I87,"<>")+COUNTIF(Data!J2:J87,"<>")+COUNTIF(Data!K2:K87,"<>")+COUNTIF(Data!L2:L87,"<>")+COUNTIF(Data!M2:M87,"<>")+COUNTIF(Data!N2:N87,"<>")+COUNTIF(Data!O2:O87,"<>") -> 38
A16: Avg detections per bytecode-resolved contract | B16: =B15/SUM(Data!C2:C87) -> 0.44186047

Sheet Tool_Wise_Analysis
A1: Wormhole_Obfuscated — Tool-wise Analysis
A3: Tool | B3: Categories Covered | C3: Contracts Flagged | D3: Contracts w/ Bytecode | E3: Flag Rate % | F3: Note
A4: MAIAN | B4: Ether Leak | C4: =SUM(Data!Q2:Q87) -> 13 | D4: =SUM(Data!C2:C87) -> 86 | E4: =IF(D4=0,0,C4/D4) -> 0.15116279 | F4: Symbolic execution, financial-flow analysis
A5: Mythril | B5: DoS | C5: =SUM(Data!R2:R87) -> 5 | D5: =SUM(Data!C2:C87) -> 86 | E5: =IF(D5=0,0,C5/D5) -> 0.058139535 | F5: Bytecode symbolic execution
A6: Securify | B6: Reentrancy, Access Control, Unchecked Call, TOD | C6: =SUM(Data!S2:S87) -> 5 | D6: =SUM(Data!C2:C87) -> 86 | E6: =IF(D6=0,0,C6/D6) -> 0.058139535
A7: Others (n/a) | B7: Integer, Delegatecall, Timestamp, Selfdestruct, Locked Ether | C7: 0 | D7: =SUM(Data!C2:C87) -> 86 | E7: 0 | F7: Zero detections in this run

Sheet Contract_Level_Statistics
A1: Wormhole_Obfuscated — Contract-Level Statistics
A3: Addresses queried | B3: =COUNTA(Data!A2:A87) -> 86
A4: Chains covered | B4: 12
A5: Contracts analyzed (bytecode resolved / detection ran) | B5: =SUM(Data!C2:C87) -> 86
A6: Not analyzed (EOA / unverified / not found) | B6: =COUNTA(Data!A2:A87)-SUM(Data!C2:C87) -> 0
A7: ...of which bytecode text is blank in source export | B7: =SUMPRODUCT((Data!C2:C87=1)*(Data!D2:D87=0)) -> 0 | D7: Detections still recorded; only the raw bytecode string is missing from the export
A8: Avg bytecode length (hex chars, where text available) | B8: =IF(SUMPRODUCT((Data!C2:C87=1)*(Data!D2:D87>0))=0,0,SUMIF(Data!C2:C87,1,Data!D2:D87)/SUMPRODUCT((Data!C2:C87=1)*(Data!D2:D87>0))) -> 243.73256 | D8: Rounded to nearest char; excludes blank-text rows
A9: Min bytecode length (where text available) | B9: =_xlfn.MINIFS(Data!D2:D87,Data!C2:C87,1,Data!D2:D87,">0") -> 105
A10: Max bytecode length | B10: =_xlfn.MAXIFS(Data!D2:D87,Data!C2:C87,1) -> 809
A12: Per-Chain Breakdown
A13: Chain | B13: Addresses | C13: With Bytecode | D13: Vulnerable Rate %
A14: arbitrum | B14: =COUNTIF(Data!B2:B87,A14) -> 7 | C14: =COUNTIFS(Data!B2:B87,A14,Data!C2:C87,1) -> 7 | D14: =IF(C14=0,0,(COUNTIFS(Data!B2:B87,A14,Data!C2:C87,1,Data!P2:P87,"Yes"))/C14) -> 0.14285714
A15: avalanche | B15: =COUNTIF(Data!B2:B87,A15) -> 11 | C15: =COUNTIFS(Data!B2:B87,A15,Data!C2:C87,1) -> 11 | D15: =IF(C15=0,0,(COUNTIFS(Data!B2:B87,A15,Data!C2:C87,1,Data!P2:P87,"Yes"))/C15) -> 0
A16: base | B16: =COUNTIF(Data!B2:B87,A16) -> 9 | C16: =COUNTIFS(Data!B2:B87,A16,Data!C2:C87,1) -> 9 | D16: =IF(C16=0,0,(COUNTIFS(Data!B2:B87,A16,Data!C2:C87,1,Data!P2:P87,"Yes"))/C16) -> 0
A17: berachain | B17: =COUNTIF(Data!B2:B87,A17) -> 4 | C17: =COUNTIFS(Data!B2:B87,A17,Data!C2:C87,1) -> 4 | D17: =IF(C17=0,0,(COUNTIFS(Data!B2:B87,A17,Data!C2:C87,1,Data!P2:P87,"Yes"))/C17) -> 0.25
A18: blast | B18: =COUNTIF(Data!B2:B87,A18) -> 3 | C18: =COUNTIFS(Data!B2:B87,A18,Data!C2:C87,1) -> 3 | D18: =IF(C18=0,0,(COUNTIFS(Data!B2:B87,A18,Data!C2:C87,1,Data!P2:P87,"Yes"))/C18) -> 0
A19: bsc | B19: =COUNTIF(Data!B2:B87,A19) -> 7 | C19: =COUNTIFS(Data!B2:B87,A19,Data!C2:C87,1) -> 7 | D19: =IF(C19=0,0,(COUNTIFS(Data!B2:B87,A19,Data!C2:C87,1,Data!P2:P87,"Yes"))/C19) -> 0
A20: celo | B20: =COUNTIF(Data!B2:B87,A20) -> 4 | C20: =COUNTIFS(Data!B2:B87,A20,Data!C2:C87,1) -> 4 | D20: =IF(C20=0,0,(COUNTIFS(Data!B2:B87,A20,Data!C2:C87,1,Data!P2:P87,"Yes"))/C20) -> 0.25
A21: ethereum | B21: =COUNTIF(Data!B2:B87,A21) -> 11 | C21: =COUNTIFS(Data!B2:B87,A21,Data!C2:C87,1) -> 11 | D21: =IF(C21=0,0,(COUNTIFS(Data!B2:B87,A21,Data!C2:C87,1,Data!P2:P87,"Yes"))/C21) -> 0.45454545
A22: mantle | B22: =COUNTIF(Data!B2:B87,A22) -> 3 | C22: =COUNTIFS(Data!B2:B87,A22,Data!C2:C87,1) -> 3 | D22: =IF(C22=0,0,(COUNTIFS(Data!B2:B87,A22,Data!C2:C87,1,Data!P2:P87,"Yes"))/C22) -> 0
A23: moonbeam | B23: =COUNTIF(Data!B2:B87,A23) -> 5 | C23: =COUNTIFS(Data!B2:B87,A23,Data!C2:C87,1) -> 5 | D23: =IF(C23=0,0,(COUNTIFS(Data!B2:B87,A23,Data!C2:C87,1,Data!P2:P87,"Yes"))/C23) -> 0.2
A24: optimism | B24: =COUNTIF(Data!B2:B87,A24) -> 8 | C24: =COUNTIFS(Data!B2:B87,A24,Data!C2:C87,1) -> 8 | D24: =IF(C24=0,0,(COUNTIFS(Data!B2:B87,A24,Data!C2:C87,1,Data!P2:P87,"Yes"))/C24) -> 0
A25: polygon | B25: =COUNTIF(Data!B2:B87,A25) -> 7 | C25: =COUNTIFS(Data!B2:B87,A25,Data!C2:C87,1) -> 7 | D25: =IF(C25=0,0,(COUNTIFS(Data!B2:B87,A25,Data!C2:C87,1,Data!P2:P87,"Yes"))/C25) -> 0.57142857
A26: sei | B26: =COUNTIF(Data!B2:B87,A26) -> 1 | C26: =COUNTIFS(Data!B2:B87,A26,Data!C2:C87,1) -> 1 | D26: =IF(C26=0,0,(COUNTIFS(Data!B2:B87,A26,Data!C2:C87,1,Data!P2:P87,"Yes"))/C26) -> 1
A27: sonic | B27: =COUNTIF(Data!B2:B87,A27) -> 1 | C27: =COUNTIFS(Data!B2:B87,A27,Data!C2:C87,1) -> 1 | D27: =IF(C27=0,0,(COUNTIFS(Data!B2:B87,A27,Data!C2:C87,1,Data!P2:P87,"Yes"))/C27) -> 0
A28: unichain | B28: =COUNTIF(Data!B2:B87,A28) -> 2 | C28: =COUNTIFS(Data!B2:B87,A28,Data!C2:C87,1) -> 2 | D28: =IF(C28=0,0,(COUNTIFS(Data!B2:B87,A28,Data!C2:C87,1,Data!P2:P87,"Yes"))/C28) -> 0
A29: world_chain | B29: =COUNTIF(Data!B2:B87,A29) -> 3 | C29: =COUNTIFS(Data!B2:B87,A29,Data!C2:C87,1) -> 3 | D29: =IF(C29=0,0,(COUNTIFS(Data!B2:B87,A29,Data!C2:C87,1,Data!P2:P87,"Yes"))/C29) -> 0

Sheet Agreement_Jaccard
A1: Wormhole_Obfuscated — Tool Agreement (Jaccard Index)
A2: Pairwise agreement among 3 tools (MAIAN, Mythril, Securify), among contracts with bytecode.
A4: MAIAN vs Mythril
A5: Set | B5: Count | C5: % of Bytecode Contracts | D5: Definition
A6: Both flag (A ∩ B) | B6: =SUMPRODUCT((Data!C2:C87=1)*(Data!Q2:Q87=1)*(Data!R2:R87=1)) -> 4 | C6: =IF(SUM(Data!C2:C87)=0,0,B6/SUM(Data!C2:C87)) -> 0.046511628 | D6: MAIAN AND Mythril
A7: Only MAIAN flags (A \ B) | B7: =SUMPRODUCT((Data!C2:C87=1)*(Data!Q2:Q87=1)*(Data!R2:R87=0)) -> 9 | C7: =IF(SUM(Data!C2:C87)=0,0,B7/SUM(Data!C2:C87)) -> 0.10465116 | D7: MAIAN only
A8: Only Mythril flags (B \ A) | B8: =SUMPRODUCT((Data!C2:C87=1)*(Data!Q2:Q87=0)*(Data!R2:R87=1)) -> 1 | C8: =IF(SUM(Data!C2:C87)=0,0,B8/SUM(Data!C2:C87)) -> 0.011627907 | D8: Mythril only
A9: Neither flags | B9: =SUMPRODUCT((Data!C2:C87=1)*(Data!Q2:Q87=0)*(Data!R2:R87=0)) -> 72 | C9: =IF(SUM(Data!C2:C87)=0,0,B9/SUM(Data!C2:C87)) -> 0.8372093 | D9: Resolved contract, no flag from either tool
A10: Union (A ∪ B) | B10: =B6+B7+B8 -> 14
A11: Jaccard Index J(MAIAN,Mythril) = |A∩B| / |A∪B| | B11: =IF(B10=0,0,B6/B10) -> 0.28571429
A13: MAIAN vs Securify
A14: Set | B14: Count | C14: % of Bytecode Contracts | D14: Definition
A15: Both flag (A ∩ B) | B15: =SUMPRODUCT((Data!C2:C87=1)*(Data!Q2:Q87=1)*(Data!S2:S87=1)) -> 4 | C15: =IF(SUM(Data!C2:C87)=0,0,B15/SUM(Data!C2:C87)) -> 0.046511628 | D15: MAIAN AND Securify
A16: Only MAIAN flags (A \ B) | B16: =SUMPRODUCT((Data!C2:C87=1)*(Data!Q2:Q87=1)*(Data!S2:S87=0)) -> 9 | C16: =IF(SUM(Data!C2:C87)=0,0,B16/SUM(Data!C2:C87)) -> 0.10465116 | D16: MAIAN only
A17: Only Securify flags (B \ A) | B17: =SUMPRODUCT((Data!C2:C87=1)*(Data!Q2:Q87=0)*(Data!S2:S87=1)) -> 1 | C17: =IF(SUM(Data!C2:C87)=0,0,B17/SUM(Data!C2:C87)) -> 0.011627907 | D17: Securify only
A18: Neither flags | B18: =SUMPRODUCT((Data!C2:C87=1)*(Data!Q2:Q87=0)*(Data!S2:S87=0)) -> 72 | C18: =IF(SUM(Data!C2:C87)=0,0,B18/SUM(Data!C2:C87)) -> 0.8372093 | D18: Resolved contract, no flag from either tool
A19: Union (A ∪ B) | B19: =B15+B16+B17 -> 14
A20: Jaccard Index J(MAIAN,Securify) = |A∩B| / |A∪B| | B20: =IF(B19=0,0,B15/B19) -> 0.28571429
A22: Mythril vs Securify
A23: Set | B23: Count | C23: % of Bytecode Contracts | D23: Definition
A24: Both flag (A ∩ B) | B24: =SUMPRODUCT((Data!C2:C87=1)*(Data!R2:R87=1)*(Data!S2:S87=1)) -> 5 | C24: =IF(SUM(Data!C2:C87)=0,0,B24/SUM(Data!C2:C87)) -> 0.058139535 | D24: Mythril AND Securify
A25: Only Mythril flags (A \ B) | B25: =SUMPRODUCT((Data!C2:C87=1)*(Data!R2:R87=1)*(Data!S2:S87=0)) -> 0 | C25: =IF(SUM(Data!C2:C87)=0,0,B25/SUM(Data!C2:C87)) -> 0 | D25: Mythril only
A26: Only Securify flags (B \ A) | B26: =SUMPRODUCT((Data!C2:C87=1)*(Data!R2:R87=0)*(Data!S2:S87=1)) -> 0 | C26: =IF(SUM(Data!C2:C87)=0,0,B26/SUM(Data!C2:C87)) -> 0 | D26: Securify only
A27: Neither flags | B27: =SUMPRODUCT((Data!C2:C87=1)*(Data!R2:R87=0)*(Data!S2:S87=0)) -> 81 | C27: =IF(SUM(Data!C2:C87)=0,0,B27/SUM(Data!C2:C87)) -> 0.94186047 | D27: Resolved contract, no flag from either tool
A28: Union (A ∪ B) | B28: =B24+B25+B26 -> 5
A29: Jaccard Index J(Mythril,Securify) = |A∩B| / |A∪B| | B29: =IF(B28=0,0,B24/B28) -> 1

Sheet Key_Findings
A1: Wormhole_Obfuscated — Key Findings
A3: ="1. Bytecode resolution: "&SUM(Data!C2:C87)&" of "&COUNTA(Data!A2:A87)&" queried addresses ("&TEXT(SUM(Data!C2:C87)/COUNTA(Data!A2:A87),"0.0%")&") resolved to deployed bytecode; the rest are EOAs, unverified, or not found on-chain." -> 1. Bytecode resolution: 86 of 86 queried addresses (100.0%) resolved to deployed bytecode; the rest are EOAs, unverified, or not found on-chain.
A4: ="2. Detection coverage: only MAIAN, Mythril, Securify produced any detections. Integer, Delegatecall, Timestamp, Selfdestruct, Locked Ether all show zero hits in this bytecode run." -> 2. Detection coverage: only MAIAN, Mythril, Securify produced any detections. Integer, Delegatecall, Timestamp, Selfdestruct, Locked Ether all show zero hits in this bytecode run.
A5: ="3. Mythril flag rate ("&TEXT(Tool_Wise_Analysis!E5,"0.0%")&") vs MAIAN flag rate ("&TEXT(Tool_Wise_Analysis!E4,"0.0%")&") among resolved contracts." -> 3. Mythril flag rate (5.8%) vs MAIAN flag rate (15.1%) among resolved contracts.
A6: ="4. Tool overlap: Jaccard(MAIAN, Mythril) = "&TEXT(Agreement_Jaccard!B11,"0.0000")&" — "&Agreement_Jaccard!B6&" contracts triggered both tools, "&Agreement_Jaccard!B7&" only MAIAN, "&Agreement_Jaccard!B8&" only Mythril." -> 4. Tool overlap: Jaccard(MAIAN, Mythril) = 0.2857 — 4 contracts triggered both tools, 9 only MAIAN, 1 only Mythril.
A7: ="5. "&Per_Vulnerability_Analysis!C15&" of "&Per_Vulnerability_Analysis!D15&" resolved contracts ("&TEXT(Per_Vulnerability_Analysis!C15/Per_Vulnerability_Analysis!D15,"0.0%")&") were flagged by at least one tool." -> 5. 14 of 86 resolved contracts (16.3%) were flagged by at least one tool.

Sheet Why_These_Results
A1: Wormhole Obfuscated — Why These Results: Forensic Explanation of the Detection Pattern
A2: Findings below combine (a) direct inspection of the raw BOSC-obfuscated bytecode where available, and (b) matched-pair comparison against the ORIGINAL (unobfuscated) run on the same addresses.
A4: 1. WHY THE TOOL SET FIRING HERE IS Mythril/MAIAN/Securify
A5: Wormhole's obfuscated run retains all three tools (Mythril, MAIAN, Securify) actually firing, unlike CCIP (no Mythril) and Axelar (Mythril only). This makes Wormhole one of the more complete obfuscated datasets for a fair category-level comparison against its original run.
A7: 2. WHAT CHANGED VERSUS THE ORIGINAL (UNOBFUSCATED) BYTECODE, SAME CONTRACTS
A8: On the 25 addresses successfully analyzed in BOTH the original and obfuscated runs: original vulnerable rate 100.0% -> obfuscated vulnerable rate 44.0%. 14 contracts that were flagged originally evaded ALL detection after obfuscation (56.0% evasion rate among originally-flagged contracts); 0 contracts that were clean originally were newly flagged after obfuscation.
A10: 3. BYTECODE-LEVEL OBSERVATIONS
A11: Bytecode text is available for 86 of 86 obfuscated contracts, ranging 105-809 hex characters (median 159). Note: BOSC's obfuscated bytecode export in this dataset is not formatted identically to the raw eth_getCode output used for the original bytecode analysis (no 0x prefix, and apparent leading-zero/byte normalization), so direct length-for-length comparison against the original bytecode reports should be treated as illustrative rather than exact.
A12: Average CALLVALUE (opcode 0x34) occurrences per contract: 0.22.
A14: SUMMARY
A15: Wormhole obfuscated shows a 56.0% point drop in matched-contract vulnerable rate, with both evasion (14 contracts) and no new detections - consistent with obfuscation partially, not completely, defeating this dataset's bytecode-level tools.

Sheet Data
A1: Address | B1: Chain | C1: Has_Bytecode | D1: Bytecode_Length | E1: Reentrancy | F1: Integer | G1: Access_Control | H1: Delegatecall | I1: Unchecked_Call | J1: Timestamp | K1: TOD | L1: DoS | M1: Selfdestruct | N1: Locked_Ether | O1: Ether_Leak | P1: Vulnerable | Q1: MAIAN_Flag | R1: Mythril_Flag | S1: Securify_Flag
A2: arbitrum_0x0b2402144Bb366A632D14B83F244D2e0e21bD39c | B2: arbitrum | C2: 1 | D2: 159 | P2: No | Q2: 0 | R2: 0 | S2: 0
A3: arbitrum_0x2703483B1a5a7c577e8680de9Df8Be03c6f30e3c | B3: arbitrum | C3: 1 | D3: 157 | P3: No | Q3: 0 | R3: 0 | S3: 0
A4: arbitrum_0x32eec14c963c23176bd8951f192292006756bDcC | B4: arbitrum | C4: 1 | D4: 761 | O4: MAIAN | P4: Yes | Q4: 1 | R4: 0 | S4: 0
A5: arbitrum_0x36CF4c88FA548c6Ad9fcDc696e1c27Bb3306163F | B5: arbitrum | C5: 1 | D5: 115 | P5: No | Q5: 0 | R5: 0 | S5: 0
A6: arbitrum_0x3980f8318fc03d79033Bbb421A622CDF8d2Eeab4 | B6: arbitrum | C6: 1 | D6: 625 | P6: No | Q6: 0 | R6: 0 | S6: 0
A7: arbitrum_0x3dD14D553cFD986EAC8e3bddF629d82073e188c8 | B7: arbitrum | C7: 1 | D7: 159 | P7: No | Q7: 0 | R7: 0 | S7: 0
A8: arbitrum_0xa5f208e072434bC67592E4C49C1B991BA79BCA46 | B8: arbitrum | C8: 1 | D8: 159 | P8: No | Q8: 0 | R8: 0 | S8: 0
A9: avalanche_0x09Fb06A271faFf70A651047395AaEb6265265F13 | B9: avalanche | C9: 1 | D9: 105 | P9: No | Q9: 0 | R9: 0 | S9: 0
A10: avalanche_0x0e082F06FF657D94310cB8cE8B0D9a04541d8052 | B10: avalanche | C10: 1 | D10: 105 | P10: No | Q10: 0 | R10: 0 | S10: 0
A11: avalanche_0x13947Bd48b18E53fdAeEe77F3473391aC727C638 | B11: avalanche | C11: 1 | D11: 105 | P11: No | Q11: 0 | R11: 0 | S11: 0
A12: avalanche_0x169D91C797edF56100F1B765268145660503a423 | B12: avalanche | C12: 1 | D12: 105 | P12: No | Q12: 0 | R12: 0 | S12: 0
A13: avalanche_0x4661F0E629E4ba8D04Ee90080Aee079740B00381 | B13: avalanche | C13: 1 | D13: 105 | P13: No | Q13: 0 | R13: 0 | S13: 0
A14: avalanche_0x54a8e5f9c4CbA08F9943965859F6c34eAF03E26c | B14: avalanche | C14: 1 | D14: 105 | P14: No | Q14: 0 | R14: 0 | S14: 0
A15: avalanche_0x58CC3AE5C097b213cE3c81979e1B9f9570746AA5 | B15: avalanche | C15: 1 | D15: 105 | P15: No | Q15: 0 | R15: 0 | S15: 0
A16: avalanche_0xA3a2A615774d34c6a4dF443C488B084eacaBd2D0 | B16: avalanche | C16: 1 | D16: 105 | P16: No | Q16: 0 | R16: 0 | S16: 0
... A28: base_0xbebdb6C8ddC678FfA9f8748f85C815C556Dd8ac6 | B28: base | C28: 1 | D28: 105 | P28: No | Q28: 0 | R28: 0 | S28: 0
A29: berachain_0x0Dd7a5a32311b8D87A615Cc7f079B632D3d5e2D3 | B29: berachain | C29: 1 | D29: 624 | E29: Securify | G29: Securify | I29: Securify | K29: Securify | L29: Mythril | O29: MAIAN | P29: Yes | Q29: 1 | R29: 1 | S29: 1
A30: berachain_0x3Ff72741fd67D6AD0668d93B41a09248F4700560 | B30: berachain | C30: 1 | D30: 159 | P30: No | Q30: 0 | R30: 0 | S30: 0
A31: berachain_0x6969696969696969696969696969696969696969 | B31: berachain | C31: 1 | D31: 809 | P31: No | Q31: 0 | R31: 0 | S31: 0
A32: berachain_0xCa1D5a146B03f6303baF59e5AD5615ae0b9d146D | B32: berachain | C32: 1 | D32: 159 | P32: No | Q32: 0 | R32: 0 | S32: 0
A33: blast_0x24850c6f61C438823F01B7A3BF2B89B72174Fa9d | B33: blast | C33: 1 | D33: 159 | P33: No | Q33: 0 | R33: 0 | S33: 0
A34: blast_0x9D020B1697035d9d54f115194c9e04a1e4Eb9aF7 | B34: blast | C34: 1 | D34: 219 | P34: No | Q34: 0 | R34: 0 | S34: 0
A35: blast_0xbebdb6C8ddC678FfA9f8748f85C815C556Dd8ac6 | B35: blast | C35: 1 | D35: 159 | P35: No | Q35: 0 | R35: 0 | S35: 0
A36: bsc_0x13947Bd48b18E53fdAeEe77F3473391aC727C638 | B36: bsc | C36: 1 | D36: 105 | P36: No | Q36: 0 | R36: 0 | S36: 0
A37: bsc_0x58CC3AE5C097b213cE3c81979e1B9f9570746AA5 | B37: bsc | C37: 1 | D37: 105 | P37: No | Q37: 0 | R37: 0 | S37: 0
A38: bsc_0x5a58505a96D1dbf8dF91cB21B54419FC36e93fdE | B38: bsc | C38: 1 | D38: 105 | P38: No | Q38: 0 | R38: 0 | S38: 0
A39: bsc_0x98f3c9e6E3fAce36bAAd05FE09d375Ef1464288B | B39: bsc | C39: 1 | D39: 105 | P39: No | Q39: 0 | R39: 0 | S39: 0
A40: bsc_0xB6F6D86a8f9879A9c87f643768d9efc38c1Da6E7 | B40: bsc | C40: 1 | D40: 105 | P40: No | Q40: 0 | R40: 0 | S40: 0
A41: bsc_0xae13d989daC2f0dEbFf460aC112a837C89BAa7cd | B41: bsc | C41: 1 | D41: 105 | P41: No | Q41: 0 | R41: 0 | S41: 0
... A45: celo_0xa321448d90d4e5b0A732867c18eA198e75CAC48E | B45: celo | C45: 1 | D45: 159 | P45: No | Q45: 0 | R45: 0 | S45: 0
A46: celo_0xe6Ea5087c6860B94Cf098a403506262D8F28cF05 | B46: celo | C46: 1 | D46: 625 | O46: MAIAN | P46: Yes | Q46: 1 | R46: 0 | S46: 0
A47: ethereum_0x1462800febd49232798132e8c8b721aa86c4c209 | B47: ethereum | C47: 1 | D47: 364 | E47: Securify | G47: Securify | I47: Securify | K47: Securify | L47: Mythril | P47: Yes | Q47: 0 | R47: 1 | S47: 1
A48: ethereum_0x23Fea5514DFC9821479fBE18BA1D7e1A61f6FfCf | B48: ethereum | C48: 1 | D48: 115 | P48: No | Q48: 0 | R48: 0 | S48: 0
A49: ethereum_0x3ee18B2214AFF97000D974cf647E7C347E8fa585 | B49: ethereum | C49: 1 | D49: 159 | P49: No | Q49: 0 | R49: 0 | S49: 0
A50: ethereum_0x6FFd7EdE62328b3Af38FCD61461Bbfc52F5651fE | B50: ethereum | C50: 1 | D50: 159 | P50: No | Q50: 0 | R50: 0 | S50: 0
A51: ethereum_0x70287c79ee41C5D1df8259Cd68Ba0890cd389c47 | B51: ethereum | C51: 1 | D51: 137 | P51: No | Q51: 0 | R51: 0 | S51: 0
A52: ethereum_0x84EEe8dBa37C36947397E1E11251cA9A06Fc6F8a | B52: ethereum | C52: 1 | D52: 625 | O52: MAIAN | P52: Yes | Q52: 1 | R52: 0 | S52: 0
A53: ethereum_0x98f3c9e6E3fAce36bAAd05FE09d375Ef1464288B | B53: ethereum | C53: 1 | D53: 159 | P53: No | Q53: 0 | R53: 0 | S53: 0
A54: ethereum_0xA25862D222Eb8343505c12d96e097e4332468D60 | B54: ethereum | C54: 1 | D54: 452 | E54: Securify | G54: Securify | I54: Securify | K54: Securify | L54: Mythril | O54: MAIAN | P54: Yes | Q54: 1 | R54: 1 | S54: 1
...
