Workbook

Sheet Executive_Summary
A1: Hyperlane — Bridge Bytecode Vulnerability Detection: Executive Summary
A3: KEY METRICS
A4: ="Addresses queried: "&COUNTA(Data!A2:A178)&" | Chains covered: 1" -> Addresses queried: 177 | Chains covered: 1
A5: ="Contracts with resolved bytecode: "&SUM(Data!C2:C178)&" | No bytecode (EOA/unverified): "&(COUNTA(Data!A2:A178)-SUM(Data!C2:C178)) -> Contracts with resolved bytecode: 61 | No bytecode (EOA/unverified): 116
A6: ="Overall vulnerable (>=1 tool): "&TEXT(Per_Vulnerability_Analysis!C15/Per_Vulnerability_Analysis!D15,"0.0%")&" of resolved contracts ("&Per_Vulnerability_Analysis!C15&"/"&Per_Vulnerability_Analysis!D15&")" -> Overall vulnerable (>=1 tool): 100.0% of resolved contracts (61/61)
A7: ="MAIAN flag rate: "&TEXT(Tool_Wise_Analysis!E4,"0.0%") -> MAIAN flag rate: 82.0%
A8: ="Mythril flag rate: "&TEXT(Tool_Wise_Analysis!E5,"0.0%") -> Mythril flag rate: 26.2%
A9: ="Tool agreement (Jaccard, MAIAN vs Mythril): "&TEXT(Agreement_Jaccard!B11,"0.0000") -> Tool agreement (Jaccard, MAIAN vs Mythril): 0.0820
A11: WHAT THE DATA SHOWS
A12: ="Highest-prevalence category: "&INDEX(Per_Vulnerability_Analysis!A5:A14,MATCH(MAX(Per_Vulnerability_Analysis!C5:C14),Per_Vulnerability_Analysis!C5:C14,0))&" ("&TEXT(MAX(Per_Vulnerability_Analysis!E5:E14),"0.0%")&" prevalence)" -> Highest-prevalence category: Ether Leak (82.0% prevalence)
A13: ="Only MAIAN and Mythril returned detections in this run; 8 of 11 tracked categories show zero hits — see Formula_Definitions / Per_Vulnerability_Analysis." -> Only MAIAN and Mythril returned detections in this run; 8 of 11 tracked categories show zero hits — see Formula_Definitions / Per_Vulnerability_Analysis.

Sheet Formula_Definitions
A1: Metric | B1: Formula | C1: Interpretation
A2: Detections D(v) | B2: COUNTIF(category_column, "<>") | C2: Number of contracts flagged for vulnerability v by its reporting tool
A3: Contracts w/ Bytecode | B3: SUM(Has_Bytecode) | C3: Denominator for prevalence; excludes EOA/unverified/no-code addresses
A4: Prevalence % | B4: D(v) / Contracts_w_Bytecode | C4: Share of resolved contracts flagged for category v
A5: Overall Vulnerable | B5: COUNTIFS(Has_Bytecode=1, Vulnerable="Yes") | C5: Contracts flagged by >=1 tool, among resolved contracts
A6: Flags per Contract | B6: COUNT of active categories triggered per row | C6: How many distinct categories fire on the same contract
A7: Tool Flag Rate % | B7: Tool-flagged contracts / Contracts w/ Bytecode | C7: Per-tool prevalence, independent of category breakdown
A8: Jaccard Index J(A,B) | B8: |A ∩ B| / |A ∪ B| | C8: Overlap between the two tools' flagged sets; 0=no overlap, 1=identical sets
A9: Vulnerable Rate % (chain) | B9: Vulnerable(chain) / With_Bytecode(chain) | C9: Per-chain share of resolved contracts flagged

Sheet Per_Vulnerability_Analysis
A1: Hyperlane — Per-Vulnerability Analysis
A3: Category | B3: Detecting Tool | C3: Detections D(v) | D3: Contracts w/ Bytecode | E3: Prevalence % | F3: Note
A4: Reentrancy | B4: Not covered (0 detections) | C4: =COUNTIF(Data!E2:E178,"<>") -> 0 | D4: =SUM(Data!C2:C178) -> 61 | E4: =IF(D4=0,0,C4/D4) -> 0 | F4: Zero detections this run
A5: Integer | B5: Mythril | C5: =COUNTIF(Data!F2:F178,"<>") -> 16 | D5: =SUM(Data!C2:C178) -> 61 | E5: =IF(D5=0,0,C5/D5) -> 0.26229508 | F5: Bytecode-level detection
A6: Access Control | B6: Not covered (0 detections) | C6: =COUNTIF(Data!G2:G178,"<>") -> 0 | D6: =SUM(Data!C2:C178) -> 61 | E6: =IF(D6=0,0,C6/D6) -> 0 | F6: Zero detections this run
A7: Delegatecall | B7: Not covered (0 detections) | C7: =COUNTIF(Data!H2:H178,"<>") -> 0 | D7: =SUM(Data!C2:C178) -> 61 | E7: =IF(D7=0,0,C7/D7) -> 0 | F7: Zero detections this run
A8: Unchecked Call | B8: Not covered (0 detections) | C8: =COUNTIF(Data!I2:I178,"<>") -> 0 | D8: =SUM(Data!C2:C178) -> 61 | E8: =IF(D8=0,0,C8/D8) -> 0 | F8: Zero detections this run
A9: Timestamp | B9: Not covered (0 detections) | C9: =COUNTIF(Data!J2:J178,"<>") -> 0 | D9: =SUM(Data!C2:C178) -> 61 | E9: =IF(D9=0,0,C9/D9) -> 0 | F9: Zero detections this run
A10: TOD | B10: Not covered (0 detections) | C10: =COUNTIF(Data!K2:K178,"<>") -> 0 | D10: =SUM(Data!C2:C178) -> 61 | E10: =IF(D10=0,0,C10/D10) -> 0 | F10: Zero detections this run
A11: DoS | B11: Not covered (0 detections) | C11: =COUNTIF(Data!L2:L178,"<>") -> 0 | D11: =SUM(Data!C2:C178) -> 61 | E11: =IF(D11=0,0,C11/D11) -> 0 | F11: Zero detections this run
A12: Selfdestruct | B12: Not covered (0 detections) | C12: =COUNTIF(Data!M2:M178,"<>") -> 0 | D12: =SUM(Data!C2:C178) -> 61 | E12: =IF(D12=0,0,C12/D12) -> 0 | F12: Zero detections this run
A13: Locked Ether | B13: MAIAN | C13: =COUNTIF(Data!N2:N178,"<>") -> 20 | D13: =SUM(Data!C2:C178) -> 61 | E13: =IF(D13=0,0,C13/D13) -> 0.32786885 | F13: Bytecode-level detection
A14: Ether Leak | B14: MAIAN | C14: =COUNTIF(Data!O2:O178,"<>") -> 50 | D14: =SUM(Data!C2:C178) -> 61 | E14: =IF(D14=0,0,C14/D14) -> 0.81967213 | F14: Bytecode-level detection
A15: OVERALL VULNERABLE | B15: Any tool | C15: =COUNTIFS(Data!C2:C178,1,Data!P2:P178,"Yes") -> 61 | D15: =SUM(Data!C2:C178) -> 61 | E15: =IF(D15=0,0,C15/D15) -> 1 | F15: Flagged by >=1 tool

Sheet Detection_Count_Analysis
A1: Hyperlane — Detection Count Analysis
A3: Flags per contract = count of (Integer, Locked Ether, Ether Leak) triggered on that contract
A5: Flags per Contract | B5: Contract Count | C5: % of Bytecode Contracts | D5: Note
A6: 0 categories flagged | B6: =SUMPRODUCT((Data!C2:C178=1)*(((Data!F2:F178<>"")+(Data!N2:N178<>"")+(Data!O2:O178<>""))=0)) -> 0 | C6: =IF(SUM(Data!C2:C178)=0,0,B6/SUM(Data!C2:C178)) -> 0
A7: 1 categories flagged | B7: =SUMPRODUCT((Data!C2:C178=1)*(((Data!F2:F178<>"")+(Data!N2:N178<>"")+(Data!O2:O178<>""))=1)) -> 40 | C7: =IF(SUM(Data!C2:C178)=0,0,B7/SUM(Data!C2:C178)) -> 0.6557377
A8: 2 categories flagged | B8: =SUMPRODUCT((Data!C2:C178=1)*(((Data!F2:F178<>"")+(Data!N2:N178<>"")+(Data!O2:O178<>""))=2)) -> 17 | C8: =IF(SUM(Data!C2:C178)=0,0,B8/SUM(Data!C2:C178)) -> 0.27868852
A9: 3 categories flagged | B9: =SUMPRODUCT((Data!C2:C178=1)*(((Data!F2:F178<>"")+(Data!N2:N178<>"")+(Data!O2:O178<>""))=3)) -> 4 | C9: =IF(SUM(Data!C2:C178)=0,0,B9/SUM(Data!C2:C178)) -> 0.06557377
A10: Total contracts w/ bytecode | B10: =SUM(B6:B9) -> 61
A12: Total raw detections (sum across all 11 categories) | B12: =COUNTIF(Data!E2:E178,"<>")+COUNTIF(Data!F2:F178,"<>")+COUNTIF(Data!G2:G178,"<>")+COUNTIF(Data!H2:H178,"<>")+COUNTIF(Data!I2:I178,"<>")+COUNTIF(Data!J2:J178,"<>")+COUNTIF(Data!K2:K178,"<>")+COUNTIF(Data!L2:L178,"<>")+COUNTIF(Data!M2:M178,"<>")+COUNTIF(Data!N2:N178,"<>")+COUNTIF(Data!O2:O178,"<>") -> 86
A13: Avg detections per bytecode-resolved contract | B13: =B12/SUM(Data!C2:C178) -> 1.4098361

Sheet Tool_Wise_Analysis
A1: Hyperlane — Tool-wise Analysis
A3: Tool | B3: Categories Covered | C3: Contracts Flagged | D3: Contracts w/ Bytecode | E3: Flag Rate % | F3: Note
A4: MAIAN | B4: Locked Ether, Ether Leak | C4: =SUM(Data!Q2:Q178) -> 50 | D4: =SUM(Data!C2:C178) -> 61 | E4: =IF(D4=0,0,C4/D4) -> 0.81967213 | F4: Symbolic execution, financial-flow analysis
A5: Mythril | B5: Integer | C5: =SUM(Data!R2:R178) -> 16 | D5: =SUM(Data!C2:C178) -> 61 | E5: =IF(D5=0,0,C5/D5) -> 0.26229508 | F5: Bytecode symbolic execution
A6: Others (n/a) | B6: Reentrancy, Access Control, Delegatecall, Unchecked Call, Timestamp, TOD, DoS, Selfdestruct | C6: 0 | D6: =SUM(Data!C2:C178) -> 61 | E6: 0 | F6: Zero detections in this run

Sheet Contract_Level_Statistics
A1: Hyperlane — Contract-Level Statistics
A3: Addresses queried | B3: =COUNTA(Data!A2:A178) -> 177
A4: Chains covered | B4: 1
A5: Contracts analyzed (bytecode resolved / detection ran) | B5: =SUM(Data!C2:C178) -> 61
A6: Not analyzed (EOA / unverified / not found) | B6: =COUNTA(Data!A2:A178)-SUM(Data!C2:C178) -> 116
A7: ...of which bytecode text is blank in source export | B7: =SUMPRODUCT((Data!C2:C178=1)*(Data!D2:D178=0)) -> 35 | D7: Detections still recorded; only the raw bytecode string is missing from the export
A8: Avg bytecode length (hex chars, where text available) | B8: =IF(SUMPRODUCT((Data!C2:C178=1)*(Data!D2:D178>0))=0,0,SUMIF(Data!C2:C178,1,Data!D2:D178)/SUMPRODUCT((Data!C2:C178=1)*(Data!D2:D178>0))) -> 12328.385 | D8: Rounded to nearest char; excludes blank-text rows
A9: Min bytecode length (where text available) | B9: =_xlfn.MINIFS(Data!D2:D178,Data!C2:C178,1,Data!D2:D178,">0") -> 2108
A10: Max bytecode length | B10: =_xlfn.MAXIFS(Data!D2:D178,Data!C2:C178,1) -> 42200
A12: Per-Chain Breakdown
A13: Chain | B13: Addresses | C13: With Bytecode | D13: Vulnerable Rate %
A14: All (chain not encoded in address) | B14: =COUNTIF(Data!B2:B178,A14) -> 177 | C14: =COUNTIFS(Data!B2:B178,A14,Data!C2:C178,1) -> 61 | D14: =IF(C14=0,0,(COUNTIFS(Data!B2:B178,A14,Data!C2:C178,1,Data!P2:P178,"Yes"))/C14) -> 1

Sheet Agreement_Jaccard
A1: Hyperlane — Tool Agreement (Jaccard Index)
A2: Agreement between MAIAN and Mythril, among contracts with bytecode.
A4: Set | B4: Count | C4: % of Bytecode Contracts | D4: Definition
A5: Both tools flag (A ∩ B) | B5: =SUMPRODUCT((Data!C2:C178=1)*(Data!Q2:Q178=1)*(Data!R2:R178=1)) -> 5 | C5: =IF(SUM(Data!C2:C178)=0,0,B5/SUM(Data!C2:C178)) -> 0.081967213 | D5: MAIAN AND Mythril
A6: Only MAIAN flags (A \ B) | B6: =SUMPRODUCT((Data!C2:C178=1)*(Data!Q2:Q178=1)*(Data!R2:R178=0)) -> 45 | C6: =IF(SUM(Data!C2:C178)=0,0,B6/SUM(Data!C2:C178)) -> 0.73770492 | D6: MAIAN only
A7: Only Mythril flags (B \ A) | B7: =SUMPRODUCT((Data!C2:C178=1)*(Data!Q2:Q178=0)*(Data!R2:R178=1)) -> 11 | C7: =IF(SUM(Data!C2:C178)=0,0,B7/SUM(Data!C2:C178)) -> 0.18032787 | D7: Mythril only
A8: Neither flags | B8: =SUMPRODUCT((Data!C2:C178=1)*(Data!Q2:Q178=0)*(Data!R2:R178=0)) -> 0 | C8: =IF(SUM(Data!C2:C178)=0,0,B8/SUM(Data!C2:C178)) -> 0 | D8: Resolved contract, no flag from either tool
A10: Union (A ∪ B) | B10: =B5+B6+B7 -> 61
A11: Jaccard Index J(A,B) = |A∩B| / |A∪B| | B11: =IF(B10=0,0,B5/B10) -> 0.081967213

Sheet Key_Findings
A1: Hyperlane — Key Findings
A3: ="1. Bytecode resolution: "&SUM(Data!C2:C178)&" of "&COUNTA(Data!A2:A178)&" queried addresses ("&TEXT(SUM(Data!C2:C178)/COUNTA(Data!A2:A178),"0.0%")&") resolved to deployed bytecode; the rest are EOAs, unverified, or not found on-chain." -> 1. Bytecode resolution: 61 of 177 queried addresses (34.5%) resolved to deployed bytecode; the rest are EOAs, unverified, or not found on-chain.
A4: ="2. Detection coverage: only MAIAN and Mythril produced any detections. Reentrancy, Access Control, Delegatecall, Unchecked Call, Timestamp, TOD, DoS, Selfdestruct all show zero hits in this bytecode run." -> 2. Detection coverage: only MAIAN and Mythril produced any detections. Reentrancy, Access Control, Delegatecall, Unchecked Call, Timestamp, TOD, DoS, Selfdestruct all show zero hits in this bytecode run.
A5: ="3. Mythril flag rate ("&TEXT(Tool_Wise_Analysis!E5,"0.0%")&") vs MAIAN flag rate ("&TEXT(Tool_Wise_Analysis!E4,"0.0%")&") among resolved contracts." -> 3. Mythril flag rate (26.2%) vs MAIAN flag rate (82.0%) among resolved contracts.
A6: ="4. Tool overlap: Jaccard(MAIAN, Mythril) = "&TEXT(Agreement_Jaccard!B11,"0.0000")&" — "&Agreement_Jaccard!B5&" contracts triggered both tools, "&Agreement_Jaccard!B6&" only MAIAN, "&Agreement_Jaccard!B7&" only Mythril." -> 4. Tool overlap: Jaccard(MAIAN, Mythril) = 0.0820 — 5 contracts triggered both tools, 45 only MAIAN, 11 only Mythril.
A7: ="5. "&Per_Vulnerability_Analysis!C15&" of "&Per_Vulnerability_Analysis!D15&" resolved contracts ("&TEXT(Per_Vulnerability_Analysis!C15/Per_Vulnerability_Analysis!D15,"0.0%")&") were flagged by at least one tool." -> 5. 61 of 61 resolved contracts (100.0%) were flagged by at least one tool.

Sheet Data
A1: Address | B1: Chain | C1: Has_Bytecode | D1: Bytecode_Length | E1: Reentrancy | F1: Integer | G1: Access_Control | H1: Delegatecall | I1: Unchecked_Call | J1: Timestamp | K1: TOD | L1: DoS | M1: Selfdestruct | N1: Locked_Ether | O1: Ether_Leak | P1: Vulnerable | Q1: MAIAN_Flag | R1: Mythril_Flag
A2: 0x01c0752455282BC139A325e479c6121E060a7bBd | B2: All (chain not encoded in address) | C2: 1 | D2: 0 | O2: MAIAN | P2: Yes | Q2: 1 | R2: 0
A3: 0x0296D16d371a49F631143612020138896b3eA421 | B3: All (chain not encoded in address) | C3: 0 | D3: 0 | P3: No | Q3: 0 | R3: 0
A4: 0x038F9F4e93e88Af2C688da265222FdE80e455aA4 | B4: All (chain not encoded in address) | C4: 1 | D4: 0 | N4: MAIAN | O4: MAIAN | P4: Yes | Q4: 1 | R4: 0
A5: 0x0526E47C49742C15F8817ef8cf0d8FFc72139D4F | B5: All (chain not encoded in address) | C5: 0 | D5: 0 | P5: No | Q5: 0 | R5: 0
A6: 0x06De94EfBE80A2804c5FDE2e7C4278a10575A272 | B6: All (chain not encoded in address) | C6: 1 | D6: 0 | O6: MAIAN | P6: Yes | Q6: 1 | R6: 0
A7: 0x08Aa6263078ddC6139F8EAB59D838C17bf555e93 | B7: All (chain not encoded in address) | C7: 0 | D7: 0 | P7: No | Q7: 0 | R7: 0
A8: 0x11b69aB33AD8a550dcF9B4A041AA1121255F08A5 | B8: All (chain not encoded in address) | C8: 1 | D8: 0 | N8: MAIAN | O8: MAIAN | P8: Yes | Q8: 1 | R8: 0
A9: 0x11f4E62575EE171D4df15b2D5426abd5d4196284 | B9: All (chain not encoded in address) | C9: 0 | D9: 0 | P9: No | Q9: 0 | R9: 0
A10: 0x12582c7B0f43c6A667CBaA7fA8b112F7fb1E69F0 | B10: All (chain not encoded in address) | C10: 1 | D10: 6948 | O10: MAIAN | P10: Yes | Q10: 1 | R10: 0
A11: 0x12Df53079d399a47e9E730df095b712B0FDFA791 | B11: All (chain not encoded in address) | C11: 0 | D11: 0 | P11: No | Q11: 0 | R11: 0
A12: 0x175821F30AdCAA4bbB72Ce98eF76C2E0De2C3f21 | B12: All (chain not encoded in address) | C12: 0 | D12: 0 | P12: No | Q12: 0 | R12: 0
A13: 0x17E216fBb22dF4ef8A6640ae9Cb147C92710ac84 | B13: All (chain not encoded in address) | C13: 1 | D13: 5266 | F13: Mythril | P13: Yes | Q13: 0 | R13: 1
A14: 0x182E8d7c5F1B06201b102123FC7dF0EaeB445a7B | B14: All (chain not encoded in address) | C14: 0 | D14: 0 | P14: No | Q14: 0 | R14: 0
A15: 0x18B0688990720103dB63559a3563f7E8d0f63EDb | B15: All (chain not encoded in address) | C15: 0 | D15: 0 | P15: No | Q15: 0 | R15: 0
A16: 0x19Be55D859368e02d7b9C00803Eb677BDC1359Bd | B16: All (chain not encoded in address) | C16: 0 | D16: 0 | P16: No | Q16: 0 | R16: 0
A17: 0x19dc38aeae620380430C200a6E990D5Af5480117 | B17: All (chain not encoded in address) | C17: 0 | D17: 0 | P17: No | Q17: 0 | R17: 0
A18: 0x1D5EbC3e15e9ECDe0e3530C85899556797eeaea5 | B18: All (chain not encoded in address) | C18: 0 | D18: 0 | P18: No | Q18: 0 | R18: 0
A19: 0x1E38556b4fE553e6249448960875883990efcf34 | B19: All (chain not encoded in address) | C19: 0 | D19: 0 | P19: No | Q19: 0 | R19: 0
A20: 0x1aFD5191738d365C8079e955E4cEdDfe7e01C62d | B20: All (chain not encoded in address) | C20: 0 | D20: 0 | P20: No | Q20: 0 | R20: 0
A21: 0x1b33611fCc073aB0737011d5512EF673Bff74962 | B21: All (chain not encoded in address) | C21: 1 | D21: 12166 | F21: Mythril | P21: Yes | Q21: 0 | R21: 1
A22: 0x1cE4d0E16570C362feef85Ce2713555fCbd3dBC7 | B22: All (chain not encoded in address) | C22: 1 | D22: 0 | N22: MAIAN | O22: MAIAN | P22: Yes | Q22: 1 | R22: 0
A23: 0x1df063280C4166AF9a725e3828b4dAC6c7113B08 | B23: All (chain not encoded in address) | C23: 1 | D23: 12272 | F23: Mythril | P23: Yes | Q23: 0 | R23: 1
A24: 0x208263bB303B2a737642fB13C765F106a2591be8 | B24: All (chain not encoded in address) | C24: 0 | D24: 0 | P24: No | Q24: 0 | R24: 0
A25: 0x20E98684e3879e76eb09BBa45035Ef290a85a7c6 | B25: All (chain not encoded in address) | C25: 1 | D25: 0 | O25: MAIAN | P25: Yes | Q25: 1 | R25: 0
A26: 0x2214711817f49665240f68efED0De888838BB375 | B26: All (chain not encoded in address) | C26: 0 | D26: 0 | P26: No | Q26: 0 | R26: 0
A27: 0x2235662a9a8ED39AE489aafb2feE13Db26f72044 | B27: All (chain not encoded in address) | C27: 1 | D27: 0 | N27: MAIAN | O27: MAIAN | P27: Yes | Q27: 1 | R27: 0
A28: 0x2254A9826b4bE58612b83498C327F37A796954DF | B28: All (chain not encoded in address) | C28: 0 | D28: 0 | P28: No | Q28: 0 | R28: 0
A29: 0x2351FBe24C1212F253b7a300ff0cBCFd97952a19 | B29: All (chain not encoded in address) | C29: 0 | D29: 0 | P29: No | Q29: 0 | R29: 0
A30: 0x239eB860770F1C48ABAC9bE9825d20e3E7c018df | B30: All (chain not encoded in address) | C30: 0 | D30: 0 | P30: No | Q30: 0 | R30: 0
A31: 0x270B3D343Dfbb67ADd7659F83F8e3e381A3369aC | B31: All (chain not encoded in address) | C31: 1 | D31: 0 | N31: MAIAN | O31: MAIAN | P31: Yes | Q31: 1 | R31: 0
A32: 0x27A43305C387b464F47D7feC179DF028fF6c1188 | B32: All (chain not encoded in address) | C32: 1 | D32: 0 | N32: MAIAN | O32: MAIAN | P32: Yes | Q32: 1 | R32: 0
A33: 0x28B02B97a850872C4D33C3E024fab6499ad96564 | B33: All (chain not encoded in address) | C33: 0 | D33: 0 | P33: No | Q33: 0 | R33: 0
A34: 0x28F7907911C7E321c596686AE6D1F20516450037 | B34: All (chain not encoded in address) | C34: 0 | D34: 0 | P34: No | Q34: 0 | R34: 0
A35: 0x29cEAFEE1F76B9CE271750f86B2bD12C23F9dDb6 | B35: All (chain not encoded in address) | C35: 0 | D35: 0 | P35: No | Q35: 0 | R35: 0
A36: 0x2AF32cF8e3Cf42d221eDa0c843818fA5ee129E27 | B36: All (chain not encoded in address) | C36: 0 | D36: 0 | P36: No | Q36: 0 | R36: 0
A37: 0x2F619Ac5122689180AeBB930ADccdae215d538a9 | B37: All (chain not encoded in address) | C37: 0 | D37: 0 | P37: No | Q37: 0 | R37: 0
A38: 0x2c58687fFfCD5b7043a5bF256B196216a98a6587 | B38: All (chain not encoded in address) | C38: 0 | D38: 0 | P38: No | Q38: 0 | R38: 0
A39: 0x2d0092538AB16c996D8E60b10B015Cd83616334D | B39: All (chain not encoded in address) | C39: 0 | D39: 0 | P39: No | Q39: 0 | R39: 0
A40: 0x3135f748747438854833cEbc1FD6A5636992c769 | B40: All (chain not encoded in address) | C40: 0 | D40: 0 | P40: No | Q40: 0 | R40: 0
...
